Workbook

Sheet BDR
A1: brand_id | B1: title | C1: title_category | D1: title_sub_category | E1: genre | F1: primary_genre | G1: rovi_id | H1: ticker_symbol | I1: title_content_windows | J1: companies | K1: brand_set | L1: active | M1: released_on | N1: box_office | O1: street_date | P1: gross_screen | Q1: opening_weekend_box_office | R1: network | S1: brand_listing_hidden | T1: facebook_page | U1: twitter_handle | V1: instagram_user | W1: youtube_channel_username | X1: tiktok_user | Y1: tumblr_page | Z1: pinterest_user_username | AA1: pinterest_board | AB1: wikipedia_page | AC1: rottentomatoes | AD1: imdb_id | AE1: metacritic | AF1: facebook_search_terms | AG1: twitter_search_terms | AH1: instagram_search_terms | AI1: tumblr_search_terms | AJ1: twitter_search_term_keywords | AK1: reddit_search_terms | AL1: youtube_search_terms | AM1: url_managers
B2: ='Ingest Template'!B2&IF('Ingest Template'!A2 = "Standard", " - DAR","") | C2: Movies | D2: {=CONCATENATE(INDEX(DropDown!$H$2:$H$10,MATCH(1,COUNTIF('Ingest Template'!F2,"*"&DropDown!$H$2:$H$10&"*"),0)),CHAR(10),'Ingest Template'!G2)} -> #N/A | E2: =CONCATENATE('Ingest Template'!H2,CHAR(10),'Ingest Template'!I2,CHAR(10),'Ingest Template'!J2) | F2: ='Ingest Template'!H2 | J2: {=iF('Ingest Template'!A2="Standard","Pristine Brand",INDEX(DropDown!$M$2:$M$392,MATCH('Ingest Template'!E2,DropDown!$J$2:$J$392,0)))} -> #N/A | K2: =iF('Ingest Template'!A2="Standard",'Ingest Template'!K2&CHAR(10)&'Ingest Template'!L2,"Competitive View") -> Competitive View | L2: t | M2: ='Ingest Template'!D2 | R2: ='Ingest Template'!E2 | S2: f | T2: ='Ingest Template'!T2 | U2: ='Ingest Template'!S2 | V2: =LOWER(SUBSTITUTE(SUBSTITUTE(SUBSTITUTE(SUBSTITUTE(SUBSTITUTE('Ingest Template'!U2,"https:",""),"www.",""),"/",""),"?hl=en",""),"instagram.com","")) | W2: {=IF('Ingest Template'!V2="",(INDEX(DropDown!$L$2:$L$392,MATCH('Ingest Template'!E2,DropDown!$J$2:$J$392,0))&"|"&'Ingest Template'!B2),(INDEX(DropDown!$L$2:$L$392,MATCH('Ingest Template'!E2,DropDown!$J$2:$J$392,0))&"|"&'Ingest Template'!B2)&CHAR(10)&'Ingest Template'!V2)} -> #N/A | X2: ='Ingest Template'!W2 | Y2: =SUBSTITUTE(SUBSTITUTE(SUBSTITUTE('Ingest Template'!X2,"http:",""),"https:",""),"/","") | Z2: {=IF('Ingest Template'!A2="Standard",(IF(ISBLANK('Ingest Template'!AA2),"", 'Ingest Template'!AA2&"|DAR")),(IF(ISBLANK('Ingest Template'!AA2),"", 'Ingest Template'!AA2&"|Film Ops")))} | AB2: ='Ingest Template'!M2 | AC2: ='Ingest Template'!Y2 | AD2: ='Ingest Template'!C2 | AE2: ='Ingest Template'!Z2 | AG2: {=IF('Ingest Template'!A2="Standard",(CONCATENATE(IF(ISBLANK('Ingest Template'!O2),"", 'Ingest Template'!O2&"|DAR"),CHAR(10), IF(ISBLANK('Ingest Template'!P2),"", 'Ingest Template'!P2&"|DAR"),CHAR(10), IF(ISBLANK('Ingest Template'!Q2),"", 'Ingest Template'!Q2&"|DAR"))),(CONCATENATE(IF(ISBLANK('Ingest Template'!O2),"", 'Ingest Template'!O2&"|Operations - Core Title"),CHAR(10), IF(ISBLANK('Ingest Template'!P2),"", 'Ingest Template'!P2&"|Operations - Core Title"),CHAR(10), IF(ISBLANK('Ingest Template'!Q2),"", 'Ingest Template'!Q2&"|Operations - Core Title"))))} -> #|Operations - Core Title #|Operations - Core Title | AJ2: =if('Ingest Template'!A2="Standard",'Ingest Template'!N2& "|DAR|DAR|2021-01-01",'Ingest Template'!N2& "|Operations - Core Title|Operations - Core Title") -> #N/A | AK2: =if('Ingest Template'!A2="Standard",'Ingest Template'!R2& "|2021-01-01",'Ingest Template'!R2) -> #N/A
B3: ='Ingest Template'!B3&IF('Ingest Template'!A3 = "Standard", " - DAR","") | C3: Movies | D3: {=CONCATENATE(INDEX(DropDown!$H$2:$H$10,MATCH(1,COUNTIF('Ingest Template'!F3,"*"&DropDown!$H$2:$H$10&"*"),0)),CHAR(10),'Ingest Template'!G3)} -> #N/A | E3: =CONCATENATE('Ingest Template'!H3,CHAR(10),'Ingest Template'!I3,CHAR(10),'Ingest Template'!J3) | F3: ='Ingest Template'!H3 | J3: {=iF('Ingest Template'!A3="Standard","Pristine Brand",INDEX(DropDown!$M$2:$M$392,MATCH('Ingest Template'!E3,DropDown!$J$2:$J$392,0)))} -> #N/A | K3: =iF('Ingest Template'!A3="Standard",'Ingest Template'!K3&CHAR(10)&'Ingest Template'!L3,"Competitive View") -> Competitive View | L3: t | M3: ='Ingest Template'!D3 | R3: ='Ingest Template'!E3 | S3: f | T3: ='Ingest Template'!T3 | U3: ='Ingest Template'!S3 | V3: =LOWER(SUBSTITUTE(SUBSTITUTE(SUBSTITUTE(SUBSTITUTE(SUBSTITUTE('Ingest Template'!U3,"https:",""),"www.",""),"/",""),"?hl=en",""),"instagram.com","")) | W3: {=IF('Ingest Template'!V3="",(INDEX(DropDown!$L$2:$L$392,MATCH('Ingest Template'!E3,DropDown!$J$2:$J$392,0))&"|"&'Ingest Template'!B3),(INDEX(DropDown!$L$2:$L$392,MATCH('Ingest Template'!E3,DropDown!$J$2:$J$392,0))&"|"&'Ingest Template'!B3)&CHAR(10)&'Ingest Template'!V3)} -> #N/A | X3: ='Ingest Template'!W3 | Y3: =SUBSTITUTE(SUBSTITUTE(SUBSTITUTE('Ingest Template'!X3,"http:",""),"https:",""),"/","") | Z3: {=IF('Ingest Template'!A3="Standard",(IF(ISBLANK('Ingest Template'!AA3),"", 'Ingest Template'!AA3&"|DAR")),(IF(ISBLANK('Ingest Template'!AA3),"", 'Ingest Template'!AA3&"|Film Ops")))} | AB3: ='Ingest Template'!M3 | AC3: ='Ingest Template'!Y3 | AD3: ='Ingest Template'!C3 | AE3: ='Ingest Template'!Z3 | AG3: {=IF('Ingest Template'!A3="Standard",(CONCATENATE(IF(ISBLANK('Ingest Template'!O3),"", 'Ingest Template'!O3&"|DAR"),CHAR(10), IF(ISBLANK('Ingest Template'!P3),"", 'Ingest Template'!P3&"|DAR"),CHAR(10), IF(ISBLANK('Ingest Template'!Q3),"", 'Ingest Template'!Q3&"|DAR"))),(CONCATENATE(IF(ISBLANK('Ingest Template'!O3),"", 'Ingest Template'!O3&"|Operations - Core Title"),CHAR(10), IF(ISBLANK('Ingest Template'!P3),"", 'Ingest Template'!P3&"|Operations - Core Title"),CHAR(10), IF(ISBLANK('Ingest Template'!Q3),"", 'Ingest Template'!Q3&"|Operations - Core Title"))))} -> #|Operations - Core Title #|Operations - Core Title | AJ3: =if('Ingest Template'!A3="Standard",'Ingest Template'!N3& "|DAR|DAR|2021-01-01",'Ingest Template'!N3& "|Operations - Core Title|Operations - Core Title") -> #N/A | AK3: =if('Ingest Template'!A3="Standard",'Ingest Template'!R3& "|2021-01-01",'Ingest Template'!R3) -> #N/A
B4: ='Ingest Template'!B4&IF('Ingest Template'!A4 = "Standard", " - DAR","") | C4: Movies | D4: {=CONCATENATE(INDEX(DropDown!$H$2:$H$10,MATCH(1,COUNTIF('Ingest Template'!F4,"*"&DropDown!$H$2:$H$10&"*"),0)),CHAR(10),'Ingest Template'!G4)} -> #N/A | E4: =CONCATENATE('Ingest Template'!H4,CHAR(10),'Ingest Template'!I4,CHAR(10),'Ingest Template'!J4) | F4: ='Ingest Template'!H4 | J4: {=iF('Ingest Template'!A4="Standard","Pristine Brand",INDEX(DropDown!$M$2:$M$392,MATCH('Ingest Template'!E4,DropDown!$J$2:$J$392,0)))} -> #N/A | K4: =iF('Ingest Template'!A4="Standard",'Ingest Template'!K4&CHAR(10)&'Ingest Template'!L4,"Competitive View") -> Competitive View | L4: t | M4: ='Ingest Template'!D4 | R4: ='Ingest Template'!E4 | S4: f | T4: ='Ingest Template'!T4 | U4: ='Ingest Template'!S4 | V4: =LOWER(SUBSTITUTE(SUBSTITUTE(SUBSTITUTE(SUBSTITUTE(SUBSTITUTE('Ingest Template'!U4,"https:",""),"www.",""),"/",""),"?hl=en",""),"instagram.com","")) | W4: {=IF('Ingest Template'!V4="",(INDEX(DropDown!$L$2:$L$392,MATCH('Ingest Template'!E4,DropDown!$J$2:$J$392,0))&"|"&'Ingest Template'!B4),(INDEX(DropDown!$L$2:$L$392,MATCH('Ingest Template'!E4,DropDown!$J$2:$J$392,0))&"|"&'Ingest Template'!B4)&CHAR(10)&'Ingest Template'!V4)} -> #N/A | X4: ='Ingest Template'!W4 | Y4: =SUBSTITUTE(SUBSTITUTE(SUBSTITUTE('Ingest Template'!X4,"http:",""),"https:",""),"/","") | Z4: {=IF('Ingest Template'!A4="Standard",(IF(ISBLANK('Ingest Template'!AA4),"", 'Ingest Template'!AA4&"|DAR")),(IF(ISBLANK('Ingest Template'!AA4),"", 'Ingest Template'!AA4&"|Film Ops")))} | AB4: ='Ingest Template'!M4 | AC4: ='Ingest Template'!Y4 | AD4: ='Ingest Template'!C4 | AE4: ='Ingest Template'!Z4 | AG4: {=IF('Ingest Template'!A4="Standard",(CONCATENATE(IF(ISBLANK('Ingest Template'!O4),"", 'Ingest Template'!O4&"|DAR"),CHAR(10), IF(ISBLANK('Ingest Template'!P4),"", 'Ingest Template'!P4&"|DAR"),CHAR(10), IF(ISBLANK('Ingest Template'!Q4),"", 'Ingest Template'!Q4&"|DAR"))),(CONCATENATE(IF(ISBLANK('Ingest Template'!O4),"", 'Ingest Template'!O4&"|Operations - Core Title"),CHAR(10), IF(ISBLANK('Ingest Template'!P4),"", 'Ingest Template'!P4&"|Operations - Core Title"),CHAR(10), IF(ISBLANK('Ingest Template'!Q4),"", 'Ingest Template'!Q4&"|Operations - Core Title"))))} -> #|Operations - Core Title #|Operations - Core Title | AJ4: =if('Ingest Template'!A4="Standard",'Ingest Template'!N4& "|DAR|DAR|2021-01-01",'Ingest Template'!N4& "|Operations - Core Title|Operations - Core Title") -> #N/A | AK4: =if('Ingest Template'!A4="Standard",'Ingest Template'!R4& "|2021-01-01",'Ingest Template'!R4) -> #N/A
B5: ='Ingest Template'!B5&IF('Ingest Template'!A5 = "Standard", " - DAR","") | C5: Movies | D5: {=CONCATENATE(INDEX(DropDown!$H$2:$H$10,MATCH(1,COUNTIF('Ingest Template'!F5,"*"&DropDown!$H$2:$H$10&"*"),0)),CHAR(10),'Ingest Template'!G5)} -> #N/A | E5: =CONCATENATE('Ingest Template'!H5,CHAR(10),'Ingest Template'!I5,CHAR(10),'Ingest Template'!J5) | F5: ='Ingest Template'!H5 | J5: {=iF('Ingest Template'!A5="Standard","Pristine Brand",INDEX(DropDown!$M$2:$M$392,MATCH('Ingest Template'!E5,DropDown!$J$2:$J$392,0)))} -> #N/A | K5: =iF('Ingest Template'!A5="Standard",'Ingest Template'!K5&CHAR(10)&'Ingest Template'!L5,"Competitive View") -> Competitive View | L5: t | M5: ='Ingest Template'!D5 | R5: ='Ingest Template'!E5 | S5: f | T5: ='Ingest Template'!T5 | U5: ='Ingest Template'!S5 | V5: =LOWER(SUBSTITUTE(SUBSTITUTE(SUBSTITUTE(SUBSTITUTE(SUBSTITUTE('Ingest Template'!U5,"https:",""),"www.",""),"/",""),"?hl=en",""),"instagram.com","")) | W5: {=IF('Ingest Template'!V5="",(INDEX(DropDown!$L$2:$L$392,MATCH('Ingest Template'!E5,DropDown!$J$2:$J$392,0))&"|"&'Ingest Template'!B5),(INDEX(DropDown!$L$2:$L$392,MATCH('Ingest Template'!E5,DropDown!$J$2:$J$392,0))&"|"&'Ingest Template'!B5)&CHAR(10)&'Ingest Template'!V5)} -> #N/A | X5: ='Ingest Template'!W5 | Y5: =SUBSTITUTE(SUBSTITUTE(SUBSTITUTE('Ingest Template'!X5,"http:",""),"https:",""),"/","") | Z5: {=IF('Ingest Template'!A5="Standard",(IF(ISBLANK('Ingest Template'!AA5),"", 'Ingest Template'!AA5&"|DAR")),(IF(ISBLANK('Ingest Template'!AA5),"", 'Ingest Template'!AA5&"|Film Ops")))} | AB5: ='Ingest Template'!M5 | AC5: ='Ingest Template'!Y5 | AD5: ='Ingest Template'!C5 | AE5: ='Ingest Template'!Z5 | AG5: {=IF('Ingest Template'!A5="Standard",(CONCATENATE(IF(ISBLANK('Ingest Template'!O5),"", 'Ingest Template'!O5&"|DAR"),CHAR(10), IF(ISBLANK('Ingest Template'!P5),"", 'Ingest Template'!P5&"|DAR"),CHAR(10), IF(ISBLANK('Ingest Template'!Q5),"", 'Ingest Template'!Q5&"|DAR"))),(CONCATENATE(IF(ISBLANK('Ingest Template'!O5),"", 'Ingest Template'!O5&"|Operations - Core Title"),CHAR(10), IF(ISBLANK('Ingest Template'!P5),"", 'Ingest Template'!P5&"|Operations - Core Title"),CHAR(10), IF(ISBLANK('Ingest Template'!Q5),"", 'Ingest Template'!Q5&"|Operations - Core Title"))))} -> #|Operations - Core Title #|Operations - Core Title | AJ5: =if('Ingest Template'!A5="Standard",'Ingest Template'!N5& "|DAR|DAR|2021-01-01",'Ingest Template'!N5& "|Operations - Core Title|Operations - Core Title") -> #N/A | AK5: =if('Ingest Template'!A5="Standard",'Ingest Template'!R5& "|2021-01-01",'Ingest Template'!R5) -> #N/A
B6: ='Ingest Template'!B6&IF('Ingest Template'!A6 = "Standard", " - DAR","") | C6: Movies | D6: {=CONCATENATE(INDEX(DropDown!$H$2:$H$10,MATCH(1,COUNTIF('Ingest Template'!F6,"*"&DropDown!$H$2:$H$10&"*"),0)),CHAR(10),'Ingest Template'!G6)} -> #N/A | E6: =CONCATENATE('Ingest Template'!H6,CHAR(10),'Ingest Template'!I6,CHAR(10),'Ingest Template'!J6) | F6: ='Ingest Template'!H6 | J6: {=iF('Ingest Template'!A6="Standard","Pristine Brand",INDEX(DropDown!$M$2:$M$392,MATCH('Ingest Template'!E6,DropDown!$J$2:$J$392,0)))} -> #N/A | K6: =iF('Ingest Template'!A6="Standard",'Ingest Template'!K6&CHAR(10)&'Ingest Template'!L6,"Competitive View") -> Competitive View | L6: t | M6: ='Ingest Template'!D6 | R6: ='Ingest Template'!E6 | S6: f | T6: ='Ingest Template'!T6 | U6: ='Ingest Template'!S6 | V6: =LOWER(SUBSTITUTE(SUBSTITUTE(SUBSTITUTE(SUBSTITUTE(SUBSTITUTE('Ingest Template'!U6,"https:",""),"www.",""),"/",""),"?hl=en",""),"instagram.com","")) | W6: {=IF('Ingest Template'!V6="",(INDEX(DropDown!$L$2:$L$392,MATCH('Ingest Template'!E6,DropDown!$J$2:$J$392,0))&"|"&'Ingest Template'!B6),(INDEX(DropDown!$L$2:$L$392,MATCH('Ingest Template'!E6,DropDown!$J$2:$J$392,0))&"|"&'Ingest Template'!B6)&CHAR(10)&'Ingest Template'!V6)} -> #N/A | X6: ='Ingest Template'!W6 | Y6: =SUBSTITUTE(SUBSTITUTE(SUBSTITUTE('Ingest Template'!X6,"http:",""),"https:",""),"/","") | Z6: {=IF('Ingest Template'!A6="Standard",(IF(ISBLANK('Ingest Template'!AA6),"", 'Ingest Template'!AA6&"|DAR")),(IF(ISBLANK('Ingest Template'!AA6),"", 'Ingest Template'!AA6&"|Film Ops")))} | AB6: ='Ingest Template'!M6 | AC6: ='Ingest Template'!Y6 | AD6: ='Ingest Template'!C6 | AE6: ='Ingest Template'!Z6 | AG6: {=IF('Ingest Template'!A6="Standard",(CONCATENATE(IF(ISBLANK('Ingest Template'!O6),"", 'Ingest Template'!O6&"|DAR"),CHAR(10), IF(ISBLANK('Ingest Template'!P6),"", 'Ingest Template'!P6&"|DAR"),CHAR(10), IF(ISBLANK('Ingest Template'!Q6),"", 'Ingest Template'!Q6&"|DAR"))),(CONCATENATE(IF(ISBLANK('Ingest Template'!O6),"", 'Ingest Template'!O6&"|Operations - Core Title"),CHAR(10), IF(ISBLANK('Ingest Template'!P6),"", 'Ingest Template'!P6&"|Operations - Core Title"),CHAR(10), IF(ISBLANK('Ingest Template'!Q6),"", 'Ingest Template'!Q6&"|Operations - Core Title"))))} -> #|Operations - Core Title #|Operations - Core Title | AJ6: =if('Ingest Template'!A6="Standard",'Ingest Template'!N6& "|DAR|DAR|2021-01-01",'Ingest Template'!N6& "|Operations - Core Title|Operations - Core Title") -> #N/A | AK6: =if('Ingest Template'!A6="Standard",'Ingest Template'!R6& "|2021-01-01",'Ingest Template'!R6) -> #N/A
B7: ='Ingest Template'!B7&IF('Ingest Template'!A7 = "Standard", " - DAR","") | C7: Movies | D7: {=CONCATENATE(INDEX(DropDown!$H$2:$H$10,MATCH(1,COUNTIF('Ingest Template'!F7,"*"&DropDown!$H$2:$H$10&"*"),0)),CHAR(10),'Ingest Template'!G7)} -> #N/A | E7: =CONCATENATE('Ingest Template'!H7,CHAR(10),'Ingest Template'!I7,CHAR(10),'Ingest Template'!J7) | F7: ='Ingest Template'!H7 | J7: {=iF('Ingest Template'!A7="Standard","Pristine Brand",INDEX(DropDown!$M$2:$M$392,MATCH('Ingest Template'!E7,DropDown!$J$2:$J$392,0)))} -> #N/A | K7: =iF('Ingest Template'!A7="Standard",'Ingest Template'!K7&CHAR(10)&'Ingest Template'!L7,"Competitive View") -> Competitive View | L7: t | M7: ='Ingest Template'!D7 | R7: ='Ingest Template'!E7 | S7: f | T7: ='Ingest Template'!T7 | U7: ='Ingest Template'!S7 | V7: =LOWER(SUBSTITUTE(SUBSTITUTE(SUBSTITUTE(SUBSTITUTE(SUBSTITUTE('Ingest Template'!U7,"https:",""),"www.",""),"/",""),"?hl=en",""),"instagram.com","")) | W7: {=IF('Ingest Template'!V7="",(INDEX(DropDown!$L$2:$L$392,MATCH('Ingest Template'!E7,DropDown!$J$2:$J$392,0))&"|"&'Ingest Template'!B7),(INDEX(DropDown!$L$2:$L$392,MATCH('Ingest Template'!E7,DropDown!$J$2:$J$392,0))&"|"&'Ingest Template'!B7)&CHAR(10)&'Ingest Template'!V7)} -> #N/A | X7: ='Ingest Template'!W7 | Y7: =SUBSTITUTE(SUBSTITUTE(SUBSTITUTE('Ingest Template'!X7,"http:",""),"https:",""),"/","") | Z7: {=IF('Ingest Template'!A7="Standard",(IF(ISBLANK('Ingest Template'!AA7),"", 'Ingest Template'!AA7&"|DAR")),(IF(ISBLANK('Ingest Template'!AA7),"", 'Ingest Template'!AA7&"|Film Ops")))} | AB7: ='Ingest Template'!M7 | AC7: ='Ingest Template'!Y7 | AD7: ='Ingest Template'!C7 | AE7: ='Ingest Template'!Z7 | AG7: {=IF('Ingest Template'!A7="Standard",(CONCATENATE(IF(ISBLANK('Ingest Template'!O7),"", 'Ingest Template'!O7&"|DAR"),CHAR(10), IF(ISBLANK('Ingest Template'!P7),"", 'Ingest Template'!P7&"|DAR"),CHAR(10), IF(ISBLANK('Ingest Template'!Q7),"", 'Ingest Template'!Q7&"|DAR"))),(CONCATENATE(IF(ISBLANK('Ingest Template'!O7),"", 'Ingest Template'!O7&"|Operations - Core Title"),CHAR(10), IF(ISBLANK('Ingest Template'!P7),"", 'Ingest Template'!P7&"|Operations - Core Title"),CHAR(10), IF(ISBLANK('Ingest Template'!Q7),"", 'Ingest Template'!Q7&"|Operations - Core Title"))))} -> #|Operations - Core Title #|Operations - Core Title | AJ7: =if('Ingest Template'!A7="Standard",'Ingest Template'!N7& "|DAR|DAR|2021-01-01",'Ingest Template'!N7& "|Operations - Core Title|Operations - Core Title") -> #N/A | AK7: =if('Ingest Template'!A7="Standard",'Ingest Template'!R7& "|2021-01-01",'Ingest Template'!R7) -> #N/A
B8: ='Ingest Template'!B8&IF('Ingest Template'!A8 = "Standard", " - DAR","") | C8: Movies | D8: {=CONCATENATE(INDEX(DropDown!$H$2:$H$10,MATCH(1,COUNTIF('Ingest Template'!F8,"*"&DropDown!$H$2:$H$10&"*"),0)),CHAR(10),'Ingest Template'!G8)} -> #N/A | E8: =CONCATENATE('Ingest Template'!H8,CHAR(10),'Ingest Template'!I8,CHAR(10),'Ingest Template'!J8) | F8: ='Ingest Template'!H8 | J8: {=iF('Ingest Template'!A8="Standard","Pristine Brand",INDEX(DropDown!$M$2:$M$392,MATCH('Ingest Template'!E8,DropDown!$J$2:$J$392,0)))} -> #N/A | K8: =iF('Ingest Template'!A8="Standard",'Ingest Template'!K8&CHAR(10)&'Ingest Template'!L8,"Competitive View") -> Competitive View | L8: t | M8: ='Ingest Template'!D8 | R8: ='Ingest Template'!E8 | S8: f | T8: ='Ingest Template'!T8 | U8: ='Ingest Template'!S8 | V8: =LOWER(SUBSTITUTE(SUBSTITUTE(SUBSTITUTE(SUBSTITUTE(SUBSTITUTE('Ingest Template'!U8,"https:",""),"www.",""),"/",""),"?hl=en",""),"instagram.com","")) | W8: {=IF('Ingest Template'!V8="",(INDEX(DropDown!$L$2:$L$392,MATCH('Ingest Template'!E8,DropDown!$J$2:$J$392,0))&"|"&'Ingest Template'!B8),(INDEX(DropDown!$L$2:$L$392,MATCH('Ingest Template'!E8,DropDown!$J$2:$J$392,0))&"|"&'Ingest Template'!B8)&CHAR(10)&'Ingest Template'!V8)} -> #N/A | X8: ='Ingest Template'!W8 | Y8: =SUBSTITUTE(SUBSTITUTE(SUBSTITUTE('Ingest Template'!X8,"http:",""),"https:",""),"/","") | Z8: {=IF('Ingest Template'!A8="Standard",(IF(ISBLANK('Ingest Template'!AA8),"", 'Ingest Template'!AA8&"|DAR")),(IF(ISBLANK('Ingest Template'!AA8),"", 'Ingest Template'!AA8&"|Film Ops")))} | AB8: ='Ingest Template'!M8 | AC8: ='Ingest Template'!Y8 | AD8: ='Ingest Template'!C8 | AE8: ='Ingest Template'!Z8 | AG8: {=IF('Ingest Template'!A8="Standard",(CONCATENATE(IF(ISBLANK('Ingest Template'!O8),"", 'Ingest Template'!O8&"|DAR"),CHAR(10), IF(ISBLANK('Ingest Template'!P8),"", 'Ingest Template'!P8&"|DAR"),CHAR(10), IF(ISBLANK('Ingest Template'!Q8),"", 'Ingest Template'!Q8&"|DAR"))),(CONCATENATE(IF(ISBLANK('Ingest Template'!O8),"", 'Ingest Template'!O8&"|Operations - Core Title"),CHAR(10), IF(ISBLANK('Ingest Template'!P8),"", 'Ingest Template'!P8&"|Operations - Core Title"),CHAR(10), IF(ISBLANK('Ingest Template'!Q8),"", 'Ingest Template'!Q8&"|Operations - Core Title"))))} -> #|Operations - Core Title #|Operations - Core Title | AJ8: =if('Ingest Template'!A8="Standard",'Ingest Template'!N8& "|DAR|DAR|2021-01-01",'Ingest Template'!N8& "|Operations - Core Title|Operations - Core Title") -> #N/A | AK8: =if('Ingest Template'!A8="Standard",'Ingest Template'!R8& "|2021-01-01",'Ingest Template'!R8) -> #N/A
B9: ='Ingest Template'!B9&IF('Ingest Template'!A9 = "Standard", " - DAR","") | C9: Movies | D9: {=CONCATENATE(INDEX(DropDown!$H$2:$H$10,MATCH(1,COUNTIF('Ingest Template'!F9,"*"&DropDown!$H$2:$H$10&"*"),0)),CHAR(10),'Ingest Template'!G9)} -> #N/A | E9: =CONCATENATE('Ingest Template'!H9,CHAR(10),'Ingest Template'!I9,CHAR(10),'Ingest Template'!J9) | F9: ='Ingest Template'!H9 | J9: {=iF('Ingest Template'!A9="Standard","Pristine Brand",INDEX(DropDown!$M$2:$M$392,MATCH('Ingest Template'!E9,DropDown!$J$2:$J$392,0)))} -> #N/A | K9: =iF('Ingest Template'!A9="Standard",'Ingest Template'!K9&CHAR(10)&'Ingest Template'!L9,"Competitive View") -> Competitive View | L9: t | M9: ='Ingest Template'!D9 | R9: ='Ingest Template'!E9 | S9: f | T9: ='Ingest Template'!T9 | U9: ='Ingest Template'!S9 | V9: =LOWER(SUBSTITUTE(SUBSTITUTE(SUBSTITUTE(SUBSTITUTE(SUBSTITUTE('Ingest Template'!U9,"https:",""),"www.",""),"/",""),"?hl=en",""),"instagram.com","")) | W9: {=IF('Ingest Template'!V9="",(INDEX(DropDown!$L$2:$L$392,MATCH('Ingest Template'!E9,DropDown!$J$2:$J$392,0))&"|"&'Ingest Template'!B9),(INDEX(DropDown!$L$2:$L$392,MATCH('Ingest Template'!E9,DropDown!$J$2:$J$392,0))&"|"&'Ingest Template'!B9)&CHAR(10)&'Ingest Template'!V9)} -> #N/A | X9: ='Ingest Template'!W9 | Y9: =SUBSTITUTE(SUBSTITUTE(SUBSTITUTE('Ingest Template'!X9,"http:",""),"https:",""),"/","") | Z9: {=IF('Ingest Template'!A9="Standard",(IF(ISBLANK('Ingest Template'!AA9),"", 'Ingest Template'!AA9&"|DAR")),(IF(ISBLANK('Ingest Template'!AA9),"", 'Ingest Template'!AA9&"|Film Ops")))} | AB9: ='Ingest Template'!M9 | AC9: ='Ingest Template'!Y9 | AD9: ='Ingest Template'!C9 | AE9: ='Ingest Template'!Z9 | AG9: {=IF('Ingest Template'!A9="Standard",(CONCATENATE(IF(ISBLANK('Ingest Template'!O9),"", 'Ingest Template'!O9&"|DAR"),CHAR(10), IF(ISBLANK('Ingest Template'!P9),"", 'Ingest Template'!P9&"|DAR"),CHAR(10), IF(ISBLANK('Ingest Template'!Q9),"", 'Ingest Template'!Q9&"|DAR"))),(CONCATENATE(IF(ISBLANK('Ingest Template'!O9),"", 'Ingest Template'!O9&"|Operations - Core Title"),CHAR(10), IF(ISBLANK('Ingest Template'!P9),"", 'Ingest Template'!P9&"|Operations - Core Title"),CHAR(10), IF(ISBLANK('Ingest Template'!Q9),"", 'Ingest Template'!Q9&"|Operations - Core Title"))))} -> #|Operations - Core Title #|Operations - Core Title | AJ9: =if('Ingest Template'!A9="Standard",'Ingest Template'!N9& "|DAR|DAR|2021-01-01",'Ingest Template'!N9& "|Operations - Core Title|Operations - Core Title") -> #N/A | AK9: =if('Ingest Template'!A9="Standard",'Ingest Template'!R9& "|2021-01-01",'Ingest Template'!R9) -> #N/A
B10: ='Ingest Template'!B10&IF('Ingest Template'!A10 = "Standard", " - DAR","") | C10: Movies | D10: {=CONCATENATE(INDEX(DropDown!$H$2:$H$10,MATCH(1,COUNTIF('Ingest Template'!F10,"*"&DropDown!$H$2:$H$10&"*"),0)),CHAR(10),'Ingest Template'!G10)} -> #N/A | E10: =CONCATENATE('Ingest Template'!H10,CHAR(10),'Ingest Template'!I10,CHAR(10),'Ingest Template'!J10) | F10: ='Ingest Template'!H10 | J10: {=iF('Ingest Template'!A10="Standard","Pristine Brand",INDEX(DropDown!$M$2:$M$392,MATCH('Ingest Template'!E10,DropDown!$J$2:$J$392,0)))} -> #N/A | K10: =iF('Ingest Template'!A10="Standard",'Ingest Template'!K10&CHAR(10)&'Ingest Template'!L10,"Competitive View") -> Competitive View | L10: t | M10: ='Ingest Template'!D10 | R10: ='Ingest Template'!E10 | S10: f | T10: ='Ingest Template'!T10 | U10: ='Ingest Template'!S10 | V10: =LOWER(SUBSTITUTE(SUBSTITUTE(SUBSTITUTE(SUBSTITUTE(SUBSTITUTE('Ingest Template'!U10,"https:",""),"www.",""),"/",""),"?hl=en",""),"instagram.com","")) | W10: {=IF('Ingest Template'!V10="",(INDEX(DropDown!$L$2:$L$392,MATCH('Ingest Template'!E10,DropDown!$J$2:$J$392,0))&"|"&'Ingest Template'!B10),(INDEX(DropDown!$L$2:$L$392,MATCH('Ingest Template'!E10,DropDown!$J$2:$J$392,0))&"|"&'Ingest Template'!B10)&CHAR(10)&'Ingest Template'!V10)} -> #N/A | X10: ='Ingest Template'!W10 | Y10: =SUBSTITUTE(SUBSTITUTE(SUBSTITUTE('Ingest Template'!X10,"http:",""),"https:",""),"/","") | Z10: {=IF('Ingest Template'!A10="Standard",(IF(ISBLANK('Ingest Template'!AA10),"", 'Ingest Template'!AA10&"|DAR")),(IF(ISBLANK('Ingest Template'!AA10),"", 'Ingest Template'!AA10&"|Film Ops")))} | AB10: ='Ingest Template'!M10 | AC10: ='Ingest Template'!Y10 | AD10: ='Ingest Template'!C10 | AE10: ='Ingest Template'!Z10 | AG10: {=IF('Ingest Template'!A10="Standard",(CONCATENATE(IF(ISBLANK('Ingest Template'!O10),"", 'Ingest Template'!O10&"|DAR"),CHAR(10), IF(ISBLANK('Ingest Template'!P10),"", 'Ingest Template'!P10&"|DAR"),CHAR(10), IF(ISBLANK('Ingest Template'!Q10),"", 'Ingest Template'!Q10&"|DAR"))),(CONCATENATE(IF(ISBLANK('Ingest Template'!O10),"", 'Ingest Template'!O10&"|Operations - Core Title"),CHAR(10), IF(ISBLANK('Ingest Template'!P10),"", 'Ingest Template'!P10&"|Operations - Core Title"),CHAR(10), IF(ISBLANK('Ingest Template'!Q10),"", 'Ingest Template'!Q10&"|Operations - Core Title"))))} -> #|Operations - Core Title #|Operations - Core Title | AJ10: =if('Ingest Template'!A10="Standard",'Ingest Template'!N10& "|DAR|DAR|2021-01-01",'Ingest Template'!N10& "|Operations - Core Title|Operations - Core Title") -> #N/A | AK10: =if('Ingest Template'!A10="Standard",'Ingest Template'!R10& "|2021-01-01",'Ingest Template'!R10) -> #N/A
B11: ='Ingest Template'!B11&IF('Ingest Template'!A11 = "Standard", " - DAR","") | C11: Movies | D11: {=CONCATENATE(INDEX(DropDown!$H$2:$H$10,MATCH(1,COUNTIF('Ingest Template'!F11,"*"&DropDown!$H$2:$H$10&"*"),0)),CHAR(10),'Ingest Template'!G11)} -> #N/A | E11: =CONCATENATE('Ingest Template'!H11,CHAR(10),'Ingest Template'!I11,CHAR(10),'Ingest Template'!J11) | F11: ='Ingest Template'!H11 | J11: {=iF('Ingest Template'!A11="Standard","Pristine Brand",INDEX(DropDown!$M$2:$M$392,MATCH('Ingest Template'!E11,DropDown!$J$2:$J$392,0)))} -> #N/A | K11: =iF('Ingest Template'!A11="Standard",'Ingest Template'!K11&CHAR(10)&'Ingest Template'!L11,"Competitive View") -> Competitive View | L11: t | M11: ='Ingest Template'!D11 | R11: ='Ingest Template'!E11 | S11: f | T11: ='Ingest Template'!T11 | U11: ='Ingest Template'!S11 | V11: =LOWER(SUBSTITUTE(SUBSTITUTE(SUBSTITUTE(SUBSTITUTE(SUBSTITUTE('Ingest Template'!U11,"https:",""),"www.",""),"/",""),"?hl=en",""),"instagram.com","")) | W11: {=IF('Ingest Template'!V11="",(INDEX(DropDown!$L$2:$L$392,MATCH('Ingest Template'!E11,DropDown!$J$2:$J$392,0))&"|"&'Ingest Template'!B11),(INDEX(DropDown!$L$2:$L$392,MATCH('Ingest Template'!E11,DropDown!$J$2:$J$392,0))&"|"&'Ingest Template'!B11)&CHAR(10)&'Ingest Template'!V11)} -> #N/A | X11: ='Ingest Template'!W11 | Y11: =SUBSTITUTE(SUBSTITUTE(SUBSTITUTE('Ingest Template'!X11,"http:",""),"https:",""),"/","") | Z11: {=IF('Ingest Template'!A11="Standard",(IF(ISBLANK('Ingest Template'!AA11),"", 'Ingest Template'!AA11&"|DAR")),(IF(ISBLANK('Ingest Template'!AA11),"", 'Ingest Template'!AA11&"|Film Ops")))} | AB11: ='Ingest Template'!M11 | AC11: ='Ingest Template'!Y11 | AD11: ='Ingest Template'!C11 | AE11: ='Ingest Template'!Z11 | AG11: {=IF('Ingest Template'!A11="Standard",(CONCATENATE(IF(ISBLANK('Ingest Template'!O11),"", 'Ingest Template'!O11&"|DAR"),CHAR(10), IF(ISBLANK('Ingest Template'!P11),"", 'Ingest Template'!P11&"|DAR"),CHAR(10), IF(ISBLANK('Ingest Template'!Q11),"", 'Ingest Template'!Q11&"|DAR"))),(CONCATENATE(IF(ISBLANK('Ingest Template'!O11),"", 'Ingest Template'!O11&"|Operations - Core Title"),CHAR(10), IF(ISBLANK('Ingest Template'!P11),"", 'Ingest Template'!P11&"|Operations - Core Title"),CHAR(10), IF(ISBLANK('Ingest Template'!Q11),"", 'Ingest Template'!Q11&"|Operations - Core Title"))))} -> #|Operations - Core Title #|Operations - Core Title | AJ11: =if('Ingest Template'!A11="Standard",'Ingest Template'!N11& "|DAR|DAR|2021-01-01",'Ingest Template'!N11& "|Operations - Core Title|Operations - Core Title") -> #N/A | AK11: =if('Ingest Template'!A11="Standard",'Ingest Template'!R11& "|2021-01-01",'Ingest Template'!R11) -> #N/A
B12: ='Ingest Template'!B12&IF('Ingest Template'!A12 = "Standard", " - DAR","") | C12: Movies | D12: {=CONCATENATE(INDEX(DropDown!$H$2:$H$10,MATCH(1,COUNTIF('Ingest Template'!F12,"*"&DropDown!$H$2:$H$10&"*"),0)),CHAR(10),'Ingest Template'!G12)} -> #N/A | E12: =CONCATENATE('Ingest Template'!H12,CHAR(10),'Ingest Template'!I12,CHAR(10),'Ingest Template'!J12) | F12: ='Ingest Template'!H12 | J12: {=iF('Ingest Template'!A12="Standard","Pristine Brand",INDEX(DropDown!$M$2:$M$392,MATCH('Ingest Template'!E12,DropDown!$J$2:$J$392,0)))} -> #N/A | K12: =iF('Ingest Template'!A12="Standard",'Ingest Template'!K12&CHAR(10)&'Ingest Template'!L12,"Competitive View") -> Competitive View | L12: t | M12: ='Ingest Template'!D12 | R12: ='Ingest Template'!E12 | S12: f | T12: ='Ingest Template'!T12 | U12: ='Ingest Template'!S12 | V12: =LOWER(SUBSTITUTE(SUBSTITUTE(SUBSTITUTE(SUBSTITUTE(SUBSTITUTE('Ingest Template'!U12,"https:",""),"www.",""),"/",""),"?hl=en",""),"instagram.com","")) | W12: {=IF('Ingest Template'!V12="",(INDEX(DropDown!$L$2:$L$392,MATCH('Ingest Template'!E12,DropDown!$J$2:$J$392,0))&"|"&'Ingest Template'!B12),(INDEX(DropDown!$L$2:$L$392,MATCH('Ingest Template'!E12,DropDown!$J$2:$J$392,0))&"|"&'Ingest Template'!B12)&CHAR(10)&'Ingest Template'!V12)} -> #N/A | X12: ='Ingest Template'!W12 | Y12: =SUBSTITUTE(SUBSTITUTE(SUBSTITUTE('Ingest Template'!X12,"http:",""),"https:",""),"/","") | Z12: {=IF('Ingest Template'!A12="Standard",(IF(ISBLANK('Ingest Template'!AA12),"", 'Ingest Template'!AA12&"|DAR")),(IF(ISBLANK('Ingest Template'!AA12),"", 'Ingest Template'!AA12&"|Film Ops")))} | AB12: ='Ingest Template'!M12 | AC12: ='Ingest Template'!Y12 | AD12: ='Ingest Template'!C12 | AE12: ='Ingest Template'!Z12 | AG12: {=IF('Ingest Template'!A12="Standard",(CONCATENATE(IF(ISBLANK('Ingest Template'!O12),"", 'Ingest Template'!O12&"|DAR"),CHAR(10), IF(ISBLANK('Ingest Template'!P12),"", 'Ingest Template'!P12&"|DAR"),CHAR(10), IF(ISBLANK('Ingest Template'!Q12),"", 'Ingest Template'!Q12&"|DAR"))),(CONCATENATE(IF(ISBLANK('Ingest Template'!O12),"", 'Ingest Template'!O12&"|Operations - Core Title"),CHAR(10), IF(ISBLANK('Ingest Template'!P12),"", 'Ingest Template'!P12&"|Operations - Core Title"),CHAR(10), IF(ISBLANK('Ingest Template'!Q12),"", 'Ingest Template'!Q12&"|Operations - Core Title"))))} -> #|Operations - Core Title #|Operations - Core Title | AJ12: =if('Ingest Template'!A12="Standard",'Ingest Template'!N12& "|DAR|DAR|2021-01-01",'Ingest Template'!N12& "|Operations - Core Title|Operations - Core Title") -> #N/A | AK12: =if('Ingest Template'!A12="Standard",'Ingest Template'!R12& "|2021-01-01",'Ingest Template'!R12) -> #N/A
B13: ='Ingest Template'!B13&IF('Ingest Template'!A13 = "Standard", " - DAR","") | C13: Movies | D13: {=CONCATENATE(INDEX(DropDown!$H$2:$H$10,MATCH(1,COUNTIF('Ingest Template'!F13,"*"&DropDown!$H$2:$H$10&"*"),0)),CHAR(10),'Ingest Template'!G13)} -> #N/A | E13: =CONCATENATE('Ingest Template'!H13,CHAR(10),'Ingest Template'!I13,CHAR(10),'Ingest Template'!J13) | F13: ='Ingest Template'!H13 | J13: {=iF('Ingest Template'!A13="Standard","Pristine Brand",INDEX(DropDown!$M$2:$M$392,MATCH('Ingest Template'!E13,DropDown!$J$2:$J$392,0)))} -> #N/A | K13: =iF('Ingest Template'!A13="Standard",'Ingest Template'!K13&CHAR(10)&'Ingest Template'!L13,"Competitive View") -> Competitive View | L13: t | M13: ='Ingest Template'!D13 | R13: ='Ingest Template'!E13 | S13: f | T13: ='Ingest Template'!T13 | U13: ='Ingest Template'!S13 | V13: =LOWER(SUBSTITUTE(SUBSTITUTE(SUBSTITUTE(SUBSTITUTE(SUBSTITUTE('Ingest Template'!U13,"https:",""),"www.",""),"/",""),"?hl=en",""),"instagram.com","")) | W13: {=IF('Ingest Template'!V13="",(INDEX(DropDown!$L$2:$L$392,MATCH('Ingest Template'!E13,DropDown!$J$2:$J$392,0))&"|"&'Ingest Template'!B13),(INDEX(DropDown!$L$2:$L$392,MATCH('Ingest Template'!E13,DropDown!$J$2:$J$392,0))&"|"&'Ingest Template'!B13)&CHAR(10)&'Ingest Template'!V13)} -> #N/A | X13: ='Ingest Template'!W13 | Y13: =SUBSTITUTE(SUBSTITUTE(SUBSTITUTE('Ingest Template'!X13,"http:",""),"https:",""),"/","") | Z13: {=IF('Ingest Template'!A13="Standard",(IF(ISBLANK('Ingest Template'!AA13),"", 'Ingest Template'!AA13&"|DAR")),(IF(ISBLANK('Ingest Template'!AA13),"", 'Ingest Template'!AA13&"|Film Ops")))} | AB13: ='Ingest Template'!M13 | AC13: ='Ingest Template'!Y13 | AD13: ='Ingest Template'!C13 | AE13: ='Ingest Template'!Z13 | AG13: {=IF('Ingest Template'!A13="Standard",(CONCATENATE(IF(ISBLANK('Ingest Template'!O13),"", 'Ingest Template'!O13&"|DAR"),CHAR(10), IF(ISBLANK('Ingest Template'!P13),"", 'Ingest Template'!P13&"|DAR"),CHAR(10), IF(ISBLANK('Ingest Template'!Q13),"", 'Ingest Template'!Q13&"|DAR"))),(CONCATENATE(IF(ISBLANK('Ingest Template'!O13),"", 'Ingest Template'!O13&"|Operations - Core Title"),CHAR(10), IF(ISBLANK('Ingest Template'!P13),"", 'Ingest Template'!P13&"|Operations - Core Title"),CHAR(10), IF(ISBLANK('Ingest Template'!Q13),"", 'Ingest Template'!Q13&"|Operations - Core Title"))))} -> #|Operations - Core Title #|Operations - Core Title | AJ13: =if('Ingest Template'!A13="Standard",'Ingest Template'!N13& "|DAR|DAR|2021-01-01",'Ingest Template'!N13& "|Operations - Core Title|Operations - Core Title") -> #N/A | AK13: =if('Ingest Template'!A13="Standard",'Ingest Template'!R13& "|2021-01-01",'Ingest Template'!R13) -> #N/A
... B1000: ='Ingest Template'!B1000&IF('Ingest Template'!A1000 = "Standard", " - DAR","") | C1000: Movies | D1000: {=CONCATENATE(INDEX(DropDown!$H$2:$H$10,MATCH(1,COUNTIF('Ingest Template'!F1000,"*"&DropDown!$H$2:$H$10&"*"),0)),CHAR(10),'Ingest Template'!G1000)} -> #N/A | E1000: =CONCATENATE('Ingest Template'!H1000,CHAR(10),'Ingest Template'!I1000,CHAR(10),'Ingest Template'!J1000) | F1000: ='Ingest Template'!H1000 | J1000: {=iF('Ingest Template'!A1000="Standard","Pristine Brand",INDEX(DropDown!$M$2:$M$392,MATCH('Ingest Template'!E1000,DropDown!$J$2:$J$392,0)))} -> #N/A | K1000: =iF('Ingest Template'!A1000="Standard",'Ingest Template'!K1000&CHAR(10)&'Ingest Template'!L1000,"Competitive View") -> Competitive View | L1000: t | M1000: ='Ingest Template'!D1000 | R1000: ='Ingest Template'!E1000 | S1000: f | T1000: ='Ingest Template'!T1000 | U1000: ='Ingest Template'!S1000 | V1000: =LOWER(SUBSTITUTE(SUBSTITUTE(SUBSTITUTE(SUBSTITUTE(SUBSTITUTE('Ingest Template'!U1000,"https:",""),"www.",""),"/",""),"?hl=en",""),"instagram.com","")) | W1000: {=IF('Ingest Template'!V1000="",(INDEX(DropDown!$L$2:$L$392,MATCH('Ingest Template'!E1000,DropDown!$J$2:$J$392,0))&"|"&'Ingest Template'!B1000),(INDEX(DropDown!$L$2:$L$392,MATCH('Ingest Template'!E1000,DropDown!$J$2:$J$392,0))&"|"&'Ingest Template'!B1000)&CHAR(10)&'Ingest Template'!V1000)} -> #N/A | X1000: ='Ingest Template'!W1000 | Y1000: =SUBSTITUTE(SUBSTITUTE(SUBSTITUTE('Ingest Template'!X1000,"http:",""),"https:",""),"/","") | Z1000: {=IF('Ingest Template'!A1000="Standard",(IF(ISBLANK('Ingest Template'!AA1000),"", 'Ingest Template'!AA1000&"|DAR")),(IF(ISBLANK('Ingest Template'!AA1000),"", 'Ingest Template'!AA1000&"|Film Ops")))} | AB1000: ='Ingest Template'!M1000 | AC1000: ='Ingest Template'!Y1000 | AD1000: ='Ingest Template'!C1000 | AE1000: ='Ingest Template'!Z1000 | AG1000: {=IF('Ingest Template'!A1000="Standard",(CONCATENATE(IF(ISBLANK('Ingest Template'!O1000),"", 'Ingest Template'!O1000&"|DAR"),CHAR(10), IF(ISBLANK('Ingest Template'!P1000),"", 'Ingest Template'!P1000&"|DAR"),CHAR(10), IF(ISBLANK('Ingest Template'!Q1000),"", 'Ingest Template'!Q1000&"|DAR"))),(CONCATENATE(IF(ISBLANK('Ingest Template'!O1000),"", 'Ingest Template'!O1000&"|Operations - Core Title"),CHAR(10), IF(ISBLANK('Ingest Template'!P1000),"", 'Ingest Template'!P1000&"|Operations - Core Title"),CHAR(10), IF(ISBLANK('Ingest Template'!Q1000),"", 'Ingest Template'!Q1000&"|Operations - Core Title"))))} -> #|Operations - Core Title #|Operations - Core Title | AJ1000: =if('Ingest Template'!A1000="Standard",'Ingest Template'!N1000& "|DAR|DAR|2021-01-01",'Ingest Template'!N1000& "|Operations - Core Title|Operations - Core Title") -> #N/A | AK1000: =if('Ingest Template'!A1000="Standard",'Ingest Template'!R1000& "|2021-01-01",'Ingest Template'!R1000) -> #N/A

Sheet Ingest Template
A1: Perspective | B1: Title Name | C1: IMDB URL | D1: Release Date | E1: Studio | F1: Release Type | G1: Studio Type | H1: Genre 1 | I1: Genre 2 | J1: Genre 3 | K1: Film Brand Sets | L1: Media Conglomerate Brand Sets | M1: Wikipedia | N1: Twitter Keyword (Search String) | O1: Twitter Hashtag 1 | P1: # 2 | Q1: # 3 | R1: Reddit Keyword (Search String) | S1: Twitter Page (URL) | T1: Facebook Page (URL) | U1: Instagram Account (URL) | V1: YouTube (Brand) | W1: TikTok | X1: Tumblr | Y1: Rotten Tomatoes | Z1: Metacritic | AA1: Pinterest Username
G2: =VLOOKUP(E2,DropDown!J:K,2,FALSE) -> #N/A | K2: LF // Film - Majors + Independents | N2: ="("""&B2&""") ("&Vlookup(E2,DropDown!J:N,5,FALSE)&" OR """ &YEAR(D2) & """ OR ""All New"" OR Episode OR Watch OR tv OR Show OR Series OR season OR binge OR Stream OR Film OR Movie OR Premiere OR Screening OR Feature OR Trailer OR Teaser OR theater OR release)" -> #N/A | O2: =Substitute(Substitute(Substitute(Substitute(Substitute(Substitute(Substitute(Substitute(Substitute(Substitute(Substitute(Substitute("#" & B2, " ", ""), ":", ""), "," ,""), "-", ""), "!", ""), "'", ""), ".", ""), "&", "and"), "+", "plus"), "\", ""), "(", ""), ")", "") -> # | P2: =Substitute(Substitute(Substitute(Substitute(Substitute(Substitute(Substitute(Substitute(Substitute(Substitute(Substitute(Substitute(Substitute("#" & B2 &E2, " ", ""), ":", ""), ",", ""), "/" ,""), "-", ""), "!", ""), "'", ""), ".", ""), "&", "and"), "+", "plus"), "\", ""), "(", ""), ")", "") -> # | R2: ="("""&B2&""") ("&Vlookup(E2,DropDown!R:V,5,FALSE)&IF(ISBLANK(D2)," | "," "&"OR """&YEAR(D2)&""" | ") & """All New"" | Episode | Watch | tv | Show | Series | season | binge | Stream | Film | Movie | Premiere | Screening | Feature | Trailer | Teaser | theater | release)" -> #N/A
G3: =VLOOKUP(E3,DropDown!J:K,2,FALSE) -> #N/A | K3: LF // Film - Majors + Independents | N3: ="("""&B3&""") ("&Vlookup(E3,DropDown!J:N,5,FALSE)&" OR """ &YEAR(D3) & """ OR ""All New"" OR Episode OR Watch OR tv OR Show OR Series OR season OR binge OR Stream OR Film OR Movie OR Premiere OR Screening OR Feature OR Trailer OR Teaser OR theater OR release)" -> #N/A | O3: =Substitute(Substitute(Substitute(Substitute(Substitute(Substitute(Substitute(Substitute(Substitute(Substitute(Substitute(Substitute("#" & B3, " ", ""), ":", ""), "," ,""), "-", ""), "!", ""), "'", ""), ".", ""), "&", "and"), "+", "plus"), "\", ""), "(", ""), ")", "") -> # | P3: =Substitute(Substitute(Substitute(Substitute(Substitute(Substitute(Substitute(Substitute(Substitute(Substitute(Substitute(Substitute(Substitute("#" & B3 &E3, " ", ""), ":", ""), ",", ""), "/" ,""), "-", ""), "!", ""), "'", ""), ".", ""), "&", "and"), "+", "plus"), "\", ""), "(", ""), ")", "") -> # | R3: ="("""&B3&""") ("&Vlookup(E3,DropDown!R:V,5,FALSE)&IF(ISBLANK(D3)," | "," "&"OR """&YEAR(D3)&""" | ") & """All New"" | Episode | Watch | tv | Show | Series | season | binge | Stream | Film | Movie | Premiere | Screening | Feature | Trailer | Teaser | theater | release)" -> #N/A
G4: =VLOOKUP(E4,DropDown!J:K,2,FALSE) -> #N/A | K4: LF // Film - Majors + Independents | N4: ="("""&B4&""") ("&Vlookup(E4,DropDown!J:N,5,FALSE)&" OR """ &YEAR(D4) & """ OR ""All New"" OR Episode OR Watch OR tv OR Show OR Series OR season OR binge OR Stream OR Film OR Movie OR Premiere OR Screening OR Feature OR Trailer OR Teaser OR theater OR release)" -> #N/A | O4: =Substitute(Substitute(Substitute(Substitute(Substitute(Substitute(Substitute(Substitute(Substitute(Substitute(Substitute(Substitute("#" & B4, " ", ""), ":", ""), "," ,""), "-", ""), "!", ""), "'", ""), ".", ""), "&", "and"), "+", "plus"), "\", ""), "(", ""), ")", "") -> # | P4: =Substitute(Substitute(Substitute(Substitute(Substitute(Substitute(Substitute(Substitute(Substitute(Substitute(Substitute(Substitute(Substitute("#" & B4 &E4, " ", ""), ":", ""), ",", ""), "/" ,""), "-", ""), "!", ""), "'", ""), ".", ""), "&", "and"), "+", "plus"), "\", ""), "(", ""), ")", "") -> # | R4: ="("""&B4&""") ("&Vlookup(E4,DropDown!R:V,5,FALSE)&IF(ISBLANK(D4)," | "," "&"OR """&YEAR(D4)&""" | ") & """All New"" | Episode | Watch | tv | Show | Series | season | binge | Stream | Film | Movie | Premiere | Screening | Feature | Trailer | Teaser | theater | release)" -> #N/A
G5: =VLOOKUP(E5,DropDown!J:K,2,FALSE) -> #N/A | K5: LF // Film - Majors + Independents | N5: ="("""&B5&""") ("&Vlookup(E5,DropDown!J:N,5,FALSE)&" OR """ &YEAR(D5) & """ OR ""All New"" OR Episode OR Watch OR tv OR Show OR Series OR season OR binge OR Stream OR Film OR Movie OR Premiere OR Screening OR Feature OR Trailer OR Teaser OR theater OR release)" -> #N/A | O5: =Substitute(Substitute(Substitute(Substitute(Substitute(Substitute(Substitute(Substitute(Substitute(Substitute(Substitute(Substitute("#" & B5, " ", ""), ":", ""), "," ,""), "-", ""), "!", ""), "'", ""), ".", ""), "&", "and"), "+", "plus"), "\", ""), "(", ""), ")", "") -> # | P5: =Substitute(Substitute(Substitute(Substitute(Substitute(Substitute(Substitute(Substitute(Substitute(Substitute(Substitute(Substitute(Substitute("#" & B5 &E5, " ", ""), ":", ""), ",", ""), "/" ,""), "-", ""), "!", ""), "'", ""), ".", ""), "&", "and"), "+", "plus"), "\", ""), "(", ""), ")", "") -> # | R5: ="("""&B5&""") ("&Vlookup(E5,DropDown!R:V,5,FALSE)&IF(ISBLANK(D5)," | "," "&"OR """&YEAR(D5)&""" | ") & """All New"" | Episode | Watch | tv | Show | Series | season | binge | Stream | Film | Movie | Premiere | Screening | Feature | Trailer | Teaser | theater | release)" -> #N/A
G6: =VLOOKUP(E6,DropDown!J:K,2,FALSE) -> #N/A | K6: LF // Film - Majors + Independents | N6: ="("""&B6&""") ("&Vlookup(E6,DropDown!J:N,5,FALSE)&" OR """ &YEAR(D6) & """ OR ""All New"" OR Episode OR Watch OR tv OR Show OR Series OR season OR binge OR Stream OR Film OR Movie OR Premiere OR Screening OR Feature OR Trailer OR Teaser OR theater OR release)" -> #N/A | O6: =Substitute(Substitute(Substitute(Substitute(Substitute(Substitute(Substitute(Substitute(Substitute(Substitute(Substitute(Substitute("#" & B6, " ", ""), ":", ""), "," ,""), "-", ""), "!", ""), "'", ""), ".", ""), "&", "and"), "+", "plus"), "\", ""), "(", ""), ")", "") -> # | P6: =Substitute(Substitute(Substitute(Substitute(Substitute(Substitute(Substitute(Substitute(Substitute(Substitute(Substitute(Substitute(Substitute("#" & B6 &E6, " ", ""), ":", ""), ",", ""), "/" ,""), "-", ""), "!", ""), "'", ""), ".", ""), "&", "and"), "+", "plus"), "\", ""), "(", ""), ")", "") -> # | R6: ="("""&B6&""") ("&Vlookup(E6,DropDown!R:V,5,FALSE)&IF(ISBLANK(D6)," | "," "&"OR """&YEAR(D6)&""" | ") & """All New"" | Episode | Watch | tv | Show | Series | season | binge | Stream | Film | Movie | Premiere | Screening | Feature | Trailer | Teaser | theater | release)" -> #N/A
G7: =VLOOKUP(E7,DropDown!J:K,2,FALSE) -> #N/A | K7: LF // Film - Majors + Independents | N7: ="("""&B7&""") ("&Vlookup(E7,DropDown!J:N,5,FALSE)&" OR """ &YEAR(D7) & """ OR ""All New"" OR Episode OR Watch OR tv OR Show OR Series OR season OR binge OR Stream OR Film OR Movie OR Premiere OR Screening OR Feature OR Trailer OR Teaser OR theater OR release)" -> #N/A | O7: =Substitute(Substitute(Substitute(Substitute(Substitute(Substitute(Substitute(Substitute(Substitute(Substitute(Substitute(Substitute("#" & B7, " ", ""), ":", ""), "," ,""), "-", ""), "!", ""), "'", ""), ".", ""), "&", "and"), "+", "plus"), "\", ""), "(", ""), ")", "") -> # | P7: =Substitute(Substitute(Substitute(Substitute(Substitute(Substitute(Substitute(Substitute(Substitute(Substitute(Substitute(Substitute(Substitute("#" & B7 &E7, " ", ""), ":", ""), ",", ""), "/" ,""), "-", ""), "!", ""), "'", ""), ".", ""), "&", "and"), "+", "plus"), "\", ""), "(", ""), ")", "") -> # | R7: ="("""&B7&""") ("&Vlookup(E7,DropDown!R:V,5,FALSE)&IF(ISBLANK(D7)," | "," "&"OR """&YEAR(D7)&""" | ") & """All New"" | Episode | Watch | tv | Show | Series | season | binge | Stream | Film | Movie | Premiere | Screening | Feature | Trailer | Teaser | theater | release)" -> #N/A
G8: =VLOOKUP(E8,DropDown!J:K,2,FALSE) -> #N/A | K8: LF // Film - Majors + Independents | N8: ="("""&B8&""") ("&Vlookup(E8,DropDown!J:N,5,FALSE)&" OR """ &YEAR(D8) & """ OR ""All New"" OR Episode OR Watch OR tv OR Show OR Series OR season OR binge OR Stream OR Film OR Movie OR Premiere OR Screening OR Feature OR Trailer OR Teaser OR theater OR release)" -> #N/A | O8: =Substitute(Substitute(Substitute(Substitute(Substitute(Substitute(Substitute(Substitute(Substitute(Substitute(Substitute(Substitute("#" & B8, " ", ""), ":", ""), "," ,""), "-", ""), "!", ""), "'", ""), ".", ""), "&", "and"), "+", "plus"), "\", ""), "(", ""), ")", "") -> # | P8: =Substitute(Substitute(Substitute(Substitute(Substitute(Substitute(Substitute(Substitute(Substitute(Substitute(Substitute(Substitute(Substitute("#" & B8 &E8, " ", ""), ":", ""), ",", ""), "/" ,""), "-", ""), "!", ""), "'", ""), ".", ""), "&", "and"), "+", "plus"), "\", ""), "(", ""), ")", "") -> # | R8: ="("""&B8&""") ("&Vlookup(E8,DropDown!R:V,5,FALSE)&IF(ISBLANK(D8)," | "," "&"OR """&YEAR(D8)&""" | ") & """All New"" | Episode | Watch | tv | Show | Series | season | binge | Stream | Film | Movie | Premiere | Screening | Feature | Trailer | Teaser | theater | release)" -> #N/A
G9: =VLOOKUP(E9,DropDown!J:K,2,FALSE) -> #N/A | K9: LF // Film - Majors + Independents | N9: ="("""&B9&""") ("&Vlookup(E9,DropDown!J:N,5,FALSE)&" OR """ &YEAR(D9) & """ OR ""All New"" OR Episode OR Watch OR tv OR Show OR Series OR season OR binge OR Stream OR Film OR Movie OR Premiere OR Screening OR Feature OR Trailer OR Teaser OR theater OR release)" -> #N/A | O9: =Substitute(Substitute(Substitute(Substitute(Substitute(Substitute(Substitute(Substitute(Substitute(Substitute(Substitute(Substitute("#" & B9, " ", ""), ":", ""), "," ,""), "-", ""), "!", ""), "'", ""), ".", ""), "&", "and"), "+", "plus"), "\", ""), "(", ""), ")", "") -> # | P9: =Substitute(Substitute(Substitute(Substitute(Substitute(Substitute(Substitute(Substitute(Substitute(Substitute(Substitute(Substitute(Substitute("#" & B9 &E9, " ", ""), ":", ""), ",", ""), "/" ,""), "-", ""), "!", ""), "'", ""), ".", ""), "&", "and"), "+", "plus"), "\", ""), "(", ""), ")", "") -> # | R9: ="("""&B9&""") ("&Vlookup(E9,DropDown!R:V,5,FALSE)&IF(ISBLANK(D9)," | "," "&"OR """&YEAR(D9)&""" | ") & """All New"" | Episode | Watch | tv | Show | Series | season | binge | Stream | Film | Movie | Premiere | Screening | Feature | Trailer | Teaser | theater | release)" -> #N/A
G10: =VLOOKUP(E10,DropDown!J:K,2,FALSE) -> #N/A | K10: LF // Film - Majors + Independents | N10: ="("""&B10&""") ("&Vlookup(E10,DropDown!J:N,5,FALSE)&" OR """ &YEAR(D10) & """ OR ""All New"" OR Episode OR Watch OR tv OR Show OR Series OR season OR binge OR Stream OR Film OR Movie OR Premiere OR Screening OR Feature OR Trailer OR Teaser OR theater OR release)" -> #N/A | O10: =Substitute(Substitute(Substitute(Substitute(Substitute(Substitute(Substitute(Substitute(Substitute(Substitute(Substitute(Substitute("#" & B10, " ", ""), ":", ""), "," ,""), "-", ""), "!", ""), "'", ""), ".", ""), "&", "and"), "+", "plus"), "\", ""), "(", ""), ")", "") -> # | P10: =Substitute(Substitute(Substitute(Substitute(Substitute(Substitute(Substitute(Substitute(Substitute(Substitute(Substitute(Substitute(Substitute("#" & B10 &E10, " ", ""), ":", ""), ",", ""), "/" ,""), "-", ""), "!", ""), "'", ""), ".", ""), "&", "and"), "+", "plus"), "\", ""), "(", ""), ")", "") -> # | R10: ="("""&B10&""") ("&Vlookup(E10,DropDown!R:V,5,FALSE)&IF(ISBLANK(D10)," | "," "&"OR """&YEAR(D10)&""" | ") & """All New"" | Episode | Watch | tv | Show | Series | season | binge | Stream | Film | Movie | Premiere | Screening | Feature | Trailer | Teaser | theater | release)" -> #N/A
G11: =VLOOKUP(E11,DropDown!J:K,2,FALSE) -> #N/A | K11: LF // Film - Majors + Independents | N11: ="("""&B11&""") ("&Vlookup(E11,DropDown!J:N,5,FALSE)&" OR """ &YEAR(D11) & """ OR ""All New"" OR Episode OR Watch OR tv OR Show OR Series OR season OR binge OR Stream OR Film OR Movie OR Premiere OR Screening OR Feature OR Trailer OR Teaser OR theater OR release)" -> #N/A | O11: =Substitute(Substitute(Substitute(Substitute(Substitute(Substitute(Substitute(Substitute(Substitute(Substitute(Substitute(Substitute("#" & B11, " ", ""), ":", ""), "," ,""), "-", ""), "!", ""), "'", ""), ".", ""), "&", "and"), "+", "plus"), "\", ""), "(", ""), ")", "") -> # | P11: =Substitute(Substitute(Substitute(Substitute(Substitute(Substitute(Substitute(Substitute(Substitute(Substitute(Substitute(Substitute(Substitute("#" & B11 &E11, " ", ""), ":", ""), ",", ""), "/" ,""), "-", ""), "!", ""), "'", ""), ".", ""), "&", "and"), "+", "plus"), "\", ""), "(", ""), ")", "") -> # | R11: ="("""&B11&""") ("&Vlookup(E11,DropDown!R:V,5,FALSE)&IF(ISBLANK(D11)," | "," "&"OR """&YEAR(D11)&""" | ") & """All New"" | Episode | Watch | tv | Show | Series | season | binge | Stream | Film | Movie | Premiere | Screening | Feature | Trailer | Teaser | theater | release)" -> #N/A
G12: =VLOOKUP(E12,DropDown!J:K,2,FALSE) -> #N/A | K12: LF // Film - Majors + Independents | N12: ="("""&B12&""") ("&Vlookup(E12,DropDown!J:N,5,FALSE)&IF(ISBLANK(D12)," OR "," "&"OR """&YEAR(D12)&""" OR ") & """All New"" OR Episode OR Watch OR tv OR Show OR Series OR season OR binge OR Stream OR Film OR Movie OR Premiere OR Screening OR Feature OR Trailer OR Teaser OR theater OR release)" -> #N/A | O12: =Substitute(Substitute(Substitute(Substitute(Substitute(Substitute(Substitute(Substitute(Substitute(Substitute(Substitute(Substitute("#" & B12, " ", ""), ":", ""), "," ,""), "-", ""), "!", ""), "'", ""), ".", ""), "&", "and"), "+", "plus"), "\", ""), "(", ""), ")", "") -> # | P12: =Substitute(Substitute(Substitute(Substitute(Substitute(Substitute(Substitute(Substitute(Substitute(Substitute(Substitute(Substitute(Substitute("#" & B12 &E12, " ", ""), ":", ""), ",", ""), "/" ,""), "-", ""), "!", ""), "'", ""), ".", ""), "&", "and"), "+", "plus"), "\", ""), "(", ""), ")", "") -> # | R12: ="("""&B12&""") ("&Vlookup(E12,DropDown!R:V,5,FALSE)&IF(ISBLANK(D12)," | "," "&"OR """&YEAR(D12)&""" | ") & """All New"" | Episode | Watch | tv | Show | Series | season | binge | Stream | Film | Movie | Premiere | Screening | Feature | Trailer | Teaser | theater | release)" -> #N/A
G13: =VLOOKUP(E13,DropDown!J:K,2,FALSE) -> #N/A | K13: LF // Film - Majors + Independents | N13: ="("""&B13&""") ("&Vlookup(E13,DropDown!J:N,5,FALSE)&" OR """ &YEAR(D13) & """ OR ""All New"" OR Episode OR Watch OR tv OR Show OR Series OR season OR binge OR Stream OR Film OR Movie OR Premiere OR Screening OR Feature OR Trailer OR Teaser OR theater OR release)" -> #N/A | O13: =Substitute(Substitute(Substitute(Substitute(Substitute(Substitute(Substitute(Substitute(Substitute(Substitute(Substitute(Substitute("#" & B13, " ", ""), ":", ""), "," ,""), "-", ""), "!", ""), "'", ""), ".", ""), "&", "and"), "+", "plus"), "\", ""), "(", ""), ")", "") -> # | P13: =Substitute(Substitute(Substitute(Substitute(Substitute(Substitute(Substitute(Substitute(Substitute(Substitute(Substitute(Substitute(Substitute("#" & B13 &E13, " ", ""), ":", ""), ",", ""), "/" ,""), "-", ""), "!", ""), "'", ""), ".", ""), "&", "and"), "+", "plus"), "\", ""), "(", ""), ")", "") -> # | R13: ="("""&B13&""") ("&Vlookup(E13,DropDown!R:V,5,FALSE)&IF(ISBLANK(D13)," | "," "&"OR """&YEAR(D13)&""" | ") & """All New"" | Episode | Watch | tv | Show | Series | season | binge | Stream | Film | Movie | Premiere | Screening | Feature | Trailer | Teaser | theater | release)" -> #N/A
G14: =VLOOKUP(E14,DropDown!J:K,2,FALSE) -> #N/A | K14: LF // Film - Majors + Independents | N14: ="("""&B14&""") ("&Vlookup(E14,DropDown!J:N,5,FALSE)&" OR """ &YEAR(D14) & """ OR ""All New"" OR Episode OR Watch OR tv OR Show OR Series OR season OR binge OR Stream OR Film OR Movie OR Premiere OR Screening OR Feature OR Trailer OR Teaser OR theater OR release)" -> #N/A | O14: =Substitute(Substitute(Substitute(Substitute(Substitute(Substitute(Substitute(Substitute(Substitute(Substitute(Substitute(Substitute("#" & B14, " ", ""), ":", ""), "," ,""), "-", ""), "!", ""), "'", ""), ".", ""), "&", "and"), "+", "plus"), "\", ""), "(", ""), ")", "") -> # | P14: =Substitute(Substitute(Substitute(Substitute(Substitute(Substitute(Substitute(Substitute(Substitute(Substitute(Substitute(Substitute(Substitute("#" & B14 &E14, " ", ""), ":", ""), ",", ""), "/" ,""), "-", ""), "!", ""), "'", ""), ".", ""), "&", "and"), "+", "plus"), "\", ""), "(", ""), ")", "") -> # | R14: ="("""&B14&""") ("&Vlookup(E14,DropDown!R:V,5,FALSE)&IF(ISBLANK(D14)," | "," "&"OR """&YEAR(D14)&""" | ") & """All New"" | Episode | Watch | tv | Show | Series | season | binge | Stream | Film | Movie | Premiere | Screening | Feature | Trailer | Teaser | theater | release)" -> #N/A
G15: =VLOOKUP(E15,DropDown!J:K,2,FALSE) -> #N/A | K15: LF // Film - Majors + Independents | N15: ="("""&B15&""") ("&Vlookup(E15,DropDown!J:N,5,FALSE)&" OR """ &YEAR(D15) & """ OR ""All New"" OR Episode OR Watch OR tv OR Show OR Series OR season OR binge OR Stream OR Film OR Movie OR Premiere OR Screening OR Feature OR Trailer OR Teaser OR theater OR release)" -> #N/A | O15: =Substitute(Substitute(Substitute(Substitute(Substitute(Substitute(Substitute(Substitute(Substitute(Substitute(Substitute(Substitute("#" & B15, " ", ""), ":", ""), "," ,""), "-", ""), "!", ""), "'", ""), ".", ""), "&", "and"), "+", "plus"), "\", ""), "(", ""), ")", "") -> # | P15: =Substitute(Substitute(Substitute(Substitute(Substitute(Substitute(Substitute(Substitute(Substitute(Substitute(Substitute(Substitute(Substitute("#" & B15 &E15, " ", ""), ":", ""), ",", ""), "/" ,""), "-", ""), "!", ""), "'", ""), ".", ""), "&", "and"), "+", "plus"), "\", ""), "(", ""), ")", "") -> # | R15: ="("""&B15&""") ("&Vlookup(E15,DropDown!R:V,5,FALSE)&IF(ISBLANK(D15)," | "," "&"OR """&YEAR(D15)&""" | ") & """All New"" | Episode | Watch | tv | Show | Series | season | binge | Stream | Film | Movie | Premiere | Screening | Feature | Trailer | Teaser | theater | release)" -> #N/A
G16: =VLOOKUP(E16,DropDown!J:K,2,FALSE) -> #N/A | K16: LF // Film - Majors + Independents | N16: ="("""&B16&""") ("&Vlookup(E16,DropDown!J:N,5,FALSE)&" OR """ &YEAR(D16) & """ OR ""All New"" OR Episode OR Watch OR tv OR Show OR Series OR season OR binge OR Stream OR Film OR Movie OR Premiere OR Screening OR Feature OR Trailer OR Teaser OR theater OR release)" -> #N/A | O16: =Substitute(Substitute(Substitute(Substitute(Substitute(Substitute(Substitute(Substitute(Substitute(Substitute(Substitute(Substitute("#" & B16, " ", ""), ":", ""), "," ,""), "-", ""), "!", ""), "'", ""), ".", ""), "&", "and"), "+", "plus"), "\", ""), "(", ""), ")", "") -> # | P16: =Substitute(Substitute(Substitute(Substitute(Substitute(Substitute(Substitute(Substitute(Substitute(Substitute(Substitute(Substitute(Substitute("#" & B16 &E16, " ", ""), ":", ""), ",", ""), "/" ,""), "-", ""), "!", ""), "'", ""), ".", ""), "&", "and"), "+", "plus"), "\", ""), "(", ""), ")", "") -> # | R16: ="("""&B16&""") ("&Vlookup(E16,DropDown!R:V,5,FALSE)&IF(ISBLANK(D16)," | "," "&"OR """&YEAR(D16)&""" | ") & """All New"" | Episode | Watch | tv | Show | Series | season | binge | Stream | Film | Movie | Premiere | Screening | Feature | Trailer | Teaser | theater | release)" -> #N/A
G17: =VLOOKUP(E17,DropDown!J:K,2,FALSE) -> #N/A | K17: LF // Film - Majors + Independents | N17: ="("""&B17&""") ("&Vlookup(E17,DropDown!J:N,5,FALSE)&" OR """ &YEAR(D17) & """ OR ""All New"" OR Episode OR Watch OR tv OR Show OR Series OR season OR binge OR Stream OR Film OR Movie OR Premiere OR Screening OR Feature OR Trailer OR Teaser OR theater OR release)" -> #N/A | O17: =Substitute(Substitute(Substitute(Substitute(Substitute(Substitute(Substitute(Substitute(Substitute(Substitute(Substitute(Substitute("#" & B17, " ", ""), ":", ""), "," ,""), "-", ""), "!", ""), "'", ""), ".", ""), "&", "and"), "+", "plus"), "\", ""), "(", ""), ")", "") -> # | P17: =Substitute(Substitute(Substitute(Substitute(Substitute(Substitute(Substitute(Substitute(Substitute(Substitute(Substitute(Substitute(Substitute("#" & B17 &E17, " ", ""), ":", ""), ",", ""), "/" ,""), "-", ""), "!", ""), "'", ""), ".", ""), "&", "and"), "+", "plus"), "\", ""), "(", ""), ")", "") -> # | R17: ="("""&B17&""") ("&Vlookup(E17,DropDown!R:V,5,FALSE)&IF(ISBLANK(D17)," | "," "&"OR """&YEAR(D17)&""" | ") & """All New"" | Episode | Watch | tv | Show | Series | season | binge | Stream | Film | Movie | Premiere | Screening | Feature | Trailer | Teaser | theater | release)" -> #N/A
G18: =VLOOKUP(E18,DropDown!J:K,2,FALSE) -> #N/A | K18: LF // Film - Majors + Independents | N18: ="("""&B18&""") ("&Vlookup(E18,DropDown!J:N,5,FALSE)&" OR """ &YEAR(D18) & """ OR ""All New"" OR Episode OR Watch OR tv OR Show OR Series OR season OR binge OR Stream OR Film OR Movie OR Premiere OR Screening OR Feature OR Trailer OR Teaser OR theater OR release)" -> #N/A | O18: =Substitute(Substitute(Substitute(Substitute(Substitute(Substitute(Substitute(Substitute(Substitute(Substitute(Substitute(Substitute("#" & B18, " ", ""), ":", ""), "," ,""), "-", ""), "!", ""), "'", ""), ".", ""), "&", "and"), "+", "plus"), "\", ""), "(", ""), ")", "") -> # | P18: =Substitute(Substitute(Substitute(Substitute(Substitute(Substitute(Substitute(Substitute(Substitute(Substitute(Substitute(Substitute(Substitute("#" & B18 &E18, " ", ""), ":", ""), ",", ""), "/" ,""), "-", ""), "!", ""), "'", ""), ".", ""), "&", "and"), "+", "plus"), "\", ""), "(", ""), ")", "") -> # | R18: ="("""&B18&""") ("&Vlookup(E18,DropDown!R:V,5,FALSE)&IF(ISBLANK(D18)," | "," "&"OR """&YEAR(D18)&""" | ") & """All New"" | Episode | Watch | tv | Show | Series | season | binge | Stream | Film | Movie | Premiere | Screening | Feature | Trailer | Teaser | theater | release)" -> #N/A
G19: =VLOOKUP(E19,DropDown!J:K,2,FALSE) -> #N/A | K19: LF // Film - Majors + Independents | N19: ="("""&B19&""") ("&Vlookup(E19,DropDown!J:N,5,FALSE)&" OR """ &YEAR(D19) & """ OR ""All New"" OR Episode OR Watch OR tv OR Show OR Series OR season OR binge OR Stream OR Film OR Movie OR Premiere OR Screening OR Feature OR Trailer OR Teaser OR theater OR release)" -> #N/A | O19: =Substitute(Substitute(Substitute(Substitute(Substitute(Substitute(Substitute(Substitute(Substitute(Substitute(Substitute(Substitute("#" & B19, " ", ""), ":", ""), "," ,""), "-", ""), "!", ""), "'", ""), ".", ""), "&", "and"), "+", "plus"), "\", ""), "(", ""), ")", "") -> # | P19: =Substitute(Substitute(Substitute(Substitute(Substitute(Substitute(Substitute(Substitute(Substitute(Substitute(Substitute(Substitute(Substitute("#" & B19 &E19, " ", ""), ":", ""), ",", ""), "/" ,""), "-", ""), "!", ""), "'", ""), ".", ""), "&", "and"), "+", "plus"), "\", ""), "(", ""), ")", "") -> # | R19: ="("""&B19&""") ("&Vlookup(E19,DropDown!R:V,5,FALSE)&IF(ISBLANK(D19)," | "," "&"OR """&YEAR(D19)&""" | ") & """All New"" | Episode | Watch | tv | Show | Series | season | binge | Stream | Film | Movie | Premiere | Screening | Feature | Trailer | Teaser | theater | release)" -> #N/A
G20: =VLOOKUP(E20,DropDown!J:K,2,FALSE) -> #N/A | K20: LF // Film - Majors + Independents | N20: ="("""&B20&""") ("&Vlookup(E20,DropDown!J:N,5,FALSE)&IF(ISBLANK(D20)," OR "," "&"OR """&YEAR(D20)&""" OR ") & """All New"" OR Episode OR Watch OR tv OR Show OR Series OR season OR binge OR Stream OR Film OR Movie OR Premiere OR Screening OR Feature OR Trailer OR Teaser OR theater OR release)" -> #N/A | O20: =Substitute(Substitute(Substitute(Substitute(Substitute(Substitute(Substitute(Substitute(Substitute(Substitute(Substitute(Substitute("#" & B20, " ", ""), ":", ""), "," ,""), "-", ""), "!", ""), "'", ""), ".", ""), "&", "and"), "+", "plus"), "\", ""), "(", ""), ")", "") -> # | P20: =Substitute(Substitute(Substitute(Substitute(Substitute(Substitute(Substitute(Substitute(Substitute(Substitute(Substitute(Substitute(Substitute("#" & B20 &E20, " ", ""), ":", ""), ",", ""), "/" ,""), "-", ""), "!", ""), "'", ""), ".", ""), "&", "and"), "+", "plus"), "\", ""), "(", ""), ")", "") -> # | R20: ="("""&B20&""") ("&Vlookup(E20,DropDown!R:V,5,FALSE)&IF(ISBLANK(D20)," | "," "&"OR """&YEAR(D20)&""" | ") & """All New"" | Episode | Watch | tv | Show | Series | season | binge | Stream | Film | Movie | Premiere | Screening | Feature | Trailer | Teaser | theater | release)" -> #N/A
