Workbook

Sheet BDR
A1: brand_id | B1: title | C1: title_category | D1: title_sub_category | E1: genre | F1: primary_genre | G1: rovi_id | H1: ticker_symbol | I1: title_content_windows | J1: companies | K1: brand_set | L1: active | M1: released_on | N1: box_office | O1: street_date | P1: gross_screen | Q1: opening_weekend_box_office | R1: network | S1: brand_listing_hidden | T1: facebook_page | U1: twitter_handle | V1: instagram_user | W1: youtube_channel_username | X1: tiktok_user | Y1: tumblr_page | Z1: pinterest_user_username | AA1: pinterest_board | AB1: wikipedia_page | AC1: rottentomatoes | AD1: imdb_id | AE1: metacritic | AF1: facebook_search_terms | AG1: twitter_search_terms | AH1: instagram_search_terms | AI1: tumblr_search_terms | AJ1: twitter_search_term_keywords | AK1: youtube_search_terms | AL1: reddit_search_terms | AM1: url_managers
B2: ='Ingest Template'!C2&IF('Ingest Template'!A2 = "Standard", " - DAR","") | C2: TV Shows | D2: {=CONCATENATE(INDEX(DropdownLists!$H$2:$H$11,MATCH(1,COUNTIF('Ingest Template'!E2,"*"&DropdownLists!$I$2:$I$11&"*"),0)),CHAR(10),'Ingest Template'!F2,CHAR(10),'Ingest Template'!G2,CHAR(10),VLOOKUP('Ingest Template'!D2,DropdownLists!C:D,2,FALSE))} -> #N/A | E2: =CONCATENATE('Ingest Template'!H2,CHAR(10),'Ingest Template'!I2,CHAR(10),'Ingest Template'!J2,CHAR(10)) | F2: {=INDEX(DropdownLists!$O$2:$O$36,MATCH(1,COUNTIF(E2,"*"&DropdownLists!$N$2:$N$36&"*"),0))} | H2: {=INDEX(DropdownLists!$E$2:$E$276,MATCH('Ingest Template'!D2,DropdownLists!$C$2:$C$276,0))} -> #N/A | J2: {=iF('Ingest Template'!A2="Standard","Pristine Brand",INDEX(DropdownLists!$B$2:$B$246,MATCH('Ingest Template'!D2,DropdownLists!$C$2:$C$246,0)))} -> #N/A | K2: =iF('Ingest Template'!A2="Standard",'Ingest Template'!K2&CHAR(10)&'Ingest Template'!L2,"Competitive View") -> Competitive View | L2: t | M2: ='Ingest Template'!B2 | R2: ='Ingest Template'!D2 | S2: f | T2: ='Ingest Template'!V2 | U2: ='Ingest Template'!W2 | V2: =LOWER(SUBSTITUTE(SUBSTITUTE(SUBSTITUTE(SUBSTITUTE(SUBSTITUTE('Ingest Template'!X2,"https:",""),"www.",""),"/",""),"?hl=en",""),"instagram.com","")) | W2: {=IF( 'Ingest Template'!Y2="", SUBSTITUTE( INDEX(DropdownLists!$F$2:$F$277,MATCH('Ingest Template'!D2,DropdownLists!$C$2:$C$277,0)), CHAR(10), "|"&'Ingest Template'!C2&CHAR(10) )&"|"&'Ingest Template'!C2, SUBSTITUTE( INDEX(DropdownLists!$F$2:$F$277,MATCH('Ingest Template'!D2,DropdownLists!$C$2:$C$277,0)), CHAR(10), "|"&'Ingest Template'!C2&CHAR(10) )&"|"&'Ingest Template'!C2&CHAR(10)&'Ingest Template'!Y2 )} -> #N/A | X2: ='Ingest Template'!Z2 | Y2: =SUBSTITUTE(SUBSTITUTE(SUBSTITUTE('Ingest Template'!AA2,"http:",""),"https:",""),"/","") | Z2: {=IF('Ingest Template'!A2="Standard",(IF(ISBLANK('Ingest Template'!AB2),"", 'Ingest Template'!AB2&"|DAR")),(IF(ISBLANK('Ingest Template'!AB2),"", 'Ingest Template'!AB2&"|TV Ops")))} | AB2: ='Ingest Template'!R2 | AC2: ='Ingest Template'!T2 | AD2: ='Ingest Template'!S2 | AE2: ='Ingest Template'!U2 | AG2: {=IF('Ingest Template'!A2="Standard",(CONCATENATE(IF(ISBLANK('Ingest Template'!N2),"", 'Ingest Template'!N2&"|DAR"),CHAR(10), IF(ISBLANK('Ingest Template'!O2),"", 'Ingest Template'!O2&"|DAR"),CHAR(10), IF(ISBLANK('Ingest Template'!P2),"", 'Ingest Template'!P2&"|DAR"))),(CONCATENATE(IF(ISBLANK('Ingest Template'!N2),"", 'Ingest Template'!N2&"|TV Ops"),CHAR(10), IF(ISBLANK('Ingest Template'!O2),"", 'Ingest Template'!O2&"|TV Ops"),CHAR(10), IF(ISBLANK('Ingest Template'!P2),"", 'Ingest Template'!P2&"|TV Ops"))))} | AJ2: =if('Ingest Template'!A2="Standard",(IF(OR('Ingest Template'!F2 = "Program Type - Special", 'Ingest Template'!F2 = "Program Type - Live Event"),'Ingest Template'!M2& "|DAR|DAR|"&TEXT('Ingest Template'!C2-3, "yyyy-mm-dd")&"|"&TEXT('Ingest Template'!C2+3, "yyyy-mm-dd"),'Ingest Template'!M2& "|DAR|DAR|2021-01-01")),(IF(OR('Ingest Template'!F2 = "Program Type - Special", 'Ingest Template'!F2 = "Program Type - Live Event"),'Ingest Template'!M2& "|Operations - Core Title|Operations - Core Title|"&TEXT('Ingest Template'!C2-3, "yyyy-mm-dd")&"|"&TEXT('Ingest Template'!C2+3, "yyyy-mm-dd"),'Ingest Template'!M2& "|Operations - Core Title|Operations - Core Title"))) -> |Operations - Core Title|Operations - Core Title | AL2: =if('Ingest Template'!A2="Standard",(IF(OR('Ingest Template'!F2 = "Program Type - Special", 'Ingest Template'!F2 = "Program Type - Live Event"),'Ingest Template'!Q2&"|"&TEXT('Ingest Template'!C2-3, "yyyy-mm-dd")&"|"&TEXT('Ingest Template'!C2+3, "yyyy-mm-dd"),'Ingest Template'!Q2& "|2021-01-01")),(IF(OR('Ingest Template'!F2 = "Program Type - Special", 'Ingest Template'!F2 = "Program Type - Live Event"),'Ingest Template'!Q2& "|"&TEXT('Ingest Template'!C2-3, "yyyy-mm-dd")&"|"&TEXT('Ingest Template'!C2+3, "yyyy-mm-dd"),'Ingest Template'!Q2))) | AM2: ='Ingest Template'!AC2
B3: ='Ingest Template'!C3&IF('Ingest Template'!A3 = "Standard", " - DAR","") | C3: TV Shows | D3: {=CONCATENATE(INDEX(DropdownLists!$H$2:$H$11,MATCH(1,COUNTIF('Ingest Template'!E3,"*"&DropdownLists!$I$2:$I$11&"*"),0)),CHAR(10),'Ingest Template'!F3,CHAR(10),'Ingest Template'!G3,CHAR(10),VLOOKUP('Ingest Template'!D3,DropdownLists!C:D,2,FALSE))} -> #N/A | E3: =CONCATENATE('Ingest Template'!H3,CHAR(10),'Ingest Template'!I3,CHAR(10),'Ingest Template'!J3,CHAR(10)) | F3: {=INDEX(DropdownLists!$O$2:$O$36,MATCH(1,COUNTIF(E3,"*"&DropdownLists!$N$2:$N$36&"*"),0))} | H3: {=INDEX(DropdownLists!$E$2:$E$276,MATCH('Ingest Template'!D3,DropdownLists!$C$2:$C$276,0))} -> #N/A | J3: {=iF('Ingest Template'!A3="Standard","Pristine Brand",INDEX(DropdownLists!$B$2:$B$246,MATCH('Ingest Template'!D3,DropdownLists!$C$2:$C$246,0)))} -> #N/A | K3: =iF('Ingest Template'!A3="Standard",'Ingest Template'!K3&CHAR(10)&'Ingest Template'!L3,"Competitive View") -> Competitive View | L3: t | M3: ='Ingest Template'!B3 | R3: ='Ingest Template'!D3 | S3: f | T3: ='Ingest Template'!V3 | U3: ='Ingest Template'!W3 | V3: =LOWER(SUBSTITUTE(SUBSTITUTE(SUBSTITUTE(SUBSTITUTE(SUBSTITUTE('Ingest Template'!X3,"https:",""),"www.",""),"/",""),"?hl=en",""),"instagram.com","")) | W3: {=IF( 'Ingest Template'!Y3="", SUBSTITUTE( INDEX(DropdownLists!$F$2:$F$277,MATCH('Ingest Template'!D3,DropdownLists!$C$2:$C$277,0)), CHAR(10), "|"&'Ingest Template'!C3&CHAR(10) )&"|"&'Ingest Template'!C3, SUBSTITUTE( INDEX(DropdownLists!$F$2:$F$277,MATCH('Ingest Template'!D3,DropdownLists!$C$2:$C$277,0)), CHAR(10), "|"&'Ingest Template'!C3&CHAR(10) )&"|"&'Ingest Template'!C3&CHAR(10)&'Ingest Template'!Y3 )} -> #N/A | X3: ='Ingest Template'!Z3 | Y3: =SUBSTITUTE(SUBSTITUTE(SUBSTITUTE('Ingest Template'!AA3,"http:",""),"https:",""),"/","") | Z3: {=IF('Ingest Template'!A3="Standard",(IF(ISBLANK('Ingest Template'!AB3),"", 'Ingest Template'!AB3&"|DAR")),(IF(ISBLANK('Ingest Template'!AB3),"", 'Ingest Template'!AB3&"|TV Ops")))} | AB3: ='Ingest Template'!R3 | AC3: ='Ingest Template'!T3 | AD3: ='Ingest Template'!S3 | AE3: ='Ingest Template'!U3 | AG3: {=IF('Ingest Template'!A3="Standard",(CONCATENATE(IF(ISBLANK('Ingest Template'!N3),"", 'Ingest Template'!N3&"|DAR"),CHAR(10), IF(ISBLANK('Ingest Template'!O3),"", 'Ingest Template'!O3&"|DAR"),CHAR(10), IF(ISBLANK('Ingest Template'!P3),"", 'Ingest Template'!P3&"|DAR"))),(CONCATENATE(IF(ISBLANK('Ingest Template'!N3),"", 'Ingest Template'!N3&"|TV Ops"),CHAR(10), IF(ISBLANK('Ingest Template'!O3),"", 'Ingest Template'!O3&"|TV Ops"),CHAR(10), IF(ISBLANK('Ingest Template'!P3),"", 'Ingest Template'!P3&"|TV Ops"))))} | AJ3: =if('Ingest Template'!A3="Standard",(IF(OR('Ingest Template'!F3 = "Program Type - Special", 'Ingest Template'!F3 = "Program Type - Live Event"),'Ingest Template'!M3& "|DAR|DAR|"&TEXT('Ingest Template'!C3-3, "yyyy-mm-dd")&"|"&TEXT('Ingest Template'!C3+3, "yyyy-mm-dd"),'Ingest Template'!M3& "|DAR|DAR|2021-01-01")),(IF(OR('Ingest Template'!F3 = "Program Type - Special", 'Ingest Template'!F3 = "Program Type - Live Event"),'Ingest Template'!M3& "|Operations - Core Title|Operations - Core Title|"&TEXT('Ingest Template'!C3-3, "yyyy-mm-dd")&"|"&TEXT('Ingest Template'!C3+3, "yyyy-mm-dd"),'Ingest Template'!M3& "|Operations - Core Title|Operations - Core Title"))) -> |Operations - Core Title|Operations - Core Title | AL3: =if('Ingest Template'!A3="Standard",(IF(OR('Ingest Template'!F3 = "Program Type - Special", 'Ingest Template'!F3 = "Program Type - Live Event"),'Ingest Template'!Q3&"|"&TEXT('Ingest Template'!C3-3, "yyyy-mm-dd")&"|"&TEXT('Ingest Template'!C3+3, "yyyy-mm-dd"),'Ingest Template'!Q3& "|2021-01-01")),(IF(OR('Ingest Template'!F3 = "Program Type - Special", 'Ingest Template'!F3 = "Program Type - Live Event"),'Ingest Template'!Q3& "|"&TEXT('Ingest Template'!C3-3, "yyyy-mm-dd")&"|"&TEXT('Ingest Template'!C3+3, "yyyy-mm-dd"),'Ingest Template'!Q3))) | AM3: ='Ingest Template'!AC3
B4: ='Ingest Template'!C4&IF('Ingest Template'!A4 = "Standard", " - DAR","") | C4: TV Shows | D4: {=CONCATENATE(INDEX(DropdownLists!$H$2:$H$11,MATCH(1,COUNTIF('Ingest Template'!E4,"*"&DropdownLists!$I$2:$I$11&"*"),0)),CHAR(10),'Ingest Template'!F4,CHAR(10),'Ingest Template'!G4,CHAR(10),VLOOKUP('Ingest Template'!D4,DropdownLists!C:D,2,FALSE))} -> #N/A | E4: =CONCATENATE('Ingest Template'!H4,CHAR(10),'Ingest Template'!I4,CHAR(10),'Ingest Template'!J4,CHAR(10)) | F4: {=INDEX(DropdownLists!$O$2:$O$36,MATCH(1,COUNTIF(E4,"*"&DropdownLists!$N$2:$N$36&"*"),0))} | H4: {=INDEX(DropdownLists!$E$2:$E$276,MATCH('Ingest Template'!D4,DropdownLists!$C$2:$C$276,0))} -> #N/A | J4: {=iF('Ingest Template'!A4="Standard","Pristine Brand",INDEX(DropdownLists!$B$2:$B$246,MATCH('Ingest Template'!D4,DropdownLists!$C$2:$C$246,0)))} -> #N/A | K4: =iF('Ingest Template'!A4="Standard",'Ingest Template'!K4&CHAR(10)&'Ingest Template'!L4,"Competitive View") -> Competitive View | L4: t | M4: ='Ingest Template'!B4 | R4: ='Ingest Template'!D4 | S4: f | T4: ='Ingest Template'!V4 | U4: ='Ingest Template'!W4 | V4: =LOWER(SUBSTITUTE(SUBSTITUTE(SUBSTITUTE(SUBSTITUTE(SUBSTITUTE('Ingest Template'!X4,"https:",""),"www.",""),"/",""),"?hl=en",""),"instagram.com","")) | W4: {=IF( 'Ingest Template'!Y4="", SUBSTITUTE( INDEX(DropdownLists!$F$2:$F$277,MATCH('Ingest Template'!D4,DropdownLists!$C$2:$C$277,0)), CHAR(10), "|"&'Ingest Template'!C4&CHAR(10) )&"|"&'Ingest Template'!C4, SUBSTITUTE( INDEX(DropdownLists!$F$2:$F$277,MATCH('Ingest Template'!D4,DropdownLists!$C$2:$C$277,0)), CHAR(10), "|"&'Ingest Template'!C4&CHAR(10) )&"|"&'Ingest Template'!C4&CHAR(10)&'Ingest Template'!Y4 )} -> #N/A | X4: ='Ingest Template'!Z4 | Y4: =SUBSTITUTE(SUBSTITUTE(SUBSTITUTE('Ingest Template'!AA4,"http:",""),"https:",""),"/","") | Z4: {=IF('Ingest Template'!A4="Standard",(IF(ISBLANK('Ingest Template'!AB4),"", 'Ingest Template'!AB4&"|DAR")),(IF(ISBLANK('Ingest Template'!AB4),"", 'Ingest Template'!AB4&"|TV Ops")))} | AB4: ='Ingest Template'!R4 | AC4: ='Ingest Template'!T4 | AD4: ='Ingest Template'!S4 | AE4: ='Ingest Template'!U4 | AG4: {=IF('Ingest Template'!A4="Standard",(CONCATENATE(IF(ISBLANK('Ingest Template'!N4),"", 'Ingest Template'!N4&"|DAR"),CHAR(10), IF(ISBLANK('Ingest Template'!O4),"", 'Ingest Template'!O4&"|DAR"),CHAR(10), IF(ISBLANK('Ingest Template'!P4),"", 'Ingest Template'!P4&"|DAR"))),(CONCATENATE(IF(ISBLANK('Ingest Template'!N4),"", 'Ingest Template'!N4&"|TV Ops"),CHAR(10), IF(ISBLANK('Ingest Template'!O4),"", 'Ingest Template'!O4&"|TV Ops"),CHAR(10), IF(ISBLANK('Ingest Template'!P4),"", 'Ingest Template'!P4&"|TV Ops"))))} | AJ4: =if('Ingest Template'!A4="Standard",(IF(OR('Ingest Template'!F4 = "Program Type - Special", 'Ingest Template'!F4 = "Program Type - Live Event"),'Ingest Template'!M4& "|DAR|DAR|"&TEXT('Ingest Template'!C4-3, "yyyy-mm-dd")&"|"&TEXT('Ingest Template'!C4+3, "yyyy-mm-dd"),'Ingest Template'!M4& "|DAR|DAR|2021-01-01")),(IF(OR('Ingest Template'!F4 = "Program Type - Special", 'Ingest Template'!F4 = "Program Type - Live Event"),'Ingest Template'!M4& "|Operations - Core Title|Operations - Core Title|"&TEXT('Ingest Template'!C4-3, "yyyy-mm-dd")&"|"&TEXT('Ingest Template'!C4+3, "yyyy-mm-dd"),'Ingest Template'!M4& "|Operations - Core Title|Operations - Core Title"))) -> |Operations - Core Title|Operations - Core Title | AL4: =if('Ingest Template'!A4="Standard",(IF(OR('Ingest Template'!F4 = "Program Type - Special", 'Ingest Template'!F4 = "Program Type - Live Event"),'Ingest Template'!Q4&"|"&TEXT('Ingest Template'!C4-3, "yyyy-mm-dd")&"|"&TEXT('Ingest Template'!C4+3, "yyyy-mm-dd"),'Ingest Template'!Q4& "|2021-01-01")),(IF(OR('Ingest Template'!F4 = "Program Type - Special", 'Ingest Template'!F4 = "Program Type - Live Event"),'Ingest Template'!Q4& "|"&TEXT('Ingest Template'!C4-3, "yyyy-mm-dd")&"|"&TEXT('Ingest Template'!C4+3, "yyyy-mm-dd"),'Ingest Template'!Q4))) | AM4: ='Ingest Template'!AC4
B5: ='Ingest Template'!C5&IF('Ingest Template'!A5 = "Standard", " - DAR","") | C5: TV Shows | D5: {=CONCATENATE(INDEX(DropdownLists!$H$2:$H$11,MATCH(1,COUNTIF('Ingest Template'!E5,"*"&DropdownLists!$I$2:$I$11&"*"),0)),CHAR(10),'Ingest Template'!F5,CHAR(10),'Ingest Template'!G5,CHAR(10),VLOOKUP('Ingest Template'!D5,DropdownLists!C:D,2,FALSE))} -> #N/A | E5: =CONCATENATE('Ingest Template'!H5,CHAR(10),'Ingest Template'!I5,CHAR(10),'Ingest Template'!J5,CHAR(10)) | F5: {=INDEX(DropdownLists!$O$2:$O$36,MATCH(1,COUNTIF(E5,"*"&DropdownLists!$N$2:$N$36&"*"),0))} | H5: {=INDEX(DropdownLists!$E$2:$E$276,MATCH('Ingest Template'!D5,DropdownLists!$C$2:$C$276,0))} -> #N/A | J5: {=iF('Ingest Template'!A5="Standard","Pristine Brand",INDEX(DropdownLists!$B$2:$B$246,MATCH('Ingest Template'!D5,DropdownLists!$C$2:$C$246,0)))} -> #N/A | K5: =iF('Ingest Template'!A5="Standard",'Ingest Template'!K5&CHAR(10)&'Ingest Template'!L5,"Competitive View") -> Competitive View | L5: t | M5: ='Ingest Template'!B5 | R5: ='Ingest Template'!D5 | S5: f | T5: ='Ingest Template'!V5 | U5: ='Ingest Template'!W5 | V5: =LOWER(SUBSTITUTE(SUBSTITUTE(SUBSTITUTE(SUBSTITUTE(SUBSTITUTE('Ingest Template'!X5,"https:",""),"www.",""),"/",""),"?hl=en",""),"instagram.com","")) | W5: {=IF( 'Ingest Template'!Y5="", SUBSTITUTE( INDEX(DropdownLists!$F$2:$F$277,MATCH('Ingest Template'!D5,DropdownLists!$C$2:$C$277,0)), CHAR(10), "|"&'Ingest Template'!C5&CHAR(10) )&"|"&'Ingest Template'!C5, SUBSTITUTE( INDEX(DropdownLists!$F$2:$F$277,MATCH('Ingest Template'!D5,DropdownLists!$C$2:$C$277,0)), CHAR(10), "|"&'Ingest Template'!C5&CHAR(10) )&"|"&'Ingest Template'!C5&CHAR(10)&'Ingest Template'!Y5 )} -> #N/A | X5: ='Ingest Template'!Z5 | Y5: =SUBSTITUTE(SUBSTITUTE(SUBSTITUTE('Ingest Template'!AA5,"http:",""),"https:",""),"/","") | Z5: {=IF('Ingest Template'!A5="Standard",(IF(ISBLANK('Ingest Template'!AB5),"", 'Ingest Template'!AB5&"|DAR")),(IF(ISBLANK('Ingest Template'!AB5),"", 'Ingest Template'!AB5&"|TV Ops")))} | AB5: ='Ingest Template'!R5 | AC5: ='Ingest Template'!T5 | AD5: ='Ingest Template'!S5 | AE5: ='Ingest Template'!U5 | AG5: {=IF('Ingest Template'!A5="Standard",(CONCATENATE(IF(ISBLANK('Ingest Template'!N5),"", 'Ingest Template'!N5&"|DAR"),CHAR(10), IF(ISBLANK('Ingest Template'!O5),"", 'Ingest Template'!O5&"|DAR"),CHAR(10), IF(ISBLANK('Ingest Template'!P5),"", 'Ingest Template'!P5&"|DAR"))),(CONCATENATE(IF(ISBLANK('Ingest Template'!N5),"", 'Ingest Template'!N5&"|TV Ops"),CHAR(10), IF(ISBLANK('Ingest Template'!O5),"", 'Ingest Template'!O5&"|TV Ops"),CHAR(10), IF(ISBLANK('Ingest Template'!P5),"", 'Ingest Template'!P5&"|TV Ops"))))} | AJ5: =if('Ingest Template'!A5="Standard",(IF(OR('Ingest Template'!F5 = "Program Type - Special", 'Ingest Template'!F5 = "Program Type - Live Event"),'Ingest Template'!M5& "|DAR|DAR|"&TEXT('Ingest Template'!C5-3, "yyyy-mm-dd")&"|"&TEXT('Ingest Template'!C5+3, "yyyy-mm-dd"),'Ingest Template'!M5& "|DAR|DAR|2021-01-01")),(IF(OR('Ingest Template'!F5 = "Program Type - Special", 'Ingest Template'!F5 = "Program Type - Live Event"),'Ingest Template'!M5& "|Operations - Core Title|Operations - Core Title|"&TEXT('Ingest Template'!C5-3, "yyyy-mm-dd")&"|"&TEXT('Ingest Template'!C5+3, "yyyy-mm-dd"),'Ingest Template'!M5& "|Operations - Core Title|Operations - Core Title"))) -> |Operations - Core Title|Operations - Core Title | AL5: =if('Ingest Template'!A5="Standard",(IF(OR('Ingest Template'!F5 = "Program Type - Special", 'Ingest Template'!F5 = "Program Type - Live Event"),'Ingest Template'!Q5&"|"&TEXT('Ingest Template'!C5-3, "yyyy-mm-dd")&"|"&TEXT('Ingest Template'!C5+3, "yyyy-mm-dd"),'Ingest Template'!Q5& "|2021-01-01")),(IF(OR('Ingest Template'!F5 = "Program Type - Special", 'Ingest Template'!F5 = "Program Type - Live Event"),'Ingest Template'!Q5& "|"&TEXT('Ingest Template'!C5-3, "yyyy-mm-dd")&"|"&TEXT('Ingest Template'!C5+3, "yyyy-mm-dd"),'Ingest Template'!Q5))) | AM5: ='Ingest Template'!AC5
B6: ='Ingest Template'!C6&IF('Ingest Template'!A6 = "Standard", " - DAR","") | C6: TV Shows | D6: {=CONCATENATE(INDEX(DropdownLists!$H$2:$H$11,MATCH(1,COUNTIF('Ingest Template'!E6,"*"&DropdownLists!$I$2:$I$11&"*"),0)),CHAR(10),'Ingest Template'!F6,CHAR(10),'Ingest Template'!G6,CHAR(10),VLOOKUP('Ingest Template'!D6,DropdownLists!C:D,2,FALSE))} -> #N/A | E6: =CONCATENATE('Ingest Template'!H6,CHAR(10),'Ingest Template'!I6,CHAR(10),'Ingest Template'!J6,CHAR(10)) | F6: {=INDEX(DropdownLists!$O$2:$O$36,MATCH(1,COUNTIF(E6,"*"&DropdownLists!$N$2:$N$36&"*"),0))} | H6: {=INDEX(DropdownLists!$E$2:$E$276,MATCH('Ingest Template'!D6,DropdownLists!$C$2:$C$276,0))} -> #N/A | J6: {=iF('Ingest Template'!A6="Standard","Pristine Brand",INDEX(DropdownLists!$B$2:$B$246,MATCH('Ingest Template'!D6,DropdownLists!$C$2:$C$246,0)))} -> #N/A | K6: =iF('Ingest Template'!A6="Standard",'Ingest Template'!K6&CHAR(10)&'Ingest Template'!L6,"Competitive View") -> Competitive View | L6: t | M6: ='Ingest Template'!B6 | R6: ='Ingest Template'!D6 | S6: f | T6: ='Ingest Template'!V6 | U6: ='Ingest Template'!W6 | V6: =LOWER(SUBSTITUTE(SUBSTITUTE(SUBSTITUTE(SUBSTITUTE(SUBSTITUTE('Ingest Template'!X6,"https:",""),"www.",""),"/",""),"?hl=en",""),"instagram.com","")) | W6: {=IF( 'Ingest Template'!Y6="", SUBSTITUTE( INDEX(DropdownLists!$F$2:$F$277,MATCH('Ingest Template'!D6,DropdownLists!$C$2:$C$277,0)), CHAR(10), "|"&'Ingest Template'!C6&CHAR(10) )&"|"&'Ingest Template'!C6, SUBSTITUTE( INDEX(DropdownLists!$F$2:$F$277,MATCH('Ingest Template'!D6,DropdownLists!$C$2:$C$277,0)), CHAR(10), "|"&'Ingest Template'!C6&CHAR(10) )&"|"&'Ingest Template'!C6&CHAR(10)&'Ingest Template'!Y6 )} -> #N/A | X6: ='Ingest Template'!Z6 | Y6: =SUBSTITUTE(SUBSTITUTE(SUBSTITUTE('Ingest Template'!AA6,"http:",""),"https:",""),"/","") | Z6: {=IF('Ingest Template'!A6="Standard",(IF(ISBLANK('Ingest Template'!AB6),"", 'Ingest Template'!AB6&"|DAR")),(IF(ISBLANK('Ingest Template'!AB6),"", 'Ingest Template'!AB6&"|TV Ops")))} | AB6: ='Ingest Template'!R6 | AC6: ='Ingest Template'!T6 | AD6: ='Ingest Template'!S6 | AE6: ='Ingest Template'!U6 | AG6: {=IF('Ingest Template'!A6="Standard",(CONCATENATE(IF(ISBLANK('Ingest Template'!N6),"", 'Ingest Template'!N6&"|DAR"),CHAR(10), IF(ISBLANK('Ingest Template'!O6),"", 'Ingest Template'!O6&"|DAR"),CHAR(10), IF(ISBLANK('Ingest Template'!P6),"", 'Ingest Template'!P6&"|DAR"))),(CONCATENATE(IF(ISBLANK('Ingest Template'!N6),"", 'Ingest Template'!N6&"|TV Ops"),CHAR(10), IF(ISBLANK('Ingest Template'!O6),"", 'Ingest Template'!O6&"|TV Ops"),CHAR(10), IF(ISBLANK('Ingest Template'!P6),"", 'Ingest Template'!P6&"|TV Ops"))))} | AJ6: =if('Ingest Template'!A6="Standard",(IF(OR('Ingest Template'!F6 = "Program Type - Special", 'Ingest Template'!F6 = "Program Type - Live Event"),'Ingest Template'!M6& "|DAR|DAR|"&TEXT('Ingest Template'!C6-3, "yyyy-mm-dd")&"|"&TEXT('Ingest Template'!C6+3, "yyyy-mm-dd"),'Ingest Template'!M6& "|DAR|DAR|2021-01-01")),(IF(OR('Ingest Template'!F6 = "Program Type - Special", 'Ingest Template'!F6 = "Program Type - Live Event"),'Ingest Template'!M6& "|Operations - Core Title|Operations - Core Title|"&TEXT('Ingest Template'!C6-3, "yyyy-mm-dd")&"|"&TEXT('Ingest Template'!C6+3, "yyyy-mm-dd"),'Ingest Template'!M6& "|Operations - Core Title|Operations - Core Title"))) -> |Operations - Core Title|Operations - Core Title | AL6: =if('Ingest Template'!A6="Standard",(IF(OR('Ingest Template'!F6 = "Program Type - Special", 'Ingest Template'!F6 = "Program Type - Live Event"),'Ingest Template'!Q6&"|"&TEXT('Ingest Template'!C6-3, "yyyy-mm-dd")&"|"&TEXT('Ingest Template'!C6+3, "yyyy-mm-dd"),'Ingest Template'!Q6& "|2021-01-01")),(IF(OR('Ingest Template'!F6 = "Program Type - Special", 'Ingest Template'!F6 = "Program Type - Live Event"),'Ingest Template'!Q6& "|"&TEXT('Ingest Template'!C6-3, "yyyy-mm-dd")&"|"&TEXT('Ingest Template'!C6+3, "yyyy-mm-dd"),'Ingest Template'!Q6))) | AM6: ='Ingest Template'!AC6
B7: ='Ingest Template'!C7&IF('Ingest Template'!A7 = "Standard", " - DAR","") | C7: TV Shows | D7: {=CONCATENATE(INDEX(DropdownLists!$H$2:$H$11,MATCH(1,COUNTIF('Ingest Template'!E7,"*"&DropdownLists!$I$2:$I$11&"*"),0)),CHAR(10),'Ingest Template'!F7,CHAR(10),'Ingest Template'!G7,CHAR(10),VLOOKUP('Ingest Template'!D7,DropdownLists!C:D,2,FALSE))} -> #N/A | E7: =CONCATENATE('Ingest Template'!H7,CHAR(10),'Ingest Template'!I7,CHAR(10),'Ingest Template'!J7,CHAR(10)) | F7: {=INDEX(DropdownLists!$O$2:$O$36,MATCH(1,COUNTIF(E7,"*"&DropdownLists!$N$2:$N$36&"*"),0))} | H7: {=INDEX(DropdownLists!$E$2:$E$276,MATCH('Ingest Template'!D7,DropdownLists!$C$2:$C$276,0))} -> #N/A | J7: {=iF('Ingest Template'!A7="Standard","Pristine Brand",INDEX(DropdownLists!$B$2:$B$246,MATCH('Ingest Template'!D7,DropdownLists!$C$2:$C$246,0)))} -> #N/A | K7: =iF('Ingest Template'!A7="Standard",'Ingest Template'!K7&CHAR(10)&'Ingest Template'!L7,"Competitive View") -> Competitive View | L7: t | M7: ='Ingest Template'!B7 | R7: ='Ingest Template'!D7 | S7: f | T7: ='Ingest Template'!V7 | U7: ='Ingest Template'!W7 | V7: =LOWER(SUBSTITUTE(SUBSTITUTE(SUBSTITUTE(SUBSTITUTE(SUBSTITUTE('Ingest Template'!X7,"https:",""),"www.",""),"/",""),"?hl=en",""),"instagram.com","")) | W7: {=IF( 'Ingest Template'!Y7="", SUBSTITUTE( INDEX(DropdownLists!$F$2:$F$277,MATCH('Ingest Template'!D7,DropdownLists!$C$2:$C$277,0)), CHAR(10), "|"&'Ingest Template'!C7&CHAR(10) )&"|"&'Ingest Template'!C7, SUBSTITUTE( INDEX(DropdownLists!$F$2:$F$277,MATCH('Ingest Template'!D7,DropdownLists!$C$2:$C$277,0)), CHAR(10), "|"&'Ingest Template'!C7&CHAR(10) )&"|"&'Ingest Template'!C7&CHAR(10)&'Ingest Template'!Y7 )} -> #N/A | X7: ='Ingest Template'!Z7 | Y7: =SUBSTITUTE(SUBSTITUTE(SUBSTITUTE('Ingest Template'!AA7,"http:",""),"https:",""),"/","") | Z7: {=IF('Ingest Template'!A7="Standard",(IF(ISBLANK('Ingest Template'!AB7),"", 'Ingest Template'!AB7&"|DAR")),(IF(ISBLANK('Ingest Template'!AB7),"", 'Ingest Template'!AB7&"|TV Ops")))} | AB7: ='Ingest Template'!R7 | AC7: ='Ingest Template'!T7 | AD7: ='Ingest Template'!S7 | AE7: ='Ingest Template'!U7 | AG7: {=IF('Ingest Template'!A7="Standard",(CONCATENATE(IF(ISBLANK('Ingest Template'!N7),"", 'Ingest Template'!N7&"|DAR"),CHAR(10), IF(ISBLANK('Ingest Template'!O7),"", 'Ingest Template'!O7&"|DAR"),CHAR(10), IF(ISBLANK('Ingest Template'!P7),"", 'Ingest Template'!P7&"|DAR"))),(CONCATENATE(IF(ISBLANK('Ingest Template'!N7),"", 'Ingest Template'!N7&"|TV Ops"),CHAR(10), IF(ISBLANK('Ingest Template'!O7),"", 'Ingest Template'!O7&"|TV Ops"),CHAR(10), IF(ISBLANK('Ingest Template'!P7),"", 'Ingest Template'!P7&"|TV Ops"))))} | AJ7: =if('Ingest Template'!A7="Standard",(IF(OR('Ingest Template'!F7 = "Program Type - Special", 'Ingest Template'!F7 = "Program Type - Live Event"),'Ingest Template'!M7& "|DAR|DAR|"&TEXT('Ingest Template'!C7-3, "yyyy-mm-dd")&"|"&TEXT('Ingest Template'!C7+3, "yyyy-mm-dd"),'Ingest Template'!M7& "|DAR|DAR|2021-01-01")),(IF(OR('Ingest Template'!F7 = "Program Type - Special", 'Ingest Template'!F7 = "Program Type - Live Event"),'Ingest Template'!M7& "|Operations - Core Title|Operations - Core Title|"&TEXT('Ingest Template'!C7-3, "yyyy-mm-dd")&"|"&TEXT('Ingest Template'!C7+3, "yyyy-mm-dd"),'Ingest Template'!M7& "|Operations - Core Title|Operations - Core Title"))) -> |Operations - Core Title|Operations - Core Title | AL7: =if('Ingest Template'!A7="Standard",(IF(OR('Ingest Template'!F7 = "Program Type - Special", 'Ingest Template'!F7 = "Program Type - Live Event"),'Ingest Template'!Q7&"|"&TEXT('Ingest Template'!C7-3, "yyyy-mm-dd")&"|"&TEXT('Ingest Template'!C7+3, "yyyy-mm-dd"),'Ingest Template'!Q7& "|2021-01-01")),(IF(OR('Ingest Template'!F7 = "Program Type - Special", 'Ingest Template'!F7 = "Program Type - Live Event"),'Ingest Template'!Q7& "|"&TEXT('Ingest Template'!C7-3, "yyyy-mm-dd")&"|"&TEXT('Ingest Template'!C7+3, "yyyy-mm-dd"),'Ingest Template'!Q7))) | AM7: ='Ingest Template'!AC7
B8: ='Ingest Template'!C8&IF('Ingest Template'!A8 = "Standard", " - DAR","") | C8: TV Shows | D8: {=CONCATENATE(INDEX(DropdownLists!$H$2:$H$11,MATCH(1,COUNTIF('Ingest Template'!E8,"*"&DropdownLists!$I$2:$I$11&"*"),0)),CHAR(10),'Ingest Template'!F8,CHAR(10),'Ingest Template'!G8,CHAR(10),VLOOKUP('Ingest Template'!D8,DropdownLists!C:D,2,FALSE))} -> #N/A | E8: =CONCATENATE('Ingest Template'!H8,CHAR(10),'Ingest Template'!I8,CHAR(10),'Ingest Template'!J8,CHAR(10)) | F8: {=INDEX(DropdownLists!$O$2:$O$36,MATCH(1,COUNTIF(E8,"*"&DropdownLists!$N$2:$N$36&"*"),0))} | H8: {=INDEX(DropdownLists!$E$2:$E$276,MATCH('Ingest Template'!D8,DropdownLists!$C$2:$C$276,0))} -> #N/A | J8: {=iF('Ingest Template'!A8="Standard","Pristine Brand",INDEX(DropdownLists!$B$2:$B$246,MATCH('Ingest Template'!D8,DropdownLists!$C$2:$C$246,0)))} -> #N/A | K8: =iF('Ingest Template'!A8="Standard",'Ingest Template'!K8&CHAR(10)&'Ingest Template'!L8,"Competitive View") -> Competitive View | L8: t | M8: ='Ingest Template'!B8 | R8: ='Ingest Template'!D8 | S8: f | T8: ='Ingest Template'!V8 | U8: ='Ingest Template'!W8 | V8: =LOWER(SUBSTITUTE(SUBSTITUTE(SUBSTITUTE(SUBSTITUTE(SUBSTITUTE('Ingest Template'!X8,"https:",""),"www.",""),"/",""),"?hl=en",""),"instagram.com","")) | W8: {=IF( 'Ingest Template'!Y8="", SUBSTITUTE( INDEX(DropdownLists!$F$2:$F$277,MATCH('Ingest Template'!D8,DropdownLists!$C$2:$C$277,0)), CHAR(10), "|"&'Ingest Template'!C8&CHAR(10) )&"|"&'Ingest Template'!C8, SUBSTITUTE( INDEX(DropdownLists!$F$2:$F$277,MATCH('Ingest Template'!D8,DropdownLists!$C$2:$C$277,0)), CHAR(10), "|"&'Ingest Template'!C8&CHAR(10) )&"|"&'Ingest Template'!C8&CHAR(10)&'Ingest Template'!Y8 )} -> #N/A | X8: ='Ingest Template'!Z8 | Y8: =SUBSTITUTE(SUBSTITUTE(SUBSTITUTE('Ingest Template'!AA8,"http:",""),"https:",""),"/","") | Z8: {=IF('Ingest Template'!A8="Standard",(IF(ISBLANK('Ingest Template'!AB8),"", 'Ingest Template'!AB8&"|DAR")),(IF(ISBLANK('Ingest Template'!AB8),"", 'Ingest Template'!AB8&"|TV Ops")))} | AB8: ='Ingest Template'!R8 | AC8: ='Ingest Template'!T8 | AD8: ='Ingest Template'!S8 | AE8: ='Ingest Template'!U8 | AG8: {=IF('Ingest Template'!A8="Standard",(CONCATENATE(IF(ISBLANK('Ingest Template'!N8),"", 'Ingest Template'!N8&"|DAR"),CHAR(10), IF(ISBLANK('Ingest Template'!O8),"", 'Ingest Template'!O8&"|DAR"),CHAR(10), IF(ISBLANK('Ingest Template'!P8),"", 'Ingest Template'!P8&"|DAR"))),(CONCATENATE(IF(ISBLANK('Ingest Template'!N8),"", 'Ingest Template'!N8&"|TV Ops"),CHAR(10), IF(ISBLANK('Ingest Template'!O8),"", 'Ingest Template'!O8&"|TV Ops"),CHAR(10), IF(ISBLANK('Ingest Template'!P8),"", 'Ingest Template'!P8&"|TV Ops"))))} | AJ8: =if('Ingest Template'!A8="Standard",(IF(OR('Ingest Template'!F8 = "Program Type - Special", 'Ingest Template'!F8 = "Program Type - Live Event"),'Ingest Template'!M8& "|DAR|DAR|"&TEXT('Ingest Template'!C8-3, "yyyy-mm-dd")&"|"&TEXT('Ingest Template'!C8+3, "yyyy-mm-dd"),'Ingest Template'!M8& "|DAR|DAR|2021-01-01")),(IF(OR('Ingest Template'!F8 = "Program Type - Special", 'Ingest Template'!F8 = "Program Type - Live Event"),'Ingest Template'!M8& "|Operations - Core Title|Operations - Core Title|"&TEXT('Ingest Template'!C8-3, "yyyy-mm-dd")&"|"&TEXT('Ingest Template'!C8+3, "yyyy-mm-dd"),'Ingest Template'!M8& "|Operations - Core Title|Operations - Core Title"))) -> |Operations - Core Title|Operations - Core Title | AL8: =if('Ingest Template'!A8="Standard",(IF(OR('Ingest Template'!F8 = "Program Type - Special", 'Ingest Template'!F8 = "Program Type - Live Event"),'Ingest Template'!Q8&"|"&TEXT('Ingest Template'!C8-3, "yyyy-mm-dd")&"|"&TEXT('Ingest Template'!C8+3, "yyyy-mm-dd"),'Ingest Template'!Q8& "|2021-01-01")),(IF(OR('Ingest Template'!F8 = "Program Type - Special", 'Ingest Template'!F8 = "Program Type - Live Event"),'Ingest Template'!Q8& "|"&TEXT('Ingest Template'!C8-3, "yyyy-mm-dd")&"|"&TEXT('Ingest Template'!C8+3, "yyyy-mm-dd"),'Ingest Template'!Q8))) | AM8: ='Ingest Template'!AC8
B9: ='Ingest Template'!C9&IF('Ingest Template'!A9 = "Standard", " - DAR","") | C9: TV Shows | D9: {=CONCATENATE(INDEX(DropdownLists!$H$2:$H$11,MATCH(1,COUNTIF('Ingest Template'!E9,"*"&DropdownLists!$I$2:$I$11&"*"),0)),CHAR(10),'Ingest Template'!F9,CHAR(10),'Ingest Template'!G9,CHAR(10),VLOOKUP('Ingest Template'!D9,DropdownLists!C:D,2,FALSE))} -> #N/A | E9: =CONCATENATE('Ingest Template'!H9,CHAR(10),'Ingest Template'!I9,CHAR(10),'Ingest Template'!J9,CHAR(10)) | F9: {=INDEX(DropdownLists!$O$2:$O$36,MATCH(1,COUNTIF(E9,"*"&DropdownLists!$N$2:$N$36&"*"),0))} | H9: {=INDEX(DropdownLists!$E$2:$E$276,MATCH('Ingest Template'!D9,DropdownLists!$C$2:$C$276,0))} -> #N/A | J9: {=iF('Ingest Template'!A9="Standard","Pristine Brand",INDEX(DropdownLists!$B$2:$B$246,MATCH('Ingest Template'!D9,DropdownLists!$C$2:$C$246,0)))} -> #N/A | K9: =iF('Ingest Template'!A9="Standard",'Ingest Template'!K9&CHAR(10)&'Ingest Template'!L9,"Competitive View") -> Competitive View | L9: t | M9: ='Ingest Template'!B9 | R9: ='Ingest Template'!D9 | S9: f | T9: ='Ingest Template'!V9 | U9: ='Ingest Template'!W9 | V9: =LOWER(SUBSTITUTE(SUBSTITUTE(SUBSTITUTE(SUBSTITUTE(SUBSTITUTE('Ingest Template'!X9,"https:",""),"www.",""),"/",""),"?hl=en",""),"instagram.com","")) | W9: {=IF( 'Ingest Template'!Y9="", SUBSTITUTE( INDEX(DropdownLists!$F$2:$F$277,MATCH('Ingest Template'!D9,DropdownLists!$C$2:$C$277,0)), CHAR(10), "|"&'Ingest Template'!C9&CHAR(10) )&"|"&'Ingest Template'!C9, SUBSTITUTE( INDEX(DropdownLists!$F$2:$F$277,MATCH('Ingest Template'!D9,DropdownLists!$C$2:$C$277,0)), CHAR(10), "|"&'Ingest Template'!C9&CHAR(10) )&"|"&'Ingest Template'!C9&CHAR(10)&'Ingest Template'!Y9 )} -> #N/A | X9: ='Ingest Template'!Z9 | Y9: =SUBSTITUTE(SUBSTITUTE(SUBSTITUTE('Ingest Template'!AA9,"http:",""),"https:",""),"/","") | Z9: {=IF('Ingest Template'!A9="Standard",(IF(ISBLANK('Ingest Template'!AB9),"", 'Ingest Template'!AB9&"|DAR")),(IF(ISBLANK('Ingest Template'!AB9),"", 'Ingest Template'!AB9&"|TV Ops")))} | AB9: ='Ingest Template'!R9 | AC9: ='Ingest Template'!T9 | AD9: ='Ingest Template'!S9 | AE9: ='Ingest Template'!U9 | AG9: {=IF('Ingest Template'!A9="Standard",(CONCATENATE(IF(ISBLANK('Ingest Template'!N9),"", 'Ingest Template'!N9&"|DAR"),CHAR(10), IF(ISBLANK('Ingest Template'!O9),"", 'Ingest Template'!O9&"|DAR"),CHAR(10), IF(ISBLANK('Ingest Template'!P9),"", 'Ingest Template'!P9&"|DAR"))),(CONCATENATE(IF(ISBLANK('Ingest Template'!N9),"", 'Ingest Template'!N9&"|TV Ops"),CHAR(10), IF(ISBLANK('Ingest Template'!O9),"", 'Ingest Template'!O9&"|TV Ops"),CHAR(10), IF(ISBLANK('Ingest Template'!P9),"", 'Ingest Template'!P9&"|TV Ops"))))} | AJ9: =if('Ingest Template'!A9="Standard",(IF(OR('Ingest Template'!F9 = "Program Type - Special", 'Ingest Template'!F9 = "Program Type - Live Event"),'Ingest Template'!M9& "|DAR|DAR|"&TEXT('Ingest Template'!C9-3, "yyyy-mm-dd")&"|"&TEXT('Ingest Template'!C9+3, "yyyy-mm-dd"),'Ingest Template'!M9& "|DAR|DAR|2021-01-01")),(IF(OR('Ingest Template'!F9 = "Program Type - Special", 'Ingest Template'!F9 = "Program Type - Live Event"),'Ingest Template'!M9& "|Operations - Core Title|Operations - Core Title|"&TEXT('Ingest Template'!C9-3, "yyyy-mm-dd")&"|"&TEXT('Ingest Template'!C9+3, "yyyy-mm-dd"),'Ingest Template'!M9& "|Operations - Core Title|Operations - Core Title"))) -> |Operations - Core Title|Operations - Core Title | AL9: =if('Ingest Template'!A9="Standard",(IF(OR('Ingest Template'!F9 = "Program Type - Special", 'Ingest Template'!F9 = "Program Type - Live Event"),'Ingest Template'!Q9&"|"&TEXT('Ingest Template'!C9-3, "yyyy-mm-dd")&"|"&TEXT('Ingest Template'!C9+3, "yyyy-mm-dd"),'Ingest Template'!Q9& "|2021-01-01")),(IF(OR('Ingest Template'!F9 = "Program Type - Special", 'Ingest Template'!F9 = "Program Type - Live Event"),'Ingest Template'!Q9& "|"&TEXT('Ingest Template'!C9-3, "yyyy-mm-dd")&"|"&TEXT('Ingest Template'!C9+3, "yyyy-mm-dd"),'Ingest Template'!Q9))) | AM9: ='Ingest Template'!AC9
B10: ='Ingest Template'!C10&IF('Ingest Template'!A10 = "Standard", " - DAR","") | C10: TV Shows | D10: {=CONCATENATE(INDEX(DropdownLists!$H$2:$H$11,MATCH(1,COUNTIF('Ingest Template'!E10,"*"&DropdownLists!$I$2:$I$11&"*"),0)),CHAR(10),'Ingest Template'!F10,CHAR(10),'Ingest Template'!G10,CHAR(10),VLOOKUP('Ingest Template'!D10,DropdownLists!C:D,2,FALSE))} -> #N/A | E10: =CONCATENATE('Ingest Template'!H10,CHAR(10),'Ingest Template'!I10,CHAR(10),'Ingest Template'!J10,CHAR(10)) | F10: {=INDEX(DropdownLists!$O$2:$O$36,MATCH(1,COUNTIF(E10,"*"&DropdownLists!$N$2:$N$36&"*"),0))} | H10: {=INDEX(DropdownLists!$E$2:$E$276,MATCH('Ingest Template'!D10,DropdownLists!$C$2:$C$276,0))} -> #N/A | J10: {=iF('Ingest Template'!A10="Standard","Pristine Brand",INDEX(DropdownLists!$B$2:$B$246,MATCH('Ingest Template'!D10,DropdownLists!$C$2:$C$246,0)))} -> #N/A | K10: =iF('Ingest Template'!A10="Standard",'Ingest Template'!K10&CHAR(10)&'Ingest Template'!L10,"Competitive View") -> Competitive View | L10: t | M10: ='Ingest Template'!B10 | R10: ='Ingest Template'!D10 | S10: f | T10: ='Ingest Template'!V10 | U10: ='Ingest Template'!W10 | V10: =LOWER(SUBSTITUTE(SUBSTITUTE(SUBSTITUTE(SUBSTITUTE(SUBSTITUTE('Ingest Template'!X10,"https:",""),"www.",""),"/",""),"?hl=en",""),"instagram.com","")) | W10: {=IF( 'Ingest Template'!Y10="", SUBSTITUTE( INDEX(DropdownLists!$F$2:$F$277,MATCH('Ingest Template'!D10,DropdownLists!$C$2:$C$277,0)), CHAR(10), "|"&'Ingest Template'!C10&CHAR(10) )&"|"&'Ingest Template'!C10, SUBSTITUTE( INDEX(DropdownLists!$F$2:$F$277,MATCH('Ingest Template'!D10,DropdownLists!$C$2:$C$277,0)), CHAR(10), "|"&'Ingest Template'!C10&CHAR(10) )&"|"&'Ingest Template'!C10&CHAR(10)&'Ingest Template'!Y10 )} -> #N/A | X10: ='Ingest Template'!Z10 | Y10: =SUBSTITUTE(SUBSTITUTE(SUBSTITUTE('Ingest Template'!AA10,"http:",""),"https:",""),"/","") | Z10: {=IF('Ingest Template'!A10="Standard",(IF(ISBLANK('Ingest Template'!AB10),"", 'Ingest Template'!AB10&"|DAR")),(IF(ISBLANK('Ingest Template'!AB10),"", 'Ingest Template'!AB10&"|TV Ops")))} | AB10: ='Ingest Template'!R10 | AC10: ='Ingest Template'!T10 | AD10: ='Ingest Template'!S10 | AE10: ='Ingest Template'!U10 | AG10: {=IF('Ingest Template'!A10="Standard",(CONCATENATE(IF(ISBLANK('Ingest Template'!N10),"", 'Ingest Template'!N10&"|DAR"),CHAR(10), IF(ISBLANK('Ingest Template'!O10),"", 'Ingest Template'!O10&"|DAR"),CHAR(10), IF(ISBLANK('Ingest Template'!P10),"", 'Ingest Template'!P10&"|DAR"))),(CONCATENATE(IF(ISBLANK('Ingest Template'!N10),"", 'Ingest Template'!N10&"|TV Ops"),CHAR(10), IF(ISBLANK('Ingest Template'!O10),"", 'Ingest Template'!O10&"|TV Ops"),CHAR(10), IF(ISBLANK('Ingest Template'!P10),"", 'Ingest Template'!P10&"|TV Ops"))))} | AJ10: =if('Ingest Template'!A10="Standard",(IF(OR('Ingest Template'!F10 = "Program Type - Special", 'Ingest Template'!F10 = "Program Type - Live Event"),'Ingest Template'!M10& "|DAR|DAR|"&TEXT('Ingest Template'!C10-3, "yyyy-mm-dd")&"|"&TEXT('Ingest Template'!C10+3, "yyyy-mm-dd"),'Ingest Template'!M10& "|DAR|DAR|2021-01-01")),(IF(OR('Ingest Template'!F10 = "Program Type - Special", 'Ingest Template'!F10 = "Program Type - Live Event"),'Ingest Template'!M10& "|Operations - Core Title|Operations - Core Title|"&TEXT('Ingest Template'!C10-3, "yyyy-mm-dd")&"|"&TEXT('Ingest Template'!C10+3, "yyyy-mm-dd"),'Ingest Template'!M10& "|Operations - Core Title|Operations - Core Title"))) -> |Operations - Core Title|Operations - Core Title | AL10: =if('Ingest Template'!A10="Standard",(IF(OR('Ingest Template'!F10 = "Program Type - Special", 'Ingest Template'!F10 = "Program Type - Live Event"),'Ingest Template'!Q10&"|"&TEXT('Ingest Template'!C10-3, "yyyy-mm-dd")&"|"&TEXT('Ingest Template'!C10+3, "yyyy-mm-dd"),'Ingest Template'!Q10& "|2021-01-01")),(IF(OR('Ingest Template'!F10 = "Program Type - Special", 'Ingest Template'!F10 = "Program Type - Live Event"),'Ingest Template'!Q10& "|"&TEXT('Ingest Template'!C10-3, "yyyy-mm-dd")&"|"&TEXT('Ingest Template'!C10+3, "yyyy-mm-dd"),'Ingest Template'!Q10))) | AM10: ='Ingest Template'!AC10
B11: ='Ingest Template'!C11&IF('Ingest Template'!A11 = "Standard", " - DAR","") | C11: TV Shows | D11: {=CONCATENATE(INDEX(DropdownLists!$H$2:$H$11,MATCH(1,COUNTIF('Ingest Template'!E11,"*"&DropdownLists!$I$2:$I$11&"*"),0)),CHAR(10),'Ingest Template'!F11,CHAR(10),'Ingest Template'!G11,CHAR(10),VLOOKUP('Ingest Template'!D11,DropdownLists!C:D,2,FALSE))} -> #N/A | E11: =CONCATENATE('Ingest Template'!H11,CHAR(10),'Ingest Template'!I11,CHAR(10),'Ingest Template'!J11,CHAR(10)) | F11: {=INDEX(DropdownLists!$O$2:$O$36,MATCH(1,COUNTIF(E11,"*"&DropdownLists!$N$2:$N$36&"*"),0))} | H11: {=INDEX(DropdownLists!$E$2:$E$276,MATCH('Ingest Template'!D11,DropdownLists!$C$2:$C$276,0))} -> #N/A | J11: {=iF('Ingest Template'!A11="Standard","Pristine Brand",INDEX(DropdownLists!$B$2:$B$246,MATCH('Ingest Template'!D11,DropdownLists!$C$2:$C$246,0)))} -> #N/A | K11: =iF('Ingest Template'!A11="Standard",'Ingest Template'!K11&CHAR(10)&'Ingest Template'!L11,"Competitive View") -> Competitive View | L11: t | M11: ='Ingest Template'!B11 | R11: ='Ingest Template'!D11 | S11: f | T11: ='Ingest Template'!V11 | U11: ='Ingest Template'!W11 | V11: =LOWER(SUBSTITUTE(SUBSTITUTE(SUBSTITUTE(SUBSTITUTE(SUBSTITUTE('Ingest Template'!X11,"https:",""),"www.",""),"/",""),"?hl=en",""),"instagram.com","")) | W11: {=IF( 'Ingest Template'!Y11="", SUBSTITUTE( INDEX(DropdownLists!$F$2:$F$277,MATCH('Ingest Template'!D11,DropdownLists!$C$2:$C$277,0)), CHAR(10), "|"&'Ingest Template'!C11&CHAR(10) )&"|"&'Ingest Template'!C11, SUBSTITUTE( INDEX(DropdownLists!$F$2:$F$277,MATCH('Ingest Template'!D11,DropdownLists!$C$2:$C$277,0)), CHAR(10), "|"&'Ingest Template'!C11&CHAR(10) )&"|"&'Ingest Template'!C11&CHAR(10)&'Ingest Template'!Y11 )} -> #N/A | X11: ='Ingest Template'!Z11 | Y11: =SUBSTITUTE(SUBSTITUTE(SUBSTITUTE('Ingest Template'!AA11,"http:",""),"https:",""),"/","") | Z11: {=IF('Ingest Template'!A11="Standard",(IF(ISBLANK('Ingest Template'!AB11),"", 'Ingest Template'!AB11&"|DAR")),(IF(ISBLANK('Ingest Template'!AB11),"", 'Ingest Template'!AB11&"|TV Ops")))} | AB11: ='Ingest Template'!R11 | AC11: ='Ingest Template'!T11 | AD11: ='Ingest Template'!S11 | AE11: ='Ingest Template'!U11 | AG11: {=IF('Ingest Template'!A11="Standard",(CONCATENATE(IF(ISBLANK('Ingest Template'!N11),"", 'Ingest Template'!N11&"|DAR"),CHAR(10), IF(ISBLANK('Ingest Template'!O11),"", 'Ingest Template'!O11&"|DAR"),CHAR(10), IF(ISBLANK('Ingest Template'!P11),"", 'Ingest Template'!P11&"|DAR"))),(CONCATENATE(IF(ISBLANK('Ingest Template'!N11),"", 'Ingest Template'!N11&"|TV Ops"),CHAR(10), IF(ISBLANK('Ingest Template'!O11),"", 'Ingest Template'!O11&"|TV Ops"),CHAR(10), IF(ISBLANK('Ingest Template'!P11),"", 'Ingest Template'!P11&"|TV Ops"))))} | AJ11: =if('Ingest Template'!A11="Standard",(IF(OR('Ingest Template'!F11 = "Program Type - Special", 'Ingest Template'!F11 = "Program Type - Live Event"),'Ingest Template'!M11& "|DAR|DAR|"&TEXT('Ingest Template'!C11-3, "yyyy-mm-dd")&"|"&TEXT('Ingest Template'!C11+3, "yyyy-mm-dd"),'Ingest Template'!M11& "|DAR|DAR|2021-01-01")),(IF(OR('Ingest Template'!F11 = "Program Type - Special", 'Ingest Template'!F11 = "Program Type - Live Event"),'Ingest Template'!M11& "|Operations - Core Title|Operations - Core Title|"&TEXT('Ingest Template'!C11-3, "yyyy-mm-dd")&"|"&TEXT('Ingest Template'!C11+3, "yyyy-mm-dd"),'Ingest Template'!M11& "|Operations - Core Title|Operations - Core Title"))) -> |Operations - Core Title|Operations - Core Title | AL11: =if('Ingest Template'!A11="Standard",(IF(OR('Ingest Template'!F11 = "Program Type - Special", 'Ingest Template'!F11 = "Program Type - Live Event"),'Ingest Template'!Q11&"|"&TEXT('Ingest Template'!C11-3, "yyyy-mm-dd")&"|"&TEXT('Ingest Template'!C11+3, "yyyy-mm-dd"),'Ingest Template'!Q11& "|2021-01-01")),(IF(OR('Ingest Template'!F11 = "Program Type - Special", 'Ingest Template'!F11 = "Program Type - Live Event"),'Ingest Template'!Q11& "|"&TEXT('Ingest Template'!C11-3, "yyyy-mm-dd")&"|"&TEXT('Ingest Template'!C11+3, "yyyy-mm-dd"),'Ingest Template'!Q11))) | AM11: ='Ingest Template'!AC11
B12: ='Ingest Template'!C12&IF('Ingest Template'!A12 = "Standard", " - DAR","") | C12: TV Shows | D12: {=CONCATENATE(INDEX(DropdownLists!$H$2:$H$11,MATCH(1,COUNTIF('Ingest Template'!E12,"*"&DropdownLists!$I$2:$I$11&"*"),0)),CHAR(10),'Ingest Template'!F12,CHAR(10),'Ingest Template'!G12,CHAR(10),VLOOKUP('Ingest Template'!D12,DropdownLists!C:D,2,FALSE))} -> #N/A | E12: =CONCATENATE('Ingest Template'!H12,CHAR(10),'Ingest Template'!I12,CHAR(10),'Ingest Template'!J12,CHAR(10)) | F12: {=INDEX(DropdownLists!$O$2:$O$36,MATCH(1,COUNTIF(E12,"*"&DropdownLists!$N$2:$N$36&"*"),0))} | H12: {=INDEX(DropdownLists!$E$2:$E$276,MATCH('Ingest Template'!D12,DropdownLists!$C$2:$C$276,0))} -> #N/A | J12: {=iF('Ingest Template'!A12="Standard","Pristine Brand",INDEX(DropdownLists!$B$2:$B$246,MATCH('Ingest Template'!D12,DropdownLists!$C$2:$C$246,0)))} -> #N/A | K12: =iF('Ingest Template'!A12="Standard",'Ingest Template'!K12&CHAR(10)&'Ingest Template'!L12,"Competitive View") -> Competitive View | L12: t | M12: ='Ingest Template'!B12 | R12: ='Ingest Template'!D12 | S12: f | T12: ='Ingest Template'!V12 | U12: ='Ingest Template'!W12 | V12: =LOWER(SUBSTITUTE(SUBSTITUTE(SUBSTITUTE(SUBSTITUTE(SUBSTITUTE('Ingest Template'!X12,"https:",""),"www.",""),"/",""),"?hl=en",""),"instagram.com","")) | W12: {=IF( 'Ingest Template'!Y12="", SUBSTITUTE( INDEX(DropdownLists!$F$2:$F$277,MATCH('Ingest Template'!D12,DropdownLists!$C$2:$C$277,0)), CHAR(10), "|"&'Ingest Template'!C12&CHAR(10) )&"|"&'Ingest Template'!C12, SUBSTITUTE( INDEX(DropdownLists!$F$2:$F$277,MATCH('Ingest Template'!D12,DropdownLists!$C$2:$C$277,0)), CHAR(10), "|"&'Ingest Template'!C12&CHAR(10) )&"|"&'Ingest Template'!C12&CHAR(10)&'Ingest Template'!Y12 )} -> #N/A | X12: ='Ingest Template'!Z12 | Y12: =SUBSTITUTE(SUBSTITUTE(SUBSTITUTE('Ingest Template'!AA12,"http:",""),"https:",""),"/","") | Z12: {=IF('Ingest Template'!A12="Standard",(IF(ISBLANK('Ingest Template'!AB12),"", 'Ingest Template'!AB12&"|DAR")),(IF(ISBLANK('Ingest Template'!AB12),"", 'Ingest Template'!AB12&"|TV Ops")))} | AB12: ='Ingest Template'!R12 | AC12: ='Ingest Template'!T12 | AD12: ='Ingest Template'!S12 | AE12: ='Ingest Template'!U12 | AG12: {=IF('Ingest Template'!A12="Standard",(CONCATENATE(IF(ISBLANK('Ingest Template'!N12),"", 'Ingest Template'!N12&"|DAR"),CHAR(10), IF(ISBLANK('Ingest Template'!O12),"", 'Ingest Template'!O12&"|DAR"),CHAR(10), IF(ISBLANK('Ingest Template'!P12),"", 'Ingest Template'!P12&"|DAR"))),(CONCATENATE(IF(ISBLANK('Ingest Template'!N12),"", 'Ingest Template'!N12&"|TV Ops"),CHAR(10), IF(ISBLANK('Ingest Template'!O12),"", 'Ingest Template'!O12&"|TV Ops"),CHAR(10), IF(ISBLANK('Ingest Template'!P12),"", 'Ingest Template'!P12&"|TV Ops"))))} | AJ12: =if('Ingest Template'!A12="Standard",(IF(OR('Ingest Template'!F12 = "Program Type - Special", 'Ingest Template'!F12 = "Program Type - Live Event"),'Ingest Template'!M12& "|DAR|DAR|"&TEXT('Ingest Template'!C12-3, "yyyy-mm-dd")&"|"&TEXT('Ingest Template'!C12+3, "yyyy-mm-dd"),'Ingest Template'!M12& "|DAR|DAR|2021-01-01")),(IF(OR('Ingest Template'!F12 = "Program Type - Special", 'Ingest Template'!F12 = "Program Type - Live Event"),'Ingest Template'!M12& "|Operations - Core Title|Operations - Core Title|"&TEXT('Ingest Template'!C12-3, "yyyy-mm-dd")&"|"&TEXT('Ingest Template'!C12+3, "yyyy-mm-dd"),'Ingest Template'!M12& "|Operations - Core Title|Operations - Core Title"))) -> |Operations - Core Title|Operations - Core Title | AL12: =if('Ingest Template'!A12="Standard",(IF(OR('Ingest Template'!F12 = "Program Type - Special", 'Ingest Template'!F12 = "Program Type - Live Event"),'Ingest Template'!Q12&"|"&TEXT('Ingest Template'!C12-3, "yyyy-mm-dd")&"|"&TEXT('Ingest Template'!C12+3, "yyyy-mm-dd"),'Ingest Template'!Q12& "|2021-01-01")),(IF(OR('Ingest Template'!F12 = "Program Type - Special", 'Ingest Template'!F12 = "Program Type - Live Event"),'Ingest Template'!Q12& "|"&TEXT('Ingest Template'!C12-3, "yyyy-mm-dd")&"|"&TEXT('Ingest Template'!C12+3, "yyyy-mm-dd"),'Ingest Template'!Q12))) | AM12: ='Ingest Template'!AC12
B13: ='Ingest Template'!C13&IF('Ingest Template'!A13 = "Standard", " - DAR","") | C13: TV Shows | D13: {=CONCATENATE(INDEX(DropdownLists!$H$2:$H$11,MATCH(1,COUNTIF('Ingest Template'!E13,"*"&DropdownLists!$I$2:$I$11&"*"),0)),CHAR(10),'Ingest Template'!F13,CHAR(10),'Ingest Template'!G13,CHAR(10),VLOOKUP('Ingest Template'!D13,DropdownLists!C:D,2,FALSE))} -> #N/A | E13: =CONCATENATE('Ingest Template'!H13,CHAR(10),'Ingest Template'!I13,CHAR(10),'Ingest Template'!J13,CHAR(10)) | F13: {=INDEX(DropdownLists!$O$2:$O$36,MATCH(1,COUNTIF(E13,"*"&DropdownLists!$N$2:$N$36&"*"),0))} | H13: {=INDEX(DropdownLists!$E$2:$E$276,MATCH('Ingest Template'!D13,DropdownLists!$C$2:$C$276,0))} -> #N/A | J13: {=iF('Ingest Template'!A13="Standard","Pristine Brand",INDEX(DropdownLists!$B$2:$B$246,MATCH('Ingest Template'!D13,DropdownLists!$C$2:$C$246,0)))} -> #N/A | K13: =iF('Ingest Template'!A13="Standard",'Ingest Template'!K13&CHAR(10)&'Ingest Template'!L13,"Competitive View") -> Competitive View | L13: t | M13: ='Ingest Template'!B13 | R13: ='Ingest Template'!D13 | S13: f | T13: ='Ingest Template'!V13 | U13: ='Ingest Template'!W13 | V13: =LOWER(SUBSTITUTE(SUBSTITUTE(SUBSTITUTE(SUBSTITUTE(SUBSTITUTE('Ingest Template'!X13,"https:",""),"www.",""),"/",""),"?hl=en",""),"instagram.com","")) | W13: {=IF( 'Ingest Template'!Y13="", SUBSTITUTE( INDEX(DropdownLists!$F$2:$F$277,MATCH('Ingest Template'!D13,DropdownLists!$C$2:$C$277,0)), CHAR(10), "|"&'Ingest Template'!C13&CHAR(10) )&"|"&'Ingest Template'!C13, SUBSTITUTE( INDEX(DropdownLists!$F$2:$F$277,MATCH('Ingest Template'!D13,DropdownLists!$C$2:$C$277,0)), CHAR(10), "|"&'Ingest Template'!C13&CHAR(10) )&"|"&'Ingest Template'!C13&CHAR(10)&'Ingest Template'!Y13 )} -> #N/A | X13: ='Ingest Template'!Z13 | Y13: =SUBSTITUTE(SUBSTITUTE(SUBSTITUTE('Ingest Template'!AA13,"http:",""),"https:",""),"/","") | Z13: {=IF('Ingest Template'!A13="Standard",(IF(ISBLANK('Ingest Template'!AB13),"", 'Ingest Template'!AB13&"|DAR")),(IF(ISBLANK('Ingest Template'!AB13),"", 'Ingest Template'!AB13&"|TV Ops")))} | AB13: ='Ingest Template'!R13 | AC13: ='Ingest Template'!T13 | AD13: ='Ingest Template'!S13 | AE13: ='Ingest Template'!U13 | AG13: {=IF('Ingest Template'!A13="Standard",(CONCATENATE(IF(ISBLANK('Ingest Template'!N13),"", 'Ingest Template'!N13&"|DAR"),CHAR(10), IF(ISBLANK('Ingest Template'!O13),"", 'Ingest Template'!O13&"|DAR"),CHAR(10), IF(ISBLANK('Ingest Template'!P13),"", 'Ingest Template'!P13&"|DAR"))),(CONCATENATE(IF(ISBLANK('Ingest Template'!N13),"", 'Ingest Template'!N13&"|TV Ops"),CHAR(10), IF(ISBLANK('Ingest Template'!O13),"", 'Ingest Template'!O13&"|TV Ops"),CHAR(10), IF(ISBLANK('Ingest Template'!P13),"", 'Ingest Template'!P13&"|TV Ops"))))} | AJ13: =if('Ingest Template'!A13="Standard",(IF(OR('Ingest Template'!F13 = "Program Type - Special", 'Ingest Template'!F13 = "Program Type - Live Event"),'Ingest Template'!M13& "|DAR|DAR|"&TEXT('Ingest Template'!C13-3, "yyyy-mm-dd")&"|"&TEXT('Ingest Template'!C13+3, "yyyy-mm-dd"),'Ingest Template'!M13& "|DAR|DAR|2021-01-01")),(IF(OR('Ingest Template'!F13 = "Program Type - Special", 'Ingest Template'!F13 = "Program Type - Live Event"),'Ingest Template'!M13& "|Operations - Core Title|Operations - Core Title|"&TEXT('Ingest Template'!C13-3, "yyyy-mm-dd")&"|"&TEXT('Ingest Template'!C13+3, "yyyy-mm-dd"),'Ingest Template'!M13& "|Operations - Core Title|Operations - Core Title"))) -> |Operations - Core Title|Operations - Core Title | AL13: =if('Ingest Template'!A13="Standard",(IF(OR('Ingest Template'!F13 = "Program Type - Special", 'Ingest Template'!F13 = "Program Type - Live Event"),'Ingest Template'!Q13&"|"&TEXT('Ingest Template'!C13-3, "yyyy-mm-dd")&"|"&TEXT('Ingest Template'!C13+3, "yyyy-mm-dd"),'Ingest Template'!Q13& "|2021-01-01")),(IF(OR('Ingest Template'!F13 = "Program Type - Special", 'Ingest Template'!F13 = "Program Type - Live Event"),'Ingest Template'!Q13& "|"&TEXT('Ingest Template'!C13-3, "yyyy-mm-dd")&"|"&TEXT('Ingest Template'!C13+3, "yyyy-mm-dd"),'Ingest Template'!Q13))) | AM13: ='Ingest Template'!AC13
... B1008: ='Ingest Template'!C1008&IF('Ingest Template'!A1008 = "Standard", " - DAR","") | C1008: TV Shows | D1008: {=CONCATENATE(INDEX(DropdownLists!$H$2:$H$11,MATCH(1,COUNTIF('Ingest Template'!E1008,"*"&DropdownLists!$I$2:$I$11&"*"),0)),CHAR(10),'Ingest Template'!F1008,CHAR(10),'Ingest Template'!G1008,CHAR(10),VLOOKUP('Ingest Template'!D1008,DropdownLists!C:D,2,FALSE))} -> #N/A | E1008: =CONCATENATE('Ingest Template'!H1008,CHAR(10),'Ingest Template'!I1008,CHAR(10),'Ingest Template'!J1008,CHAR(10)) | F1008: {=INDEX(DropdownLists!$O$2:$O$36,MATCH(1,COUNTIF(E1008,"*"&DropdownLists!$N$2:$N$36&"*"),0))} | H1008: {=INDEX(DropdownLists!$E$2:$E$276,MATCH('Ingest Template'!D1008,DropdownLists!$C$2:$C$276,0))} -> #N/A | J1008: {=iF('Ingest Template'!A1008="Standard","Pristine Brand",INDEX(DropdownLists!$B$2:$B$246,MATCH('Ingest Template'!D1008,DropdownLists!$C$2:$C$246,0)))} -> #N/A | K1008: =iF('Ingest Template'!A1008="Standard",'Ingest Template'!K1008&CHAR(10)&'Ingest Template'!L1008,"Competitive View") -> Competitive View | L1008: t | M1008: ='Ingest Template'!B1008 | R1008: ='Ingest Template'!D1008 | S1008: f | T1008: ='Ingest Template'!V1008 | U1008: ='Ingest Template'!W1008 | V1008: =LOWER(SUBSTITUTE(SUBSTITUTE(SUBSTITUTE(SUBSTITUTE(SUBSTITUTE('Ingest Template'!X1008,"https:",""),"www.",""),"/",""),"?hl=en",""),"instagram.com","")) | W1008: {=IF( 'Ingest Template'!Y1008="", SUBSTITUTE( INDEX(DropdownLists!$F$2:$F$277,MATCH('Ingest Template'!D1008,DropdownLists!$C$2:$C$277,0)), CHAR(10), "|"&'Ingest Template'!C1008&CHAR(10) )&"|"&'Ingest Template'!C1008, SUBSTITUTE( INDEX(DropdownLists!$F$2:$F$277,MATCH('Ingest Template'!D1008,DropdownLists!$C$2:$C$277,0)), CHAR(10), "|"&'Ingest Template'!C1008&CHAR(10) )&"|"&'Ingest Template'!C1008&CHAR(10)&'Ingest Template'!Y1008 )} -> #N/A | X1008: ='Ingest Template'!Z1008 | Y1008: =SUBSTITUTE(SUBSTITUTE(SUBSTITUTE('Ingest Template'!AA1008,"http:",""),"https:",""),"/","") | Z1008: {=IF('Ingest Template'!A1008="Standard",(IF(ISBLANK('Ingest Template'!AB1008),"", 'Ingest Template'!AB1008&"|DAR")),(IF(ISBLANK('Ingest Template'!AB1008),"", 'Ingest Template'!AB1008&"|TV Ops")))} | AB1008: ='Ingest Template'!R1008 | AC1008: ='Ingest Template'!T1008 | AD1008: ='Ingest Template'!S1008 | AE1008: ='Ingest Template'!U1008 | AG1008: {=IF('Ingest Template'!A1008="Standard",(CONCATENATE(IF(ISBLANK('Ingest Template'!N1008),"", 'Ingest Template'!N1008&"|DAR"),CHAR(10), IF(ISBLANK('Ingest Template'!O1008),"", 'Ingest Template'!O1008&"|DAR"),CHAR(10), IF(ISBLANK('Ingest Template'!P1008),"", 'Ingest Template'!P1008&"|DAR"))),(CONCATENATE(IF(ISBLANK('Ingest Template'!N1008),"", 'Ingest Template'!N1008&"|TV Ops"),CHAR(10), IF(ISBLANK('Ingest Template'!O1008),"", 'Ingest Template'!O1008&"|TV Ops"),CHAR(10), IF(ISBLANK('Ingest Template'!P1008),"", 'Ingest Template'!P1008&"|TV Ops"))))} | AJ1008: =if('Ingest Template'!A1008="Standard",(IF(OR('Ingest Template'!F1008 = "Program Type - Special", 'Ingest Template'!F1008 = "Program Type - Live Event"),'Ingest Template'!M1008& "|DAR|DAR|"&TEXT('Ingest Template'!C1008-3, "yyyy-mm-dd")&"|"&TEXT('Ingest Template'!C1008+3, "yyyy-mm-dd"),'Ingest Template'!M1008& "|DAR|DAR|2021-01-01")),(IF(OR('Ingest Template'!F1008 = "Program Type - Special", 'Ingest Template'!F1008 = "Program Type - Live Event"),'Ingest Template'!M1008& "|Operations - Core Title|Operations - Core Title|"&TEXT('Ingest Template'!C1008-3, "yyyy-mm-dd")&"|"&TEXT('Ingest Template'!C1008+3, "yyyy-mm-dd"),'Ingest Template'!M1008& "|Operations - Core Title|Operations - Core Title"))) -> |Operations - Core Title|Operations - Core Title | AL1008: =if('Ingest Template'!A1008="Standard",(IF(OR('Ingest Template'!F1008 = "Program Type - Special", 'Ingest Template'!F1008 = "Program Type - Live Event"),'Ingest Template'!Q1008&"|"&TEXT('Ingest Template'!C1008-3, "yyyy-mm-dd")&"|"&TEXT('Ingest Template'!C1008+3, "yyyy-mm-dd"),'Ingest Template'!Q1008& "|2021-01-01")),(IF(OR('Ingest Template'!F1008 = "Program Type - Special", 'Ingest Template'!F1008 = "Program Type - Live Event"),'Ingest Template'!Q1008& "|"&TEXT('Ingest Template'!C1008-3, "yyyy-mm-dd")&"|"&TEXT('Ingest Template'!C1008+3, "yyyy-mm-dd"),'Ingest Template'!Q1008))) | AM1008: ='Ingest Template'!AC1008

Sheet Ingest Template
A1: Perspective | B1: Release Date | C1: Title | D1: Network | E1: Daypart | F1: Program Type | G1: Language Type | H1: Genre 1 | I1: Genre 2 | J1: Genre 3 | K1: TV Brand Sets | L1: Conglomerate Brand Sets | M1: Twitter Keyword (Search String) | N1: Twitter Hashtag 1 | O1: # 2 | P1: # 3 | Q1: Reddit Keyword (Search String) | R1: Wikipedia | S1: IMDB (URL) | T1: Rotten Tomatoes | U1: Metacritic | V1: Facebook Page (URL) | W1: Twitter Page (URL) | X1: Instagram Account (URL) | Y1: YouTube (Brand) | Z1: TikTok | AA1: Tumblr | AB1: Pinterest User (Handle) | AC1: URL Manager

Sheet Twitter Episodic Keyword Method
A1: Twitter Episodic Keyword Methodology
A2: 1. Default: | B2: (“title name”)(“Network/Studio Name” OR Network/Studio Handle OR Network/Studio Hashtag OR “Year of release" OR "All New" OR Episode OR Watch OR tv OR Show OR Series OR season OR binge OR Stream OR Film OR Movie OR Premiere OR Screening OR Feature OR Trailer OR Teaser OR theater OR release)
A3: 2. Tier 1 Modification (If the default keyword fails the 75% test) | B3: (“title name”)(“Network/Studio Name” OR Network/Studio Handle OR Network/Studio Hashtag)
A4: 2. Tier 2 Modification (If Tier 1 modification fails the 75% test) | B4: (“title name”)(“Network/Studio Name”)(network/Studio Handle OR Network/Studio Hashtag)
A5: 4. Use Human Judgement

Sheet TV Brand sets
B1: Episodic | D1: Episodic +
A3: Enter Network Below:
B4: Program Type | D4: Program Type
B5: Series & Mini-Series (exclude news & sports) | D5: TV Movie | E5: Special/Live Event/News/Sports series
A6: . | B6: =$A$5&" -- Episodic + Roll-Up" -> -- Episodic + Roll-Up | D6: LF // TV Universe | E6: =D6 -> LF // TV Universe
B7: =$A$5&"-- Episodic Network Roll-Up" -> -- Episodic Network Roll-Up | D7: LF // TV // Episodic Plus | E7: =D7 -> LF // TV // Episodic Plus
B8: LF // TV Universe | D8: =$A$5&" -- Episodic + Roll-Up" -> -- Episodic + Roll-Up | E8: =$A$5&" -- Episodic + Roll-Up" -> -- Episodic + Roll-Up
B9: LF // TV // Episodic | D9: LF // Film - Majors + Independents
B10: LF // TV // Episodic Plus

Sheet Conglomerate Brand Sets
B1: Brand Sets
A2: A&E | B2: A+E > TV Roll-up A+E > TV + Publishing Roll-up A+E > Film + TV + Publishing Roll-up
A3: ABC | B3: The Walt Disney Company > Overall Roll-up The Walt Disney Company > TV Roll-up The Walt Disney Company > TV Broadcast Roll-up The Walt Disney Company > TV + Publishing Roll-up The Walt Disney Company > Film + TV + Publishing Roll-up
A4: Acorn TV | B4: Acorn TV Network
A5: Adult Swim | B5: WarnerMedia > Overall Roll-up WarnerMedia > TV Roll-up WarnerMedia > TV Cable Roll-up WarnerMedia > TV + Publishing Roll-up WarnerMedia > Film + TV + Publishing Roll-up AT&T Overall Roll-Up
A6: ALLBLK | B6: ALLBLK TV Network
A7: Amazon Prime Video | B7: Amazon Prime Video TV Network Amazon Prime Video - Emerging Titles PV Monthly - Emerging Titles
A8: AMC | B8: AMCN > TV Roll-up AMCN > TV + Publishing Roll-up AMCN > Film + TV + Publishing Roll-up AMCN + BBCA Roll-Up AMC TV Network
A9: AMC - Episodic Only (Series & Mini-Series) | B9: AMCN > TV Roll-up AMCN > TV + Publishing Roll-up AMCN > Film + TV + Publishing Roll-up AMC [Custom]-- Episodic Network Roll-Up
A10: American Heroes Channel | B10: Discovery > TV Roll-up Discovery > TV + Publishing Roll-up Discovery > Film + TV + Publishing Roll-up
A11: Animal Planet | B11: Discovery > TV Roll-up Discovery > TV + Publishing Roll-up Discovery > Film + TV + Publishing Roll-up
A12: Apple TV+
A13: Audience Network | B13: AT&T > TV + Publishing Roll-up AT&T > Film + TV + Publishing Roll-up AT&T Communications Roll-up AT&T Overall Roll-Up
A14: BabyTV | B14: The Walt Disney Company > Overall Roll-up The Walt Disney Company > TV Roll-up The Walt Disney Company > TV Cable Roll-up The Walt Disney Company > TV + Publishing Roll-up The Walt Disney Company > Film + TV + Publishing Roll-up
A15: BBC America | B15: AMCN + BBCA Roll-Up BBC America TV Network
A16: BET | B16: Paramount > Overall Roll-up Paramount > TV Roll-up Paramount > TV Cable Roll-up Paramount > TV + Publishing Roll-up Paramount > Film + TV + Publishing Roll-up
A17: Boomerang | B17: WarnerMedia > Overall Roll-up WarnerMedia > TV Roll-up WarnerMedia > TV Cable Roll-up WarnerMedia > TV + Publishing Roll-up WarnerMedia > Film + TV + Publishing Roll-up AT&T Overall Roll-Up
A18: Bravo | B18: NBCUniversal > Overall Roll-up NBCUniversal > TV Roll-up NBCUniversal > TV Cable Roll-up NBCUniversal > TV + Publishing Roll-up NBCUniversal > Film + TV + Publishing Roll-up
A19: Cartoon Network | B19: WarnerMedia > Overall Roll-up WarnerMedia > TV Roll-up WarnerMedia > TV Cable Roll-up WarnerMedia > TV + Publishing Roll-up WarnerMedia > Film + TV + Publishing Roll-up AT&T Overall Roll-Up
A20: CBS | B20: Paramount > Overall Roll-up Paramount > TV Roll-up Paramount > TV Cable Roll-up Paramount > TV + Publishing Roll-up Paramount > Film + TV + Publishing Roll-up
A21: CBS | B21: Paramount > Overall Roll-up Paramount > TV Roll-up Paramount > TV Broadcast Roll-up Paramount > TV + Publishing Roll-up Paramount > Film + TV + Publishing Roll-up
A22: CBS All Access
A23: Centric | B23: Paramount > Overall Roll-up Paramount > TV Roll-up Paramount > TV Cable Roll-up Paramount > TV + Publishing Roll-up Paramount > Film + TV + Publishing Roll-up
A24: Chiller | B24: NBCUniversal > Overall Roll-up NBCUniversal > TV Roll-up NBCUniversal > TV Cable Roll-up NBCUniversal > TV + Publishing Roll-up NBCUniversal > Film + TV + Publishing Roll-up
A25: Cinemax | B25: WarnerMedia > Overall Roll-up WarnerMedia > TV Roll-up WarnerMedia > TV Cable Roll-up WarnerMedia > TV + Publishing Roll-up WarnerMedia > Film + TV + Publishing Roll-up AT&T Overall Roll-Up
A26: CMT | B26: Paramount > Overall Roll-up Paramount > TV Roll-up Paramount > TV Cable Roll-up Paramount > TV + Publishing Roll-up Paramount > Film + TV + Publishing Roll-up
A27: CNBC | B27: NBCUniversal > Overall Roll-up NBCUniversal > TV Roll-up NBCUniversal > TV Cable Roll-up NBCUniversal > TV + Publishing Roll-up NBCUniversal > Film + TV + Publishing Roll-up
A28: CNN | B28: WarnerMedia > Overall Roll-up WarnerMedia > TV Roll-up WarnerMedia > TV Cable Roll-up WarnerMedia > TV + Publishing Roll-up WarnerMedia > Film + TV + Publishing Roll-up AT&T Overall Roll-Up
A29: CNN en Espanol | B29: WarnerMedia > Overall Roll-up WarnerMedia > TV Roll-up WarnerMedia > TV Cable Roll-up WarnerMedia > TV + Publishing Roll-up WarnerMedia > Film + TV + Publishing Roll-up AT&T Overall Roll-Up
A30: CNN International | B30: WarnerMedia > Overall Roll-up WarnerMedia > TV Roll-up WarnerMedia > TV Cable Roll-up WarnerMedia > TV + Publishing Roll-up WarnerMedia > Film + TV + Publishing Roll-up AT&T Overall Roll-Up
A31: Comedy Central | B31: Paramount > Overall Roll-up Paramount > TV Roll-up Paramount > TV Cable Roll-up Paramount > TV + Publishing Roll-up Paramount > Film + TV + Publishing Roll-up
A32: Cooking Channel | B32: Discovery > TV Roll-up Discovery > TV + Publishing Roll-up Discovery > Film + TV + Publishing Roll-up
A33: Crackle
A34: Crime & Investigation Network | B34: A+E > TV Roll-up A+E > TV + Publishing Roll-up A+E > Film + TV + Publishing Roll-up
A35: Destination America | B35: Discovery > TV Roll-up Discovery > TV + Publishing Roll-up Discovery > Film + TV + Publishing Roll-up
A36: Discovery | B36: Discovery > TV Roll-up Discovery > TV + Publishing Roll-up Discovery > Film + TV + Publishing Roll-up
