Workbook

Sheet BDR
A1: brand_id | B1: title | C1: title_category | D1: title_sub_category | E1: genre | F1: primary_genre | G1: rovi_id | H1: ticker_symbol | I1: title_content_windows | J1: companies | K1: brand_set | L1: active | M1: released_on | N1: box_office | O1: street_date | P1: gross_screen | Q1: opening_weekend_box_office | R1: network | S1: brand_listing_hidden | T1: facebook_page | U1: twitter_handle | V1: instagram_user | W1: youtube_channel_username | X1: tiktok_user | Y1: tumblr_page | Z1: pinterest_user_username | AA1: pinterest_board | AB1: wikipedia_page | AC1: rottentomatoes | AD1: imdb_id | AE1: metacritic | AF1: facebook_search_terms | AG1: twitter_search_terms | AH1: instagram_search_terms | AI1: tumblr_search_terms | AJ1: twitter_search_term_keywords | AK1: youtube_search_terms | AL1: reddit_search_terms | AM1: url_managers
B2: ='Ingest Template'!C2&IF('Ingest Template'!A2 = "Standard", " - DAR","") | C2: Video Game | D2: =CONCATENATE('Ingest Template'!E2&Char(10)&'Ingest Template'!G2&Char(10)&'Ingest Template'!H2&Char(10)&'Ingest Template'!I2&Char(10)&'Ingest Template'!J2&Char(10)&'Ingest Template'!K2&Char(10)&'Ingest Template'!L2) | E2: =('Ingest Template'!M2) | F2: {=INDEX(DropDown!$J$2:$J$63,MATCH(1,COUNTIF(E2,DropDown!$I$2:$I$63),0))} -> #N/A | J2: ='Ingest Template'!B2 | K2: =IF('Ingest Template'!A2="Standard",'Ingest Template'!N2,"Competitive View") -> Competitive View | L2: t | M2: ='Ingest Template'!D2 | R2: =CONCATENATE('Ingest Template'!F2) | S2: f | T2: ='Ingest Template'!W2 | U2: ='Ingest Template'!X2 | V2: =LOWER(SUBSTITUTE(SUBSTITUTE(SUBSTITUTE(SUBSTITUTE(SUBSTITUTE('Ingest Template'!Y2,"https:",""),"www.",""),"/",""),"?hl=en",""),"instagram.com","")) | W2: =(IFERROR(vlookup('Ingest Template'!F2,DropDown!D:E,2,false)&'Ingest Template'!C2,"")) | X2: ='Ingest Template'!AA2 | AB2: ='Ingest Template'!T2 | AD2: ='Ingest Template'!U2 | AE2: ='Ingest Template'!V2 | AG2: {=IF('Ingest Template'!A2="Standard",(CONCATENATE(IF(ISBLANK('Ingest Template'!O2),"", 'Ingest Template'!O2&"|DAR"),CHAR(10), IF(ISBLANK('Ingest Template'!P2),"", 'Ingest Template'!P2&"|DAR"),CHAR(10), IF(ISBLANK('Ingest Template'!Q2),"", 'Ingest Template'!Q2&"|DAR"))),(CONCATENATE(IF(ISBLANK('Ingest Template'!O2),"", 'Ingest Template'!O2&"|Operations - Core Title"),CHAR(10), IF(ISBLANK('Ingest Template'!P2),"", 'Ingest Template'!P2&"|Operations - Core Title"),CHAR(10), IF(ISBLANK('Ingest Template'!Q2),"", 'Ingest Template'!Q2&"|Operations - Core Title"))))} -> #|Operations - Core Title #videoGame|Operations - Core Title | AJ2: =if('Ingest Template'!A2="Standard",'Ingest Template'!R2& "|DAR|DAR|2021-01-01",'Ingest Template'!R2& "|Operations - Core Title|Operations - Core Title") -> #N/A | AL2: =if('Ingest Template'!A2="Standard",'Ingest Template'!S2& "|2021-01-01",'Ingest Template'!S2) -> #N/A
B3: ='Ingest Template'!C3&IF('Ingest Template'!A3 = "Standard", " - DAR","") | C3: Video Game | D3: =CONCATENATE('Ingest Template'!E3&Char(10)&'Ingest Template'!G3&Char(10)&'Ingest Template'!H3&Char(10)&'Ingest Template'!I3&Char(10)&'Ingest Template'!J3&Char(10)&'Ingest Template'!K3&Char(10)&'Ingest Template'!L3) | E3: =('Ingest Template'!M3) | F3: {=INDEX(DropDown!$J$2:$J$63,MATCH(1,COUNTIF(E3,DropDown!$I$2:$I$63),0))} -> #N/A | J3: ='Ingest Template'!B3 | K3: =IF('Ingest Template'!A3="Standard",'Ingest Template'!N3,"Competitive View") -> Competitive View | L3: t | M3: ='Ingest Template'!D3 | R3: =CONCATENATE('Ingest Template'!F3) | S3: f | T3: ='Ingest Template'!W3 | U3: ='Ingest Template'!X3 | V3: =LOWER(SUBSTITUTE(SUBSTITUTE(SUBSTITUTE(SUBSTITUTE(SUBSTITUTE('Ingest Template'!Y3,"https:",""),"www.",""),"/",""),"?hl=en",""),"instagram.com","")) | W3: =(IFERROR(vlookup('Ingest Template'!F3,DropDown!D:E,2,false)&'Ingest Template'!C3,"")) | X3: ='Ingest Template'!AA3 | AB3: ='Ingest Template'!T3 | AD3: ='Ingest Template'!U3 | AE3: ='Ingest Template'!V3 | AG3: {=IF('Ingest Template'!A3="Standard",(CONCATENATE(IF(ISBLANK('Ingest Template'!O3),"", 'Ingest Template'!O3&"|DAR"),CHAR(10), IF(ISBLANK('Ingest Template'!P3),"", 'Ingest Template'!P3&"|DAR"),CHAR(10), IF(ISBLANK('Ingest Template'!Q3),"", 'Ingest Template'!Q3&"|DAR"))),(CONCATENATE(IF(ISBLANK('Ingest Template'!O3),"", 'Ingest Template'!O3&"|Operations - Core Title"),CHAR(10), IF(ISBLANK('Ingest Template'!P3),"", 'Ingest Template'!P3&"|Operations - Core Title"),CHAR(10), IF(ISBLANK('Ingest Template'!Q3),"", 'Ingest Template'!Q3&"|Operations - Core Title"))))} -> #|Operations - Core Title #videoGame|Operations - Core Title | AJ3: =if('Ingest Template'!A3="Standard",'Ingest Template'!R3& "|DAR|DAR|2021-01-01",'Ingest Template'!R3& "|Operations - Core Title|Operations - Core Title") -> #N/A | AL3: =if('Ingest Template'!A3="Standard",'Ingest Template'!S3& "|2021-01-01",'Ingest Template'!S3) -> #N/A
B4: ='Ingest Template'!C4&IF('Ingest Template'!A4 = "Standard", " - DAR","") | C4: Video Game | D4: =CONCATENATE('Ingest Template'!E4&Char(10)&'Ingest Template'!G4&Char(10)&'Ingest Template'!H4&Char(10)&'Ingest Template'!I4&Char(10)&'Ingest Template'!J4&Char(10)&'Ingest Template'!K4&Char(10)&'Ingest Template'!L4) | E4: =('Ingest Template'!M4) | F4: {=INDEX(DropDown!$J$2:$J$63,MATCH(1,COUNTIF(E4,DropDown!$I$2:$I$63),0))} -> #N/A | J4: ='Ingest Template'!B4 | K4: =IF('Ingest Template'!A4="Standard",'Ingest Template'!N4,"Competitive View") -> Competitive View | L4: t | M4: ='Ingest Template'!D4 | R4: =CONCATENATE('Ingest Template'!F4) | S4: f | T4: ='Ingest Template'!W4 | U4: ='Ingest Template'!X4 | V4: =LOWER(SUBSTITUTE(SUBSTITUTE(SUBSTITUTE(SUBSTITUTE(SUBSTITUTE('Ingest Template'!Y4,"https:",""),"www.",""),"/",""),"?hl=en",""),"instagram.com","")) | W4: =(IFERROR(vlookup('Ingest Template'!F4,DropDown!D:E,2,false)&'Ingest Template'!C4,"")) | X4: ='Ingest Template'!AA4 | AB4: ='Ingest Template'!T4 | AD4: ='Ingest Template'!U4 | AE4: ='Ingest Template'!V4 | AG4: {=IF('Ingest Template'!A4="Standard",(CONCATENATE(IF(ISBLANK('Ingest Template'!O4),"", 'Ingest Template'!O4&"|DAR"),CHAR(10), IF(ISBLANK('Ingest Template'!P4),"", 'Ingest Template'!P4&"|DAR"),CHAR(10), IF(ISBLANK('Ingest Template'!Q4),"", 'Ingest Template'!Q4&"|DAR"))),(CONCATENATE(IF(ISBLANK('Ingest Template'!O4),"", 'Ingest Template'!O4&"|Operations - Core Title"),CHAR(10), IF(ISBLANK('Ingest Template'!P4),"", 'Ingest Template'!P4&"|Operations - Core Title"),CHAR(10), IF(ISBLANK('Ingest Template'!Q4),"", 'Ingest Template'!Q4&"|Operations - Core Title"))))} -> #|Operations - Core Title #videoGame|Operations - Core Title | AJ4: =if('Ingest Template'!A4="Standard",'Ingest Template'!R4& "|DAR|DAR|2021-01-01",'Ingest Template'!R4& "|Operations - Core Title|Operations - Core Title") -> #N/A | AL4: =if('Ingest Template'!A4="Standard",'Ingest Template'!S4& "|2021-01-01",'Ingest Template'!S4) -> #N/A
B5: ='Ingest Template'!C5&IF('Ingest Template'!A5 = "Standard", " - DAR","") | C5: Video Game | D5: =CONCATENATE('Ingest Template'!E5&Char(10)&'Ingest Template'!G5&Char(10)&'Ingest Template'!H5&Char(10)&'Ingest Template'!I5&Char(10)&'Ingest Template'!J5&Char(10)&'Ingest Template'!K5&Char(10)&'Ingest Template'!L5) | E5: =('Ingest Template'!M5) | F5: {=INDEX(DropDown!$J$2:$J$63,MATCH(1,COUNTIF(E5,DropDown!$I$2:$I$63),0))} -> #N/A | J5: ='Ingest Template'!B5 | K5: =IF('Ingest Template'!A5="Standard",'Ingest Template'!N5,"Competitive View") -> Competitive View | L5: t | M5: ='Ingest Template'!D5 | R5: =CONCATENATE('Ingest Template'!F5) | S5: f | T5: ='Ingest Template'!W5 | U5: ='Ingest Template'!X5 | V5: =LOWER(SUBSTITUTE(SUBSTITUTE(SUBSTITUTE(SUBSTITUTE(SUBSTITUTE('Ingest Template'!Y5,"https:",""),"www.",""),"/",""),"?hl=en",""),"instagram.com","")) | W5: =(IFERROR(vlookup('Ingest Template'!F5,DropDown!D:E,2,false)&'Ingest Template'!C5,"")) | X5: ='Ingest Template'!AA5 | AB5: ='Ingest Template'!T5 | AD5: ='Ingest Template'!U5 | AE5: ='Ingest Template'!V5 | AG5: {=IF('Ingest Template'!A5="Standard",(CONCATENATE(IF(ISBLANK('Ingest Template'!O5),"", 'Ingest Template'!O5&"|DAR"),CHAR(10), IF(ISBLANK('Ingest Template'!P5),"", 'Ingest Template'!P5&"|DAR"),CHAR(10), IF(ISBLANK('Ingest Template'!Q5),"", 'Ingest Template'!Q5&"|DAR"))),(CONCATENATE(IF(ISBLANK('Ingest Template'!O5),"", 'Ingest Template'!O5&"|Operations - Core Title"),CHAR(10), IF(ISBLANK('Ingest Template'!P5),"", 'Ingest Template'!P5&"|Operations - Core Title"),CHAR(10), IF(ISBLANK('Ingest Template'!Q5),"", 'Ingest Template'!Q5&"|Operations - Core Title"))))} -> #|Operations - Core Title #videoGame|Operations - Core Title | AJ5: =if('Ingest Template'!A5="Standard",'Ingest Template'!R5& "|DAR|DAR|2021-01-01",'Ingest Template'!R5& "|Operations - Core Title|Operations - Core Title") -> #N/A | AL5: =if('Ingest Template'!A5="Standard",'Ingest Template'!S5& "|2021-01-01",'Ingest Template'!S5) -> #N/A
B6: ='Ingest Template'!C6&IF('Ingest Template'!A6 = "Standard", " - DAR","") | C6: Video Game | D6: =CONCATENATE('Ingest Template'!E6&Char(10)&'Ingest Template'!G6&Char(10)&'Ingest Template'!H6&Char(10)&'Ingest Template'!I6&Char(10)&'Ingest Template'!J6&Char(10)&'Ingest Template'!K6&Char(10)&'Ingest Template'!L6) | E6: =('Ingest Template'!M6) | F6: {=INDEX(DropDown!$J$2:$J$63,MATCH(1,COUNTIF(E6,DropDown!$I$2:$I$63),0))} -> #N/A | J6: ='Ingest Template'!B6 | K6: =IF('Ingest Template'!A6="Standard",'Ingest Template'!N6,"Competitive View") -> Competitive View | L6: t | M6: ='Ingest Template'!D6 | R6: =CONCATENATE('Ingest Template'!F6) | S6: f | T6: ='Ingest Template'!W6 | U6: ='Ingest Template'!X6 | V6: =LOWER(SUBSTITUTE(SUBSTITUTE(SUBSTITUTE(SUBSTITUTE(SUBSTITUTE('Ingest Template'!Y6,"https:",""),"www.",""),"/",""),"?hl=en",""),"instagram.com","")) | W6: =(IFERROR(vlookup('Ingest Template'!F6,DropDown!D:E,2,false)&'Ingest Template'!C6,"")) | X6: ='Ingest Template'!AA6 | AB6: ='Ingest Template'!T6 | AD6: ='Ingest Template'!U6 | AE6: ='Ingest Template'!V6 | AG6: {=IF('Ingest Template'!A6="Standard",(CONCATENATE(IF(ISBLANK('Ingest Template'!O6),"", 'Ingest Template'!O6&"|DAR"),CHAR(10), IF(ISBLANK('Ingest Template'!P6),"", 'Ingest Template'!P6&"|DAR"),CHAR(10), IF(ISBLANK('Ingest Template'!Q6),"", 'Ingest Template'!Q6&"|DAR"))),(CONCATENATE(IF(ISBLANK('Ingest Template'!O6),"", 'Ingest Template'!O6&"|Operations - Core Title"),CHAR(10), IF(ISBLANK('Ingest Template'!P6),"", 'Ingest Template'!P6&"|Operations - Core Title"),CHAR(10), IF(ISBLANK('Ingest Template'!Q6),"", 'Ingest Template'!Q6&"|Operations - Core Title"))))} -> #|Operations - Core Title #videoGame|Operations - Core Title | AJ6: =if('Ingest Template'!A6="Standard",'Ingest Template'!R6& "|DAR|DAR|2021-01-01",'Ingest Template'!R6& "|Operations - Core Title|Operations - Core Title") -> #N/A | AL6: =if('Ingest Template'!A6="Standard",'Ingest Template'!S6& "|2021-01-01",'Ingest Template'!S6) -> #N/A
B7: ='Ingest Template'!C7&IF('Ingest Template'!A7 = "Standard", " - DAR","") | C7: Video Game | D7: =CONCATENATE('Ingest Template'!E7&Char(10)&'Ingest Template'!G7&Char(10)&'Ingest Template'!H7&Char(10)&'Ingest Template'!I7&Char(10)&'Ingest Template'!J7&Char(10)&'Ingest Template'!K7&Char(10)&'Ingest Template'!L7) | E7: =('Ingest Template'!M7) | F7: {=INDEX(DropDown!$J$2:$J$63,MATCH(1,COUNTIF(E7,DropDown!$I$2:$I$63),0))} -> #N/A | J7: ='Ingest Template'!B7 | K7: =IF('Ingest Template'!A7="Standard",'Ingest Template'!N7,"Competitive View") -> Competitive View | L7: t | M7: ='Ingest Template'!D7 | R7: =CONCATENATE('Ingest Template'!F7) | S7: f | T7: ='Ingest Template'!W7 | U7: ='Ingest Template'!X7 | V7: =LOWER(SUBSTITUTE(SUBSTITUTE(SUBSTITUTE(SUBSTITUTE(SUBSTITUTE('Ingest Template'!Y7,"https:",""),"www.",""),"/",""),"?hl=en",""),"instagram.com","")) | W7: =(IFERROR(vlookup('Ingest Template'!F7,DropDown!D:E,2,false)&'Ingest Template'!C7,"")) | X7: ='Ingest Template'!AA7 | AB7: ='Ingest Template'!T7 | AD7: ='Ingest Template'!U7 | AE7: ='Ingest Template'!V7 | AG7: {=IF('Ingest Template'!A7="Standard",(CONCATENATE(IF(ISBLANK('Ingest Template'!O7),"", 'Ingest Template'!O7&"|DAR"),CHAR(10), IF(ISBLANK('Ingest Template'!P7),"", 'Ingest Template'!P7&"|DAR"),CHAR(10), IF(ISBLANK('Ingest Template'!Q7),"", 'Ingest Template'!Q7&"|DAR"))),(CONCATENATE(IF(ISBLANK('Ingest Template'!O7),"", 'Ingest Template'!O7&"|Operations - Core Title"),CHAR(10), IF(ISBLANK('Ingest Template'!P7),"", 'Ingest Template'!P7&"|Operations - Core Title"),CHAR(10), IF(ISBLANK('Ingest Template'!Q7),"", 'Ingest Template'!Q7&"|Operations - Core Title"))))} -> #|Operations - Core Title #videoGame|Operations - Core Title | AJ7: =if('Ingest Template'!A7="Standard",'Ingest Template'!R7& "|DAR|DAR|2021-01-01",'Ingest Template'!R7& "|Operations - Core Title|Operations - Core Title") -> #N/A | AL7: =if('Ingest Template'!A7="Standard",'Ingest Template'!S7& "|2021-01-01",'Ingest Template'!S7) -> #N/A
B8: ='Ingest Template'!C8&IF('Ingest Template'!A8 = "Standard", " - DAR","") | C8: Video Game | D8: =CONCATENATE('Ingest Template'!E8&Char(10)&'Ingest Template'!G8&Char(10)&'Ingest Template'!H8&Char(10)&'Ingest Template'!I8&Char(10)&'Ingest Template'!J8&Char(10)&'Ingest Template'!K8&Char(10)&'Ingest Template'!L8) | E8: =('Ingest Template'!M8) | F8: {=INDEX(DropDown!$J$2:$J$63,MATCH(1,COUNTIF(E8,DropDown!$I$2:$I$63),0))} -> #N/A | J8: ='Ingest Template'!B8 | K8: =IF('Ingest Template'!A8="Standard",'Ingest Template'!N8,"Competitive View") -> Competitive View | L8: t | M8: ='Ingest Template'!D8 | R8: =CONCATENATE('Ingest Template'!F8) | S8: f | T8: ='Ingest Template'!W8 | U8: ='Ingest Template'!X8 | V8: =LOWER(SUBSTITUTE(SUBSTITUTE(SUBSTITUTE(SUBSTITUTE(SUBSTITUTE('Ingest Template'!Y8,"https:",""),"www.",""),"/",""),"?hl=en",""),"instagram.com","")) | W8: =(IFERROR(vlookup('Ingest Template'!F8,DropDown!D:E,2,false)&'Ingest Template'!C8,"")) | X8: ='Ingest Template'!AA8 | AB8: ='Ingest Template'!T8 | AD8: ='Ingest Template'!U8 | AE8: ='Ingest Template'!V8 | AG8: {=IF('Ingest Template'!A8="Standard",(CONCATENATE(IF(ISBLANK('Ingest Template'!O8),"", 'Ingest Template'!O8&"|DAR"),CHAR(10), IF(ISBLANK('Ingest Template'!P8),"", 'Ingest Template'!P8&"|DAR"),CHAR(10), IF(ISBLANK('Ingest Template'!Q8),"", 'Ingest Template'!Q8&"|DAR"))),(CONCATENATE(IF(ISBLANK('Ingest Template'!O8),"", 'Ingest Template'!O8&"|Operations - Core Title"),CHAR(10), IF(ISBLANK('Ingest Template'!P8),"", 'Ingest Template'!P8&"|Operations - Core Title"),CHAR(10), IF(ISBLANK('Ingest Template'!Q8),"", 'Ingest Template'!Q8&"|Operations - Core Title"))))} -> #|Operations - Core Title #videoGame|Operations - Core Title | AJ8: =if('Ingest Template'!A8="Standard",'Ingest Template'!R8& "|DAR|DAR|2021-01-01",'Ingest Template'!R8& "|Operations - Core Title|Operations - Core Title") -> #N/A | AL8: =if('Ingest Template'!A8="Standard",'Ingest Template'!S8& "|2021-01-01",'Ingest Template'!S8) -> #N/A
B9: ='Ingest Template'!C9&IF('Ingest Template'!A9 = "Standard", " - DAR","") | C9: Video Game | D9: =CONCATENATE('Ingest Template'!E9&Char(10)&'Ingest Template'!G9&Char(10)&'Ingest Template'!H9&Char(10)&'Ingest Template'!I9&Char(10)&'Ingest Template'!J9&Char(10)&'Ingest Template'!K9&Char(10)&'Ingest Template'!L9) | E9: =('Ingest Template'!M9) | F9: {=INDEX(DropDown!$J$2:$J$63,MATCH(1,COUNTIF(E9,DropDown!$I$2:$I$63),0))} -> #N/A | J9: ='Ingest Template'!B9 | K9: =IF('Ingest Template'!A9="Standard",'Ingest Template'!N9,"Competitive View") -> Competitive View | L9: t | M9: ='Ingest Template'!D9 | R9: =CONCATENATE('Ingest Template'!F9) | S9: f | T9: ='Ingest Template'!W9 | U9: ='Ingest Template'!X9 | V9: =LOWER(SUBSTITUTE(SUBSTITUTE(SUBSTITUTE(SUBSTITUTE(SUBSTITUTE('Ingest Template'!Y9,"https:",""),"www.",""),"/",""),"?hl=en",""),"instagram.com","")) | W9: =(IFERROR(vlookup('Ingest Template'!F9,DropDown!D:E,2,false)&'Ingest Template'!C9,"")) | X9: ='Ingest Template'!AA9 | AB9: ='Ingest Template'!T9 | AD9: ='Ingest Template'!U9 | AE9: ='Ingest Template'!V9 | AG9: {=IF('Ingest Template'!A9="Standard",(CONCATENATE(IF(ISBLANK('Ingest Template'!O9),"", 'Ingest Template'!O9&"|DAR"),CHAR(10), IF(ISBLANK('Ingest Template'!P9),"", 'Ingest Template'!P9&"|DAR"),CHAR(10), IF(ISBLANK('Ingest Template'!Q9),"", 'Ingest Template'!Q9&"|DAR"))),(CONCATENATE(IF(ISBLANK('Ingest Template'!O9),"", 'Ingest Template'!O9&"|Operations - Core Title"),CHAR(10), IF(ISBLANK('Ingest Template'!P9),"", 'Ingest Template'!P9&"|Operations - Core Title"),CHAR(10), IF(ISBLANK('Ingest Template'!Q9),"", 'Ingest Template'!Q9&"|Operations - Core Title"))))} -> #|Operations - Core Title #videoGame|Operations - Core Title | AJ9: =if('Ingest Template'!A9="Standard",'Ingest Template'!R9& "|DAR|DAR|2021-01-01",'Ingest Template'!R9& "|Operations - Core Title|Operations - Core Title") -> #N/A | AL9: =if('Ingest Template'!A9="Standard",'Ingest Template'!S9& "|2021-01-01",'Ingest Template'!S9) -> #N/A
B10: ='Ingest Template'!C10&IF('Ingest Template'!A10 = "Standard", " - DAR","") | C10: Video Game | D10: =CONCATENATE('Ingest Template'!E10&Char(10)&'Ingest Template'!G10&Char(10)&'Ingest Template'!H10&Char(10)&'Ingest Template'!I10&Char(10)&'Ingest Template'!J10&Char(10)&'Ingest Template'!K10&Char(10)&'Ingest Template'!L10) | E10: =('Ingest Template'!M10) | F10: {=INDEX(DropDown!$J$2:$J$63,MATCH(1,COUNTIF(E10,DropDown!$I$2:$I$63),0))} -> #N/A | J10: ='Ingest Template'!B10 | K10: =IF('Ingest Template'!A10="Standard",'Ingest Template'!N10,"Competitive View") -> Competitive View | L10: t | M10: ='Ingest Template'!D10 | R10: =CONCATENATE('Ingest Template'!F10) | S10: f | T10: ='Ingest Template'!W10 | U10: ='Ingest Template'!X10 | V10: =LOWER(SUBSTITUTE(SUBSTITUTE(SUBSTITUTE(SUBSTITUTE(SUBSTITUTE('Ingest Template'!Y10,"https:",""),"www.",""),"/",""),"?hl=en",""),"instagram.com","")) | W10: =(IFERROR(vlookup('Ingest Template'!F10,DropDown!D:E,2,false)&'Ingest Template'!C10,"")) | X10: ='Ingest Template'!AA10 | AB10: ='Ingest Template'!T10 | AD10: ='Ingest Template'!U10 | AE10: ='Ingest Template'!V10 | AG10: {=IF('Ingest Template'!A10="Standard",(CONCATENATE(IF(ISBLANK('Ingest Template'!O10),"", 'Ingest Template'!O10&"|DAR"),CHAR(10), IF(ISBLANK('Ingest Template'!P10),"", 'Ingest Template'!P10&"|DAR"),CHAR(10), IF(ISBLANK('Ingest Template'!Q10),"", 'Ingest Template'!Q10&"|DAR"))),(CONCATENATE(IF(ISBLANK('Ingest Template'!O10),"", 'Ingest Template'!O10&"|Operations - Core Title"),CHAR(10), IF(ISBLANK('Ingest Template'!P10),"", 'Ingest Template'!P10&"|Operations - Core Title"),CHAR(10), IF(ISBLANK('Ingest Template'!Q10),"", 'Ingest Template'!Q10&"|Operations - Core Title"))))} -> #|Operations - Core Title #videoGame|Operations - Core Title | AJ10: =if('Ingest Template'!A10="Standard",'Ingest Template'!R10& "|DAR|DAR|2021-01-01",'Ingest Template'!R10& "|Operations - Core Title|Operations - Core Title") -> #N/A | AL10: =if('Ingest Template'!A10="Standard",'Ingest Template'!S10& "|2021-01-01",'Ingest Template'!S10) -> #N/A
B11: ='Ingest Template'!C11&IF('Ingest Template'!A11 = "Standard", " - DAR","") | C11: Video Game | D11: =CONCATENATE('Ingest Template'!E11&Char(10)&'Ingest Template'!G11&Char(10)&'Ingest Template'!H11&Char(10)&'Ingest Template'!I11&Char(10)&'Ingest Template'!J11&Char(10)&'Ingest Template'!K11&Char(10)&'Ingest Template'!L11) | E11: =('Ingest Template'!M11) | F11: {=INDEX(DropDown!$J$2:$J$63,MATCH(1,COUNTIF(E11,DropDown!$I$2:$I$63),0))} -> #N/A | J11: ='Ingest Template'!B11 | K11: =IF('Ingest Template'!A11="Standard",'Ingest Template'!N11,"Competitive View") -> Competitive View | L11: t | M11: ='Ingest Template'!D11 | R11: =CONCATENATE('Ingest Template'!F11) | S11: f | T11: ='Ingest Template'!W11 | U11: ='Ingest Template'!X11 | V11: =LOWER(SUBSTITUTE(SUBSTITUTE(SUBSTITUTE(SUBSTITUTE(SUBSTITUTE('Ingest Template'!Y11,"https:",""),"www.",""),"/",""),"?hl=en",""),"instagram.com","")) | W11: =(IFERROR(vlookup('Ingest Template'!F11,DropDown!D:E,2,false)&'Ingest Template'!C11,"")) | X11: ='Ingest Template'!AA11 | AB11: ='Ingest Template'!T11 | AD11: ='Ingest Template'!U11 | AE11: ='Ingest Template'!V11 | AG11: {=IF('Ingest Template'!A11="Standard",(CONCATENATE(IF(ISBLANK('Ingest Template'!O11),"", 'Ingest Template'!O11&"|DAR"),CHAR(10), IF(ISBLANK('Ingest Template'!P11),"", 'Ingest Template'!P11&"|DAR"),CHAR(10), IF(ISBLANK('Ingest Template'!Q11),"", 'Ingest Template'!Q11&"|DAR"))),(CONCATENATE(IF(ISBLANK('Ingest Template'!O11),"", 'Ingest Template'!O11&"|Operations - Core Title"),CHAR(10), IF(ISBLANK('Ingest Template'!P11),"", 'Ingest Template'!P11&"|Operations - Core Title"),CHAR(10), IF(ISBLANK('Ingest Template'!Q11),"", 'Ingest Template'!Q11&"|Operations - Core Title"))))} -> #|Operations - Core Title #videoGame|Operations - Core Title | AJ11: =if('Ingest Template'!A11="Standard",'Ingest Template'!R11& "|DAR|DAR|2021-01-01",'Ingest Template'!R11& "|Operations - Core Title|Operations - Core Title") -> #N/A | AL11: =if('Ingest Template'!A11="Standard",'Ingest Template'!S11& "|2021-01-01",'Ingest Template'!S11) -> #N/A
B12: ='Ingest Template'!C11&IF('Ingest Template'!A11 = "Standard", " - DAR","") | C12: Video Game | D12: =CONCATENATE('Ingest Template'!E11&Char(10)&'Ingest Template'!G11&Char(10)&'Ingest Template'!H11&Char(10)&'Ingest Template'!I11&Char(10)&'Ingest Template'!J11&Char(10)&'Ingest Template'!K11&Char(10)&'Ingest Template'!L11) | E12: =('Ingest Template'!M11) | F12: {=INDEX(DropDown!$J$2:$J$63,MATCH(1,COUNTIF(E12,DropDown!$I$2:$I$63),0))} -> #N/A | J12: ='Ingest Template'!B12 | K12: =IF('Ingest Template'!A11="Standard",'Ingest Template'!N11,"Competitive View") -> Competitive View | L12: t | M12: ='Ingest Template'!D11 | R12: =CONCATENATE('Ingest Template'!F11) | S12: f | T12: ='Ingest Template'!W11 | V12: =LOWER(SUBSTITUTE(SUBSTITUTE(SUBSTITUTE(SUBSTITUTE(SUBSTITUTE('Ingest Template'!Y11,"https:",""),"www.",""),"/",""),"?hl=en",""),"instagram.com","")) | W12: =(IFERROR(vlookup('Ingest Template'!F11,DropDown!D:E,2,false)&'Ingest Template'!C11,"")) | X12: ='Ingest Template'!AA11 | AB12: ='Ingest Template'!T11 | AD12: ='Ingest Template'!U11 | AE12: ='Ingest Template'!V11 | AG12: {=IF('Ingest Template'!A11="Standard",(CONCATENATE(IF(ISBLANK('Ingest Template'!O11),"", 'Ingest Template'!O11&"|DAR"),CHAR(10), IF(ISBLANK('Ingest Template'!P11),"", 'Ingest Template'!P11&"|DAR"),CHAR(10), IF(ISBLANK('Ingest Template'!Q11),"", 'Ingest Template'!Q11&"|DAR"))),(CONCATENATE(IF(ISBLANK('Ingest Template'!O11),"", 'Ingest Template'!O11&"|Operations - Core Title"),CHAR(10), IF(ISBLANK('Ingest Template'!P11),"", 'Ingest Template'!P11&"|Operations - Core Title"),CHAR(10), IF(ISBLANK('Ingest Template'!Q11),"", 'Ingest Template'!Q11&"|Operations - Core Title"))))} -> #|Operations - Core Title #videoGame|Operations - Core Title | AJ12: =if('Ingest Template'!A11="Standard",'Ingest Template'!R11& "|DAR|DAR|2021-01-01",'Ingest Template'!R11& "|Operations - Core Title|Operations - Core Title") -> #N/A | AL12: =if('Ingest Template'!A11="Standard",'Ingest Template'!S11& "|2021-01-01",'Ingest Template'!S11) -> #N/A
B13: ='Ingest Template'!C12&IF('Ingest Template'!A12 = "Standard", " - DAR","") | C13: Video Game | D13: =CONCATENATE('Ingest Template'!E12&Char(10)&'Ingest Template'!G12&Char(10)&'Ingest Template'!H12&Char(10)&'Ingest Template'!I12&Char(10)&'Ingest Template'!J12&Char(10)&'Ingest Template'!K12&Char(10)&'Ingest Template'!L12) | E13: =('Ingest Template'!M12) | F13: {=INDEX(DropDown!$J$2:$J$63,MATCH(1,COUNTIF(E13,DropDown!$I$2:$I$63),0))} -> #N/A | J13: ='Ingest Template'!B13 | K13: =IF('Ingest Template'!A12="Standard",'Ingest Template'!N12,"Competitive View") -> Competitive View | L13: t | M13: ='Ingest Template'!D12 | R13: =CONCATENATE('Ingest Template'!F12) | S13: f | T13: ='Ingest Template'!W12 | V13: =LOWER(SUBSTITUTE(SUBSTITUTE(SUBSTITUTE(SUBSTITUTE(SUBSTITUTE('Ingest Template'!Y12,"https:",""),"www.",""),"/",""),"?hl=en",""),"instagram.com","")) | W13: =(IFERROR(vlookup('Ingest Template'!F12,DropDown!D:E,2,false)&'Ingest Template'!C12,"")) | X13: ='Ingest Template'!AA12 | AB13: ='Ingest Template'!T12 | AD13: ='Ingest Template'!U12 | AE13: ='Ingest Template'!V12 | AG13: {=IF('Ingest Template'!A12="Standard",(CONCATENATE(IF(ISBLANK('Ingest Template'!O12),"", 'Ingest Template'!O12&"|DAR"),CHAR(10), IF(ISBLANK('Ingest Template'!P12),"", 'Ingest Template'!P12&"|DAR"),CHAR(10), IF(ISBLANK('Ingest Template'!Q12),"", 'Ingest Template'!Q12&"|DAR"))),(CONCATENATE(IF(ISBLANK('Ingest Template'!O12),"", 'Ingest Template'!O12&"|Operations - Core Title"),CHAR(10), IF(ISBLANK('Ingest Template'!P12),"", 'Ingest Template'!P12&"|Operations - Core Title"),CHAR(10), IF(ISBLANK('Ingest Template'!Q12),"", 'Ingest Template'!Q12&"|Operations - Core Title"))))} -> #|Operations - Core Title #videoGame|Operations - Core Title | AJ13: =if('Ingest Template'!A12="Standard",'Ingest Template'!R12& "|DAR|DAR|2021-01-01",'Ingest Template'!R12& "|Operations - Core Title|Operations - Core Title") -> #N/A | AL13: =if('Ingest Template'!A12="Standard",'Ingest Template'!S12& "|2021-01-01",'Ingest Template'!S12) -> #N/A
B14: ='Ingest Template'!C13&IF('Ingest Template'!A13 = "Standard", " - DAR","") | C14: Video Game | D14: =CONCATENATE('Ingest Template'!E13&Char(10)&'Ingest Template'!G13&Char(10)&'Ingest Template'!H13&Char(10)&'Ingest Template'!I13&Char(10)&'Ingest Template'!J13&Char(10)&'Ingest Template'!K13&Char(10)&'Ingest Template'!L13) | E14: =('Ingest Template'!M13) | F14: {=INDEX(DropDown!$J$2:$J$63,MATCH(1,COUNTIF(E14,DropDown!$I$2:$I$63),0))} -> #N/A | J14: ='Ingest Template'!B14 | K14: =IF('Ingest Template'!A13="Standard",'Ingest Template'!N13,"Competitive View") -> Competitive View | L14: t | M14: ='Ingest Template'!D13 | R14: =CONCATENATE('Ingest Template'!F13) | S14: f | T14: ='Ingest Template'!W13 | V14: =LOWER(SUBSTITUTE(SUBSTITUTE(SUBSTITUTE(SUBSTITUTE(SUBSTITUTE('Ingest Template'!Y13,"https:",""),"www.",""),"/",""),"?hl=en",""),"instagram.com","")) | W14: =(IFERROR(vlookup('Ingest Template'!F13,DropDown!D:E,2,false)&'Ingest Template'!C13,"")) | X14: ='Ingest Template'!AA13 | AB14: ='Ingest Template'!T13 | AD14: ='Ingest Template'!U13 | AE14: ='Ingest Template'!V13 | AG14: {=IF('Ingest Template'!A13="Standard",(CONCATENATE(IF(ISBLANK('Ingest Template'!O13),"", 'Ingest Template'!O13&"|DAR"),CHAR(10), IF(ISBLANK('Ingest Template'!P13),"", 'Ingest Template'!P13&"|DAR"),CHAR(10), IF(ISBLANK('Ingest Template'!Q13),"", 'Ingest Template'!Q13&"|DAR"))),(CONCATENATE(IF(ISBLANK('Ingest Template'!O13),"", 'Ingest Template'!O13&"|Operations - Core Title"),CHAR(10), IF(ISBLANK('Ingest Template'!P13),"", 'Ingest Template'!P13&"|Operations - Core Title"),CHAR(10), IF(ISBLANK('Ingest Template'!Q13),"", 'Ingest Template'!Q13&"|Operations - Core Title"))))} -> #|Operations - Core Title #videoGame|Operations - Core Title | AJ14: =if('Ingest Template'!A13="Standard",'Ingest Template'!R13& "|DAR|DAR|2021-01-01",'Ingest Template'!R13& "|Operations - Core Title|Operations - Core Title") -> #N/A | AL14: =if('Ingest Template'!A13="Standard",'Ingest Template'!S13& "|2021-01-01",'Ingest Template'!S13) -> #N/A
B15: ='Ingest Template'!C14&IF('Ingest Template'!A14 = "Standard", " - DAR","") | C15: Video Game | D15: =CONCATENATE('Ingest Template'!E14&Char(10)&'Ingest Template'!G14&Char(10)&'Ingest Template'!H14&Char(10)&'Ingest Template'!I14&Char(10)&'Ingest Template'!J14&Char(10)&'Ingest Template'!K14&Char(10)&'Ingest Template'!L14) | E15: =('Ingest Template'!M14) | F15: {=INDEX(DropDown!$J$2:$J$63,MATCH(1,COUNTIF(E15,DropDown!$I$2:$I$63),0))} -> #N/A | J15: ='Ingest Template'!B15 | K15: =IF('Ingest Template'!A14="Standard",'Ingest Template'!N14,"Competitive View") -> Competitive View | L15: t | M15: ='Ingest Template'!D14 | R15: =CONCATENATE('Ingest Template'!F14) | S15: f | T15: ='Ingest Template'!W14 | V15: =LOWER(SUBSTITUTE(SUBSTITUTE(SUBSTITUTE(SUBSTITUTE(SUBSTITUTE('Ingest Template'!Y14,"https:",""),"www.",""),"/",""),"?hl=en",""),"instagram.com","")) | W15: =(IFERROR(vlookup('Ingest Template'!F14,DropDown!D:E,2,false)&'Ingest Template'!C14,"")) | X15: ='Ingest Template'!AA14 | AB15: ='Ingest Template'!T14 | AD15: ='Ingest Template'!U14 | AE15: ='Ingest Template'!V14 | AG15: {=IF('Ingest Template'!A14="Standard",(CONCATENATE(IF(ISBLANK('Ingest Template'!O14),"", 'Ingest Template'!O14&"|DAR"),CHAR(10), IF(ISBLANK('Ingest Template'!P14),"", 'Ingest Template'!P14&"|DAR"),CHAR(10), IF(ISBLANK('Ingest Template'!Q14),"", 'Ingest Template'!Q14&"|DAR"))),(CONCATENATE(IF(ISBLANK('Ingest Template'!O14),"", 'Ingest Template'!O14&"|Operations - Core Title"),CHAR(10), IF(ISBLANK('Ingest Template'!P14),"", 'Ingest Template'!P14&"|Operations - Core Title"),CHAR(10), IF(ISBLANK('Ingest Template'!Q14),"", 'Ingest Template'!Q14&"|Operations - Core Title"))))} -> #|Operations - Core Title #videoGame|Operations - Core Title | AJ15: =if('Ingest Template'!A14="Standard",'Ingest Template'!R14& "|DAR|DAR|2021-01-01",'Ingest Template'!R14& "|Operations - Core Title|Operations - Core Title") -> #N/A | AL15: =if('Ingest Template'!A14="Standard",'Ingest Template'!S14& "|2021-01-01",'Ingest Template'!S14) -> #N/A
B16: ='Ingest Template'!C16&IF('Ingest Template'!A16 = "Standard", " - DAR","") | C16: Video Game | D16: =CONCATENATE('Ingest Template'!E16&Char(10)&'Ingest Template'!G16&Char(10)&'Ingest Template'!H16&Char(10)&'Ingest Template'!I16&Char(10)&'Ingest Template'!J16&Char(10)&'Ingest Template'!K16&Char(10)&'Ingest Template'!L16) | E16: =('Ingest Template'!M16) | F16: {=INDEX(DropDown!$J$2:$J$63,MATCH(1,COUNTIF(E16,DropDown!$I$2:$I$63),0))} -> #N/A | J16: ='Ingest Template'!B16 | K16: =IF('Ingest Template'!A16="Standard",'Ingest Template'!N16,"Competitive View") -> Competitive View | L16: t | M16: ='Ingest Template'!D16 | R16: =CONCATENATE('Ingest Template'!F16) | S16: f | T16: ='Ingest Template'!W16 | V16: =LOWER(SUBSTITUTE(SUBSTITUTE(SUBSTITUTE(SUBSTITUTE(SUBSTITUTE('Ingest Template'!Y16,"https:",""),"www.",""),"/",""),"?hl=en",""),"instagram.com","")) | W16: =(IFERROR(vlookup('Ingest Template'!F16,DropDown!D:E,2,false)&'Ingest Template'!C16,"")) | X16: ='Ingest Template'!AA16 | AB16: ='Ingest Template'!T16 | AD16: ='Ingest Template'!U16 | AE16: ='Ingest Template'!V16 | AG16: {=IF('Ingest Template'!A16="Standard",(CONCATENATE(IF(ISBLANK('Ingest Template'!O16),"", 'Ingest Template'!O16&"|DAR"),CHAR(10), IF(ISBLANK('Ingest Template'!P16),"", 'Ingest Template'!P16&"|DAR"),CHAR(10), IF(ISBLANK('Ingest Template'!Q16),"", 'Ingest Template'!Q16&"|DAR"))),(CONCATENATE(IF(ISBLANK('Ingest Template'!O16),"", 'Ingest Template'!O16&"|Operations - Core Title"),CHAR(10), IF(ISBLANK('Ingest Template'!P16),"", 'Ingest Template'!P16&"|Operations - Core Title"),CHAR(10), IF(ISBLANK('Ingest Template'!Q16),"", 'Ingest Template'!Q16&"|Operations - Core Title"))))} -> #|Operations - Core Title #videoGame|Operations - Core Title | AJ16: =if('Ingest Template'!A16="Standard",'Ingest Template'!R16& "|DAR|DAR|2021-01-01",'Ingest Template'!R16& "|Operations - Core Title|Operations - Core Title") -> #N/A | AL16: =if('Ingest Template'!A16="Standard",'Ingest Template'!S16& "|2021-01-01",'Ingest Template'!S16) -> #N/A
B17: ='Ingest Template'!C17&IF('Ingest Template'!A17 = "Standard", " - DAR","") | C17: Video Game | D17: =CONCATENATE('Ingest Template'!E17&Char(10)&'Ingest Template'!G17&Char(10)&'Ingest Template'!H17&Char(10)&'Ingest Template'!I17&Char(10)&'Ingest Template'!J17&Char(10)&'Ingest Template'!K17&Char(10)&'Ingest Template'!L17) | E17: =('Ingest Template'!M17) | F17: {=INDEX(DropDown!$J$2:$J$63,MATCH(1,COUNTIF(E17,DropDown!$I$2:$I$63),0))} -> #N/A | J17: ='Ingest Template'!B17 | K17: =IF('Ingest Template'!A17="Standard",'Ingest Template'!N17,"Competitive View") -> Competitive View | L17: t | M17: ='Ingest Template'!D17 | R17: =CONCATENATE('Ingest Template'!F17) | S17: f | T17: ='Ingest Template'!W17 | V17: =LOWER(SUBSTITUTE(SUBSTITUTE(SUBSTITUTE(SUBSTITUTE(SUBSTITUTE('Ingest Template'!Y17,"https:",""),"www.",""),"/",""),"?hl=en",""),"instagram.com","")) | W17: =(IFERROR(vlookup('Ingest Template'!F17,DropDown!D:E,2,false)&'Ingest Template'!C17,"")) | X17: ='Ingest Template'!AA17 | AB17: ='Ingest Template'!T17 | AD17: ='Ingest Template'!U17 | AE17: ='Ingest Template'!V17 | AG17: {=IF('Ingest Template'!A17="Standard",(CONCATENATE(IF(ISBLANK('Ingest Template'!O17),"", 'Ingest Template'!O17&"|DAR"),CHAR(10), IF(ISBLANK('Ingest Template'!P17),"", 'Ingest Template'!P17&"|DAR"),CHAR(10), IF(ISBLANK('Ingest Template'!Q17),"", 'Ingest Template'!Q17&"|DAR"))),(CONCATENATE(IF(ISBLANK('Ingest Template'!O17),"", 'Ingest Template'!O17&"|Operations - Core Title"),CHAR(10), IF(ISBLANK('Ingest Template'!P17),"", 'Ingest Template'!P17&"|Operations - Core Title"),CHAR(10), IF(ISBLANK('Ingest Template'!Q17),"", 'Ingest Template'!Q17&"|Operations - Core Title"))))} -> #|Operations - Core Title #videoGame|Operations - Core Title | AJ17: =if('Ingest Template'!A17="Standard",'Ingest Template'!R17& "|DAR|DAR|2021-01-01",'Ingest Template'!R17& "|Operations - Core Title|Operations - Core Title") -> #N/A | AL17: =if('Ingest Template'!A17="Standard",'Ingest Template'!S17& "|2021-01-01",'Ingest Template'!S17) -> #N/A
B18: ='Ingest Template'!C18&IF('Ingest Template'!A18 = "Standard", " - DAR","") | C18: Video Game | D18: =CONCATENATE('Ingest Template'!E18&Char(10)&'Ingest Template'!G18&Char(10)&'Ingest Template'!H18&Char(10)&'Ingest Template'!I18&Char(10)&'Ingest Template'!J18&Char(10)&'Ingest Template'!K18&Char(10)&'Ingest Template'!L18) | E18: =('Ingest Template'!M18) | F18: {=INDEX(DropDown!$J$2:$J$63,MATCH(1,COUNTIF(E18,DropDown!$I$2:$I$63),0))} -> #N/A | J18: ='Ingest Template'!B18 | K18: =IF('Ingest Template'!A18="Standard",'Ingest Template'!N18,"Competitive View") -> Competitive View | L18: t | M18: ='Ingest Template'!D18 | R18: =CONCATENATE('Ingest Template'!F18) | S18: f | T18: ='Ingest Template'!W18 | V18: =LOWER(SUBSTITUTE(SUBSTITUTE(SUBSTITUTE(SUBSTITUTE(SUBSTITUTE('Ingest Template'!Y18,"https:",""),"www.",""),"/",""),"?hl=en",""),"instagram.com","")) | W18: =(IFERROR(vlookup('Ingest Template'!F18,DropDown!D:E,2,false)&'Ingest Template'!C18,"")) | X18: ='Ingest Template'!AA18 | AB18: ='Ingest Template'!T18 | AD18: ='Ingest Template'!U18 | AE18: ='Ingest Template'!V18 | AG18: {=IF('Ingest Template'!A18="Standard",(CONCATENATE(IF(ISBLANK('Ingest Template'!O18),"", 'Ingest Template'!O18&"|DAR"),CHAR(10), IF(ISBLANK('Ingest Template'!P18),"", 'Ingest Template'!P18&"|DAR"),CHAR(10), IF(ISBLANK('Ingest Template'!Q18),"", 'Ingest Template'!Q18&"|DAR"))),(CONCATENATE(IF(ISBLANK('Ingest Template'!O18),"", 'Ingest Template'!O18&"|Operations - Core Title"),CHAR(10), IF(ISBLANK('Ingest Template'!P18),"", 'Ingest Template'!P18&"|Operations - Core Title"),CHAR(10), IF(ISBLANK('Ingest Template'!Q18),"", 'Ingest Template'!Q18&"|Operations - Core Title"))))} -> #|Operations - Core Title #videoGame|Operations - Core Title | AJ18: =if('Ingest Template'!A18="Standard",'Ingest Template'!R18& "|DAR|DAR|2021-01-01",'Ingest Template'!R18& "|Operations - Core Title|Operations - Core Title") -> #N/A | AL18: =if('Ingest Template'!A18="Standard",'Ingest Template'!S18& "|2021-01-01",'Ingest Template'!S18) -> #N/A
B19: ='Ingest Template'!C19&IF('Ingest Template'!A19 = "Standard", " - DAR","") | C19: Video Game | D19: =CONCATENATE('Ingest Template'!E19&Char(10)&'Ingest Template'!G19&Char(10)&'Ingest Template'!H19&Char(10)&'Ingest Template'!I19&Char(10)&'Ingest Template'!J19&Char(10)&'Ingest Template'!K19&Char(10)&'Ingest Template'!L19) | E19: =('Ingest Template'!M19) | F19: {=INDEX(DropDown!$J$2:$J$63,MATCH(1,COUNTIF(E19,DropDown!$I$2:$I$63),0))} -> #N/A | J19: ='Ingest Template'!B19 | K19: =IF('Ingest Template'!A19="Standard",'Ingest Template'!N19,"Competitive View") -> Competitive View | L19: t | M19: ='Ingest Template'!D19 | R19: =CONCATENATE('Ingest Template'!F19) | S19: f | T19: ='Ingest Template'!W19 | V19: =LOWER(SUBSTITUTE(SUBSTITUTE(SUBSTITUTE(SUBSTITUTE(SUBSTITUTE('Ingest Template'!Y19,"https:",""),"www.",""),"/",""),"?hl=en",""),"instagram.com","")) | W19: =(IFERROR(vlookup('Ingest Template'!F19,DropDown!D:E,2,false)&'Ingest Template'!C19,"")) | X19: ='Ingest Template'!AA19 | AB19: ='Ingest Template'!T19 | AD19: ='Ingest Template'!U19 | AE19: ='Ingest Template'!V19 | AG19: {=IF('Ingest Template'!A19="Standard",(CONCATENATE(IF(ISBLANK('Ingest Template'!O19),"", 'Ingest Template'!O19&"|DAR"),CHAR(10), IF(ISBLANK('Ingest Template'!P19),"", 'Ingest Template'!P19&"|DAR"),CHAR(10), IF(ISBLANK('Ingest Template'!Q19),"", 'Ingest Template'!Q19&"|DAR"))),(CONCATENATE(IF(ISBLANK('Ingest Template'!O19),"", 'Ingest Template'!O19&"|Operations - Core Title"),CHAR(10), IF(ISBLANK('Ingest Template'!P19),"", 'Ingest Template'!P19&"|Operations - Core Title"),CHAR(10), IF(ISBLANK('Ingest Template'!Q19),"", 'Ingest Template'!Q19&"|Operations - Core Title"))))} -> #|Operations - Core Title #videoGame|Operations - Core Title | AJ19: =if('Ingest Template'!A19="Standard",'Ingest Template'!R19& "|DAR|DAR|2021-01-01",'Ingest Template'!R19& "|Operations - Core Title|Operations - Core Title") -> #N/A | AL19: =if('Ingest Template'!A19="Standard",'Ingest Template'!S19& "|2021-01-01",'Ingest Template'!S19) -> #N/A
B20: ='Ingest Template'!C20&IF('Ingest Template'!A20 = "Standard", " - DAR","") | C20: Video Game | D20: =CONCATENATE('Ingest Template'!E20&Char(10)&'Ingest Template'!G20&Char(10)&'Ingest Template'!H20&Char(10)&'Ingest Template'!I20&Char(10)&'Ingest Template'!J20&Char(10)&'Ingest Template'!K20&Char(10)&'Ingest Template'!L20) | E20: =('Ingest Template'!M20) | F20: {=INDEX(DropDown!$J$2:$J$63,MATCH(1,COUNTIF(E20,DropDown!$I$2:$I$63),0))} -> #N/A | J20: ='Ingest Template'!B20 | K20: =IF('Ingest Template'!A20="Standard",'Ingest Template'!N20,"Competitive View") -> Competitive View | L20: t | M20: ='Ingest Template'!D20 | R20: =CONCATENATE('Ingest Template'!F20) | S20: f | T20: ='Ingest Template'!W20 | V20: =LOWER(SUBSTITUTE(SUBSTITUTE(SUBSTITUTE(SUBSTITUTE(SUBSTITUTE('Ingest Template'!Y20,"https:",""),"www.",""),"/",""),"?hl=en",""),"instagram.com","")) | W20: =(IFERROR(vlookup('Ingest Template'!F20,DropDown!D:E,2,false)&'Ingest Template'!C20,"")) | X20: ='Ingest Template'!AA20 | AB20: ='Ingest Template'!T20 | AD20: ='Ingest Template'!U20 | AE20: ='Ingest Template'!V20 | AG20: {=IF('Ingest Template'!A20="Standard",(CONCATENATE(IF(ISBLANK('Ingest Template'!O20),"", 'Ingest Template'!O20&"|DAR"),CHAR(10), IF(ISBLANK('Ingest Template'!P20),"", 'Ingest Template'!P20&"|DAR"),CHAR(10), IF(ISBLANK('Ingest Template'!Q20),"", 'Ingest Template'!Q20&"|DAR"))),(CONCATENATE(IF(ISBLANK('Ingest Template'!O20),"", 'Ingest Template'!O20&"|Operations - Core Title"),CHAR(10), IF(ISBLANK('Ingest Template'!P20),"", 'Ingest Template'!P20&"|Operations - Core Title"),CHAR(10), IF(ISBLANK('Ingest Template'!Q20),"", 'Ingest Template'!Q20&"|Operations - Core Title"))))} -> #|Operations - Core Title #videoGame|Operations - Core Title | AJ20: =if('Ingest Template'!A20="Standard",'Ingest Template'!R20& "|DAR|DAR|2021-01-01",'Ingest Template'!R20& "|Operations - Core Title|Operations - Core Title") -> #N/A | AL20: =if('Ingest Template'!A20="Standard",'Ingest Template'!S20& "|2021-01-01",'Ingest Template'!S20) -> #N/A
B21: ='Ingest Template'!C21&IF('Ingest Template'!A21 = "Standard", " - DAR","") | C21: Video Game | D21: =CONCATENATE('Ingest Template'!E21&Char(10)&'Ingest Template'!G21&Char(10)&'Ingest Template'!H21&Char(10)&'Ingest Template'!I21&Char(10)&'Ingest Template'!J21&Char(10)&'Ingest Template'!K21&Char(10)&'Ingest Template'!L21) | E21: =('Ingest Template'!M21) | F21: {=INDEX(DropDown!$J$2:$J$63,MATCH(1,COUNTIF(E21,DropDown!$I$2:$I$63),0))} -> #N/A | J21: ='Ingest Template'!B21 | K21: =IF('Ingest Template'!A21="Standard",'Ingest Template'!N21,"Competitive View") -> Competitive View | L21: t | M21: ='Ingest Template'!D21 | R21: =CONCATENATE('Ingest Template'!F21) | S21: f | T21: ='Ingest Template'!W21 | V21: =LOWER(SUBSTITUTE(SUBSTITUTE(SUBSTITUTE(SUBSTITUTE(SUBSTITUTE('Ingest Template'!Y21,"https:",""),"www.",""),"/",""),"?hl=en",""),"instagram.com","")) | W21: =(IFERROR(vlookup('Ingest Template'!F21,DropDown!D:E,2,false)&'Ingest Template'!C21,"")) | X21: ='Ingest Template'!AA21 | AB21: ='Ingest Template'!T21 | AD21: ='Ingest Template'!U21 | AE21: ='Ingest Template'!V21 | AG21: {=IF('Ingest Template'!A21="Standard",(CONCATENATE(IF(ISBLANK('Ingest Template'!O21),"", 'Ingest Template'!O21&"|DAR"),CHAR(10), IF(ISBLANK('Ingest Template'!P21),"", 'Ingest Template'!P21&"|DAR"),CHAR(10), IF(ISBLANK('Ingest Template'!Q21),"", 'Ingest Template'!Q21&"|DAR"))),(CONCATENATE(IF(ISBLANK('Ingest Template'!O21),"", 'Ingest Template'!O21&"|Operations - Core Title"),CHAR(10), IF(ISBLANK('Ingest Template'!P21),"", 'Ingest Template'!P21&"|Operations - Core Title"),CHAR(10), IF(ISBLANK('Ingest Template'!Q21),"", 'Ingest Template'!Q21&"|Operations - Core Title"))))} -> #|Operations - Core Title #videoGame|Operations - Core Title | AJ21: =if('Ingest Template'!A21="Standard",'Ingest Template'!R21& "|DAR|DAR|2021-01-01",'Ingest Template'!R21& "|Operations - Core Title|Operations - Core Title") -> #N/A | AL21: =if('Ingest Template'!A21="Standard",'Ingest Template'!S21& "|2021-01-01",'Ingest Template'!S21) -> #N/A
B22: ='Ingest Template'!C22&IF('Ingest Template'!A22 = "Standard", " - DAR","") | C22: Video Game | D22: =CONCATENATE('Ingest Template'!E22&Char(10)&'Ingest Template'!G22&Char(10)&'Ingest Template'!H22&Char(10)&'Ingest Template'!I22&Char(10)&'Ingest Template'!J22&Char(10)&'Ingest Template'!K22&Char(10)&'Ingest Template'!L22) | E22: =('Ingest Template'!M22) | F22: {=INDEX(DropDown!$J$2:$J$63,MATCH(1,COUNTIF(E22,DropDown!$I$2:$I$63),0))} -> #N/A | J22: ='Ingest Template'!B22 | K22: =IF('Ingest Template'!A22="Standard",'Ingest Template'!N22,"Competitive View") -> Competitive View | L22: t | M22: ='Ingest Template'!D22 | R22: =CONCATENATE('Ingest Template'!F22) | S22: f | T22: ='Ingest Template'!W22 | V22: =LOWER(SUBSTITUTE(SUBSTITUTE(SUBSTITUTE(SUBSTITUTE(SUBSTITUTE('Ingest Template'!Y22,"https:",""),"www.",""),"/",""),"?hl=en",""),"instagram.com","")) | W22: =(IFERROR(vlookup('Ingest Template'!F22,DropDown!D:E,2,false)&'Ingest Template'!C22,"")) | X22: ='Ingest Template'!AA22 | AB22: ='Ingest Template'!T22 | AD22: ='Ingest Template'!U22 | AE22: ='Ingest Template'!V22 | AG22: {=IF('Ingest Template'!A22="Standard",(CONCATENATE(IF(ISBLANK('Ingest Template'!O22),"", 'Ingest Template'!O22&"|DAR"),CHAR(10), IF(ISBLANK('Ingest Template'!P22),"", 'Ingest Template'!P22&"|DAR"),CHAR(10), IF(ISBLANK('Ingest Template'!Q22),"", 'Ingest Template'!Q22&"|DAR"))),(CONCATENATE(IF(ISBLANK('Ingest Template'!O22),"", 'Ingest Template'!O22&"|Operations - Core Title"),CHAR(10), IF(ISBLANK('Ingest Template'!P22),"", 'Ingest Template'!P22&"|Operations - Core Title"),CHAR(10), IF(ISBLANK('Ingest Template'!Q22),"", 'Ingest Template'!Q22&"|Operations - Core Title"))))} -> #|Operations - Core Title #videoGame|Operations - Core Title | AJ22: =if('Ingest Template'!A22="Standard",'Ingest Template'!R22& "|DAR|DAR|2021-01-01",'Ingest Template'!R22& "|Operations - Core Title|Operations - Core Title") -> #N/A | AL22: =if('Ingest Template'!A22="Standard",'Ingest Template'!S22& "|2021-01-01",'Ingest Template'!S22) -> #N/A
B23: ='Ingest Template'!C23&IF('Ingest Template'!A23 = "Standard", " - DAR","") | C23: Video Game | D23: =CONCATENATE('Ingest Template'!E23&Char(10)&'Ingest Template'!G23&Char(10)&'Ingest Template'!H23&Char(10)&'Ingest Template'!I23&Char(10)&'Ingest Template'!J23&Char(10)&'Ingest Template'!K23&Char(10)&'Ingest Template'!L23) | E23: =('Ingest Template'!M23) | F23: {=INDEX(DropDown!$J$2:$J$63,MATCH(1,COUNTIF(E23,DropDown!$I$2:$I$63),0))} -> #N/A | J23: ='Ingest Template'!B23 | K23: =IF('Ingest Template'!A23="Standard",'Ingest Template'!N23,"Competitive View") -> Competitive View | L23: t | M23: ='Ingest Template'!D23 | R23: =CONCATENATE('Ingest Template'!F23) | S23: f | T23: ='Ingest Template'!W23 | V23: =LOWER(SUBSTITUTE(SUBSTITUTE(SUBSTITUTE(SUBSTITUTE(SUBSTITUTE('Ingest Template'!Y23,"https:",""),"www.",""),"/",""),"?hl=en",""),"instagram.com","")) | W23: =(IFERROR(vlookup('Ingest Template'!F23,DropDown!D:E,2,false)&'Ingest Template'!C23,"")) | X23: ='Ingest Template'!AA23 | AB23: ='Ingest Template'!T23 | AD23: ='Ingest Template'!U23 | AE23: ='Ingest Template'!V23 | AG23: {=IF('Ingest Template'!A23="Standard",(CONCATENATE(IF(ISBLANK('Ingest Template'!O23),"", 'Ingest Template'!O23&"|DAR"),CHAR(10), IF(ISBLANK('Ingest Template'!P23),"", 'Ingest Template'!P23&"|DAR"),CHAR(10), IF(ISBLANK('Ingest Template'!Q23),"", 'Ingest Template'!Q23&"|DAR"))),(CONCATENATE(IF(ISBLANK('Ingest Template'!O23),"", 'Ingest Template'!O23&"|Operations - Core Title"),CHAR(10), IF(ISBLANK('Ingest Template'!P23),"", 'Ingest Template'!P23&"|Operations - Core Title"),CHAR(10), IF(ISBLANK('Ingest Template'!Q23),"", 'Ingest Template'!Q23&"|Operations - Core Title"))))} -> #|Operations - Core Title #videoGame|Operations - Core Title | AJ23: =if('Ingest Template'!A23="Standard",'Ingest Template'!R23& "|DAR|DAR|2021-01-01",'Ingest Template'!R23& "|Operations - Core Title|Operations - Core Title") -> #N/A | AL23: =if('Ingest Template'!A23="Standard",'Ingest Template'!S23& "|2021-01-01",'Ingest Template'!S23) -> #N/A
B24: ='Ingest Template'!C24&IF('Ingest Template'!A24 = "Standard", " - DAR","") | C24: Video Game | D24: =CONCATENATE('Ingest Template'!E24&Char(10)&'Ingest Template'!G24&Char(10)&'Ingest Template'!H24&Char(10)&'Ingest Template'!I24&Char(10)&'Ingest Template'!J24&Char(10)&'Ingest Template'!K24&Char(10)&'Ingest Template'!L24) | E24: =('Ingest Template'!M24) | F24: {=INDEX(DropDown!$J$2:$J$63,MATCH(1,COUNTIF(E24,DropDown!$I$2:$I$63),0))} -> #N/A | J24: ='Ingest Template'!B24 | K24: =IF('Ingest Template'!A24="Standard",'Ingest Template'!N24,"Competitive View") -> Competitive View | L24: t | M24: ='Ingest Template'!D24 | R24: =CONCATENATE('Ingest Template'!F24) | S24: f | T24: ='Ingest Template'!W24 | V24: =LOWER(SUBSTITUTE(SUBSTITUTE(SUBSTITUTE(SUBSTITUTE(SUBSTITUTE('Ingest Template'!Y24,"https:",""),"www.",""),"/",""),"?hl=en",""),"instagram.com","")) | W24: =(IFERROR(vlookup('Ingest Template'!F24,DropDown!D:E,2,false)&'Ingest Template'!C24,"")) | X24: ='Ingest Template'!AA24 | AB24: ='Ingest Template'!T24 | AD24: ='Ingest Template'!U24 | AE24: ='Ingest Template'!V24 | AG24: {=IF('Ingest Template'!A24="Standard",(CONCATENATE(IF(ISBLANK('Ingest Template'!O24),"", 'Ingest Template'!O24&"|DAR"),CHAR(10), IF(ISBLANK('Ingest Template'!P24),"", 'Ingest Template'!P24&"|DAR"),CHAR(10), IF(ISBLANK('Ingest Template'!Q24),"", 'Ingest Template'!Q24&"|DAR"))),(CONCATENATE(IF(ISBLANK('Ingest Template'!O24),"", 'Ingest Template'!O24&"|Operations - Core Title"),CHAR(10), IF(ISBLANK('Ingest Template'!P24),"", 'Ingest Template'!P24&"|Operations - Core Title"),CHAR(10), IF(ISBLANK('Ingest Template'!Q24),"", 'Ingest Template'!Q24&"|Operations - Core Title"))))} -> #|Operations - Core Title #videoGame|Operations - Core Title | AJ24: =if('Ingest Template'!A24="Standard",'Ingest Template'!R24& "|DAR|DAR|2021-01-01",'Ingest Template'!R24& "|Operations - Core Title|Operations - Core Title") -> #N/A | AL24: =if('Ingest Template'!A24="Standard",'Ingest Template'!S24& "|2021-01-01",'Ingest Template'!S24) -> #N/A
B25: ='Ingest Template'!C25&IF('Ingest Template'!A25 = "Standard", " - DAR","") | C25: Video Game | D25: =CONCATENATE('Ingest Template'!E25&Char(10)&'Ingest Template'!G25&Char(10)&'Ingest Template'!H25&Char(10)&'Ingest Template'!I25&Char(10)&'Ingest Template'!J25&Char(10)&'Ingest Template'!K25&Char(10)&'Ingest Template'!L25) | E25: =('Ingest Template'!M25) | F25: {=INDEX(DropDown!$J$2:$J$63,MATCH(1,COUNTIF(E25,DropDown!$I$2:$I$63),0))} -> #N/A | J25: ='Ingest Template'!B25 | K25: =IF('Ingest Template'!A25="Standard",'Ingest Template'!N25,"Competitive View") -> Competitive View | L25: t | M25: ='Ingest Template'!D25 | R25: =CONCATENATE('Ingest Template'!F25) | S25: f | T25: ='Ingest Template'!W25 | V25: =LOWER(SUBSTITUTE(SUBSTITUTE(SUBSTITUTE(SUBSTITUTE(SUBSTITUTE('Ingest Template'!Y25,"https:",""),"www.",""),"/",""),"?hl=en",""),"instagram.com","")) | W25: =(IFERROR(vlookup('Ingest Template'!F25,DropDown!D:E,2,false)&'Ingest Template'!C25,"")) | X25: ='Ingest Template'!AA25 | AB25: ='Ingest Template'!T25 | AD25: ='Ingest Template'!U25 | AE25: ='Ingest Template'!V25 | AG25: {=IF('Ingest Template'!A25="Standard",(CONCATENATE(IF(ISBLANK('Ingest Template'!O25),"", 'Ingest Template'!O25&"|DAR"),CHAR(10), IF(ISBLANK('Ingest Template'!P25),"", 'Ingest Template'!P25&"|DAR"),CHAR(10), IF(ISBLANK('Ingest Template'!Q25),"", 'Ingest Template'!Q25&"|DAR"))),(CONCATENATE(IF(ISBLANK('Ingest Template'!O25),"", 'Ingest Template'!O25&"|Operations - Core Title"),CHAR(10), IF(ISBLANK('Ingest Template'!P25),"", 'Ingest Template'!P25&"|Operations - Core Title"),CHAR(10), IF(ISBLANK('Ingest Template'!Q25),"", 'Ingest Template'!Q25&"|Operations - Core Title"))))} -> #|Operations - Core Title #videoGame|Operations - Core Title | AJ25: =if('Ingest Template'!A25="Standard",'Ingest Template'!R25& "|DAR|DAR|2021-01-01",'Ingest Template'!R25& "|Operations - Core Title|Operations - Core Title") -> #N/A | AL25: =if('Ingest Template'!A25="Standard",'Ingest Template'!S25& "|2021-01-01",'Ingest Template'!S25) -> #N/A
B26: ='Ingest Template'!C26&IF('Ingest Template'!A26 = "Standard", " - DAR","") | C26: Video Game | D26: =CONCATENATE('Ingest Template'!E26&Char(10)&'Ingest Template'!G26&Char(10)&'Ingest Template'!H26&Char(10)&'Ingest Template'!I26&Char(10)&'Ingest Template'!J26&Char(10)&'Ingest Template'!K26&Char(10)&'Ingest Template'!L26) | E26: =('Ingest Template'!M26) | F26: {=INDEX(DropDown!$J$2:$J$63,MATCH(1,COUNTIF(E26,DropDown!$I$2:$I$63),0))} -> #N/A | J26: ='Ingest Template'!B26 | K26: =IF('Ingest Template'!A26="Standard",'Ingest Template'!N26,"Competitive View") -> Competitive View | L26: t | M26: ='Ingest Template'!D26 | R26: =CONCATENATE('Ingest Template'!F26) | S26: f | T26: ='Ingest Template'!W26 | V26: =LOWER(SUBSTITUTE(SUBSTITUTE(SUBSTITUTE(SUBSTITUTE(SUBSTITUTE('Ingest Template'!Y26,"https:",""),"www.",""),"/",""),"?hl=en",""),"instagram.com","")) | W26: =(IFERROR(vlookup('Ingest Template'!F26,DropDown!D:E,2,false)&'Ingest Template'!C26,"")) | X26: ='Ingest Template'!AA26 | AB26: ='Ingest Template'!T26 | AD26: ='Ingest Template'!U26 | AE26: ='Ingest Template'!V26 | AG26: {=IF('Ingest Template'!A26="Standard",(CONCATENATE(IF(ISBLANK('Ingest Template'!O26),"", 'Ingest Template'!O26&"|DAR"),CHAR(10), IF(ISBLANK('Ingest Template'!P26),"", 'Ingest Template'!P26&"|DAR"),CHAR(10), IF(ISBLANK('Ingest Template'!Q26),"", 'Ingest Template'!Q26&"|DAR"))),(CONCATENATE(IF(ISBLANK('Ingest Template'!O26),"", 'Ingest Template'!O26&"|Operations - Core Title"),CHAR(10), IF(ISBLANK('Ingest Template'!P26),"", 'Ingest Template'!P26&"|Operations - Core Title"),CHAR(10), IF(ISBLANK('Ingest Template'!Q26),"", 'Ingest Template'!Q26&"|Operations - Core Title"))))} -> #|Operations - Core Title #videoGame|Operations - Core Title | AJ26: =if('Ingest Template'!A26="Standard",'Ingest Template'!R26& "|DAR|DAR|2021-01-01",'Ingest Template'!R26& "|Operations - Core Title|Operations - Core Title") -> #N/A | AL26: =if('Ingest Template'!A26="Standard",'Ingest Template'!S26& "|2021-01-01",'Ingest Template'!S26) -> #N/A
B27: ='Ingest Template'!C27&IF('Ingest Template'!A27 = "Standard", " - DAR","") | C27: Video Game | D27: =CONCATENATE('Ingest Template'!E27&Char(10)&'Ingest Template'!G27&Char(10)&'Ingest Template'!H27&Char(10)&'Ingest Template'!I27&Char(10)&'Ingest Template'!J27&Char(10)&'Ingest Template'!K27&Char(10)&'Ingest Template'!L27) | E27: =('Ingest Template'!M27) | F27: {=INDEX(DropDown!$J$2:$J$63,MATCH(1,COUNTIF(E27,DropDown!$I$2:$I$63),0))} -> #N/A | J27: ='Ingest Template'!B27 | K27: =IF('Ingest Template'!A27="Standard",'Ingest Template'!N27,"Competitive View") -> Competitive View | L27: t | M27: ='Ingest Template'!D27 | R27: =CONCATENATE('Ingest Template'!F27) | S27: f | T27: ='Ingest Template'!W27 | V27: =LOWER(SUBSTITUTE(SUBSTITUTE(SUBSTITUTE(SUBSTITUTE(SUBSTITUTE('Ingest Template'!Y27,"https:",""),"www.",""),"/",""),"?hl=en",""),"instagram.com","")) | W27: =(IFERROR(vlookup('Ingest Template'!F27,DropDown!D:E,2,false)&'Ingest Template'!C27,"")) | X27: ='Ingest Template'!AA27 | AB27: ='Ingest Template'!T27 | AD27: ='Ingest Template'!U27 | AE27: ='Ingest Template'!V27 | AG27: {=IF('Ingest Template'!A27="Standard",(CONCATENATE(IF(ISBLANK('Ingest Template'!O27),"", 'Ingest Template'!O27&"|DAR"),CHAR(10), IF(ISBLANK('Ingest Template'!P27),"", 'Ingest Template'!P27&"|DAR"),CHAR(10), IF(ISBLANK('Ingest Template'!Q27),"", 'Ingest Template'!Q27&"|DAR"))),(CONCATENATE(IF(ISBLANK('Ingest Template'!O27),"", 'Ingest Template'!O27&"|Operations - Core Title"),CHAR(10), IF(ISBLANK('Ingest Template'!P27),"", 'Ingest Template'!P27&"|Operations - Core Title"),CHAR(10), IF(ISBLANK('Ingest Template'!Q27),"", 'Ingest Template'!Q27&"|Operations - Core Title"))))} -> #|Operations - Core Title #videoGame|Operations - Core Title | AJ27: =if('Ingest Template'!A27="Standard",'Ingest Template'!R27& "|DAR|DAR|2021-01-01",'Ingest Template'!R27& "|Operations - Core Title|Operations - Core Title") -> #N/A | AL27: =if('Ingest Template'!A27="Standard",'Ingest Template'!S27& "|2021-01-01",'Ingest Template'!S27) -> #N/A
... B125: ='Ingest Template'!C125&IF('Ingest Template'!A125 = "Standard", " - DAR","") | C125: Video Game | D125: =CONCATENATE('Ingest Template'!E125&Char(10)&'Ingest Template'!G125&Char(10)&'Ingest Template'!H125&Char(10)&'Ingest Template'!I125&Char(10)&'Ingest Template'!J125&Char(10)&'Ingest Template'!K125&Char(10)&'Ingest Template'!L125) | E125: =('Ingest Template'!M125) | F125: {=INDEX(DropDown!$J$2:$J$63,MATCH(1,COUNTIF(E125,DropDown!$I$2:$I$63),0))} -> #N/A | J125: ='Ingest Template'!B125 | K125: =IF('Ingest Template'!A125="Standard",'Ingest Template'!N125,"Competitive View") -> Competitive View | L125: t | M125: ='Ingest Template'!D125 | R125: =CONCATENATE('Ingest Template'!F125) | S125: f | T125: ='Ingest Template'!W125 | V125: =LOWER(SUBSTITUTE(SUBSTITUTE(SUBSTITUTE(SUBSTITUTE(SUBSTITUTE('Ingest Template'!Y125,"https:",""),"www.",""),"/",""),"?hl=en",""),"instagram.com","")) | W125: =(IFERROR(vlookup('Ingest Template'!F125,DropDown!D:E,2,false)&'Ingest Template'!C125,"")) | X125: ='Ingest Template'!AA125 | AB125: ='Ingest Template'!T125 | AD125: ='Ingest Template'!U125 | AE125: ='Ingest Template'!V125 | AG125: {=IF('Ingest Template'!A125="Standard",(CONCATENATE(IF(ISBLANK('Ingest Template'!O125),"", 'Ingest Template'!O125&"|DAR"),CHAR(10), IF(ISBLANK('Ingest Template'!P125),"", 'Ingest Template'!P125&"|DAR"),CHAR(10), IF(ISBLANK('Ingest Template'!Q125),"", 'Ingest Template'!Q125&"|DAR"))),(CONCATENATE(IF(ISBLANK('Ingest Template'!O125),"", 'Ingest Template'!O125&"|Operations - Core Title"),CHAR(10), IF(ISBLANK('Ingest Template'!P125),"", 'Ingest Template'!P125&"|Operations - Core Title"),CHAR(10), IF(ISBLANK('Ingest Template'!Q125),"", 'Ingest Template'!Q125&"|Operations - Core Title"))))} -> #|Operations - Core Title #videoGame|Operations - Core Title | AJ125: =if('Ingest Template'!A125="Standard",'Ingest Template'!R125& "|DAR|DAR|2021-01-01",'Ingest Template'!R125& "|Operations - Core Title|Operations - Core Title") -> #N/A | AL125: =if('Ingest Template'!A125="Standard",'Ingest Template'!S125& "|2021-01-01",'Ingest Template'!S125) -> #N/A
B126: ='Ingest Template'!C125&IF('Ingest Template'!A125 = "Standard", " - DAR","") | C126: Video Game | D126: =CONCATENATE('Ingest Template'!E126&Char(10)&'Ingest Template'!G126&Char(10)&'Ingest Template'!H126&Char(10)&'Ingest Template'!I126&Char(10)&'Ingest Template'!J126&Char(10)&'Ingest Template'!K126&Char(10)&'Ingest Template'!L126) | E126: =('Ingest Template'!M126) | F126: {=INDEX(DropDown!$J$2:$J$63,MATCH(1,COUNTIF(E126,DropDown!$I$2:$I$63),0))} -> #N/A | J126: ='Ingest Template'!B126 | K126: =IF('Ingest Template'!A125="Standard",'Ingest Template'!N125,"Competitive View") -> Competitive View | L126: t | M126: ='Ingest Template'!D125 | R126: =CONCATENATE('Ingest Template'!F125) | S126: f | T126: ='Ingest Template'!W125 | V126: =LOWER(SUBSTITUTE(SUBSTITUTE(SUBSTITUTE(SUBSTITUTE(SUBSTITUTE('Ingest Template'!Y125,"https:",""),"www.",""),"/",""),"?hl=en",""),"instagram.com","")) | W126: =(IFERROR(vlookup('Ingest Template'!F126,DropDown!D:E,2,false)&'Ingest Template'!C126,"")) | X126: ='Ingest Template'!AA125 | AB126: ='Ingest Template'!T125 | AD126: ='Ingest Template'!U125 | AE126: ='Ingest Template'!V125 | AG126: {=IF('Ingest Template'!A125="Standard",(CONCATENATE(IF(ISBLANK('Ingest Template'!O125),"", 'Ingest Template'!O125&"|DAR"),CHAR(10), IF(ISBLANK('Ingest Template'!P125),"", 'Ingest Template'!P125&"|DAR"),CHAR(10), IF(ISBLANK('Ingest Template'!Q125),"", 'Ingest Template'!Q125&"|DAR"))),(CONCATENATE(IF(ISBLANK('Ingest Template'!O125),"", 'Ingest Template'!O125&"|Operations - Core Title"),CHAR(10), IF(ISBLANK('Ingest Template'!P125),"", 'Ingest Template'!P125&"|Operations - Core Title"),CHAR(10), IF(ISBLANK('Ingest Template'!Q125),"", 'Ingest Template'!Q125&"|Operations - Core Title"))))} -> #|Operations - Core Title #videoGame|Operations - Core Title | AJ126: =if('Ingest Template'!A125="Standard",'Ingest Template'!R125& "|DAR|DAR|2021-01-01",'Ingest Template'!R125& "|Operations - Core Title|Operations - Core Title") -> #N/A | AL126: =if('Ingest Template'!A125="Standard",'Ingest Template'!S125& "|2021-01-01",'Ingest Template'!S125) -> #N/A
B127: ='Ingest Template'!C126&IF('Ingest Template'!A126 = "Standard", " - DAR","") | C127: Video Game | D127: =CONCATENATE('Ingest Template'!E127&Char(10)&'Ingest Template'!G127&Char(10)&'Ingest Template'!H127&Char(10)&'Ingest Template'!I127&Char(10)&'Ingest Template'!J127&Char(10)&'Ingest Template'!K127&Char(10)&'Ingest Template'!L127) | E127: =('Ingest Template'!M127) | F127: {=INDEX(DropDown!$J$2:$J$63,MATCH(1,COUNTIF(E127,DropDown!$I$2:$I$63),0))} -> #N/A | J127: ='Ingest Template'!B127 | K127: =IF('Ingest Template'!A126="Standard",'Ingest Template'!N126,"Competitive View") -> Competitive View | L127: t | M127: ='Ingest Template'!D126 | R127: =CONCATENATE('Ingest Template'!F126) | S127: f | T127: ='Ingest Template'!W126 | V127: =LOWER(SUBSTITUTE(SUBSTITUTE(SUBSTITUTE(SUBSTITUTE(SUBSTITUTE('Ingest Template'!Y126,"https:",""),"www.",""),"/",""),"?hl=en",""),"instagram.com","")) | W127: =(IFERROR(vlookup('Ingest Template'!F127,DropDown!D:E,2,false)&'Ingest Template'!C127,"")) | X127: ='Ingest Template'!AA126 | AB127: ='Ingest Template'!T126 | AD127: ='Ingest Template'!U126 | AE127: ='Ingest Template'!V126 | AG127: {=IF('Ingest Template'!A126="Standard",(CONCATENATE(IF(ISBLANK('Ingest Template'!O126),"", 'Ingest Template'!O126&"|DAR"),CHAR(10), IF(ISBLANK('Ingest Template'!P126),"", 'Ingest Template'!P126&"|DAR"),CHAR(10), IF(ISBLANK('Ingest Template'!Q126),"", 'Ingest Template'!Q126&"|DAR"))),(CONCATENATE(IF(ISBLANK('Ingest Template'!O126),"", 'Ingest Template'!O126&"|Operations - Core Title"),CHAR(10), IF(ISBLANK('Ingest Template'!P126),"", 'Ingest Template'!P126&"|Operations - Core Title"),CHAR(10), IF(ISBLANK('Ingest Template'!Q126),"", 'Ingest Template'!Q126&"|Operations - Core Title"))))} -> #|Operations - Core Title #videoGame|Operations - Core Title | AJ127: =if('Ingest Template'!A126="Standard",'Ingest Template'!R126& "|DAR|DAR|2021-01-01",'Ingest Template'!R126& "|Operations - Core Title|Operations - Core Title") -> #N/A | AL127: =if('Ingest Template'!A126="Standard",'Ingest Template'!S126& "|2021-01-01",'Ingest Template'!S126) -> #N/A
